{"stream":"book:BTC/USD","kind":"snapshot","seq":1,"receive_ts":1788771088919969000,"monotonic_ts":3188830749907666,"payload":"{\"channel\":\"book\",\"type\":\"snapshot\",\"data\":[{\"symbol\":\"BTC/USD\",\"bids\":[{\"price\":79454.9,\"qty\":0.03675909},{\"price\":79454.7,\"qty\":0.00005100},{\"price\":79451.9,\"qty\":0.00428803},{\"price\":79450.8,\"qty\":0.00005100},{\"price\":79447.5,\"qty\":0.00200000},{\"price\":79446.8,\"qty\":0.00005100},{\"price\":79446.2,\"qty\":0.07015649},{\"price\":79446.1,\"qty\":0.62935746},{\"price\":79443.9,\"qty\":0.62937466},{\"price\":79443.2,\"qty\":0.00009600},{\"price\":79442.8,\"qty\":0.00005100},{\"price\":79440.5,\"qty\":0.12586204},{\"price\":79439.4,\"qty\":0.06853785},{\"price\":79438.9,\"qty\":0.18884407},{\"price\":79436.6,\"qty\":0.62943228},{\"price\":79435.3,\"qty\":0.30714451},{\"price\":79435.2,\"qty\":0.33994887},{\"price\":79435.1,\"qty\":0.00016000},{\"price\":79435.0,\"qty\":0.13109402},{\"price\":79434.7,\"qty\":0.05440000},{\"price\":79434.4,\"qty\":0.40000000},{\"price\":79432.0,\"qty\":0.01414792},{\"price\":79427.1,\"qty\":0.04019046},{\"price\":79426.4,\"qty\":0.01026423},{\"price\":79426.3,\"qty\":0.06294147},{\"price\":79426.1,\"qty\":1.88854572},{\"price\":79425.5,\"qty\":0.00125905},{\"price\":79425.3,\"qty\":0.01259044},{\"price\":79424.9,\"qty\":0.00080000},{\"price\":79424.5,\"qty\":0.00006803},{\"price\":79424.2,\"qty\":0.01259062},{\"price\":79424.0,\"qty\":0.02676679},{\"price\":79423.1,\"qty\":0.05440000},{\"price\":79422.8,\"qty\":1.03184167},{\"price\":79422.7,\"qty\":0.50336100},{\"price\":79422.2,\"qty\":0.11364277},{\"price\":79421.8,\"qty\":0.04030697},{\"price\":79418.5,\"qty\":0.00006803},{\"price\":79418.0,\"qty\":0.04225123},{\"price\":79417.5,\"qty\":0.00120000},{\"price\":79417.2,\"qty\":0.00110000},{\"price\":79416.7,\"qty\":1.88422139},{\"price\":79416.6,\"qty\":6.38709067},{\"price\":79415.4,\"qty\":0.02057681},{\"price\":79414.9,\"qty\":0.00100000},{\"price\":79413.8,\"qty\":0.05440000},{\"price\":79413.4,\"qty\":0.70482500},{\"price\":79412.4,\"qty\":0.00006803},{\"price\":79411.3,\"qty\":0.00226858},{\"price\":79411.2,\"qty\":0.00005100},{\"price\":79408.7,\"qty\":0.14629542},{\"price\":79407.5,\"qty\":0.00150000},{\"price\":79407.0,\"qty\":2.25323280},{\"price\":79406.9,\"qty\":6.29668071},{\"price\":79406.4,\"qty\":0.00006803},{\"price\":79404.9,\"qty\":0.00120000},{\"price\":79404.5,\"qty\":0.00050000},{\"price\":79403.5,\"qty\":0.01769664},{\"price\":79403.4,\"qty\":0.05440000},{\"price\":79401.1,\"qty\":0.00011000},{\"price\":79400.4,\"qty\":0.00006803},{\"price\":79399.9,\"qty\":0.00749432},{\"price\":79399.5,\"qty\":0.07365722},{\"price\":79397.5,\"qty\":0.00180000},{\"price\":79397.2,\"qty\":1.89235686},{\"price\":79397.1,\"qty\":6.29745867},{\"price\":79396.1,\"qty\":0.01577575},{\"price\":79395.6,\"qty\":0.00757300},{\"price\":79395.5,\"qty\":0.02090873},{\"price\":79395.4,\"qty\":0.05445100},{\"price\":79395.2,\"qty\":0.00757300},{\"price\":79394.7,\"qty\":0.00757300},{\"price\":79394.4,\"qty\":0.00006803},{\"price\":79391.3,\"qty\":0.02976092},{\"price\":79391.2,\"qty\":0.05038341},{\"price\":79391.1,\"qty\":0.00757300},{\"price\":79390.8,\"qty\":0.00757300},{\"price\":79389.9,\"qty\":0.00757300},{\"price\":79389.2,\"qty\":0.00757300},{\"price\":79388.3,\"qty\":0.00006803},{\"price\":79388.2,\"qty\":0.00757300},{\"price\":79388.1,\"qty\":0.00757300},{\"price\":79387.8,\"qty\":0.00757300},{\"price\":79387.4,\"qty\":0.05440000},{\"price\":79387.3,\"qty\":1.67010558},{\"price\":79387.0,\"qty\":6.29825994},{\"price\":79386.8,\"qty\":0.12516368},{\"price\":79386.7,\"qty\":6.32463272},{\"price\":79386.0,\"qty\":0.44051900},{\"price\":79385.6,\"qty\":0.60000000},{\"price\":79385.0,\"qty\":0.11115273},{\"price\":79382.5,\"qty\":0.01748672},{\"price\":79382.3,\"qty\":0.00006803},{\"price\":79379.5,\"qty\":0.00005100},{\"price\":79379.4,\"qty\":0.05440000},{\"price\":79376.3,\"qty\":0.00006803},{\"price\":79371.5,\"qty\":1.33044412},{\"price\":79371.4,\"qty\":0.05440000},{\"price\":79371.3,\"qty\":4.40965415},{\"price\":79371.0,\"qty\":0.69272000},{\"price\":79370.3,\"qty\":0.00006803},{\"price\":79369.9,\"qty\":0.02202417},{\"price\":79368.5,\"qty\":0.17428883},{\"price\":79367.2,\"qty\":0.34006000},{\"price\":79365.1,\"qty\":0.06172119},{\"price\":79364.2,\"qty\":0.00006803},{\"price\":79363.9,\"qty\":0.12600187},{\"price\":79363.7,\"qty\":4.49210242},{\"price\":79363.6,\"qty\":15.00000000},{\"price\":79358.2,\"qty\":0.00006803},{\"price\":79357.0,\"qty\":0.03758115},{\"price\":79356.9,\"qty\":0.12590000},{\"price\":79355.5,\"qty\":0.12516368},{\"price\":79352.3,\"qty\":0.00302998},{\"price\":79352.2,\"qty\":0.00006803},{\"price\":79349.8,\"qty\":0.05640669},{\"price\":79349.7,\"qty\":0.18890000},{\"price\":79349.0,\"qty\":4.41089054},{\"price\":79347.2,\"qty\":0.02518000},{\"price\":79346.3,\"qty\":0.01841471},{\"price\":79346.2,\"qty\":0.00006803},{\"price\":79345.3,\"qty\":0.11164949},{\"price\":79342.9,\"qty\":0.02467010},{\"price\":79340.4,\"qty\":1.39104000},{\"price\":79340.1,\"qty\":0.00006803},{\"price\":79338.7,\"qty\":0.00370041},{\"price\":79335.6,\"qty\":4.41163376},{\"price\":79334.1,\"qty\":0.00006803},{\"price\":79333.3,\"qty\":0.01970645},{\"price\":79330.8,\"qty\":0.03700300},{\"price\":79328.8,\"qty\":1.66999734},{\"price\":79328.1,\"qty\":0.00006803},{\"price\":79327.9,\"qty\":0.00659707},{\"price\":79326.8,\"qty\":1.20000000},{\"price\":79326.5,\"qty\":1.41617000},{\"price\":79325.5,\"qty\":4.41220003},{\"price\":79325.4,\"qty\":0.06045261},{\"price\":79322.1,\"qty\":0.00006803},{\"price\":79316.0,\"qty\":0.00006803},{\"price\":79312.6,\"qty\":0.10643220},{\"price\":79310.0,\"qty\":0.00006803},{\"price\":79308.8,\"qty\":0.01970743},{\"price\":79305.2,\"qty\":4.41332566},{\"price\":79304.8,\"qty\":0.12516368},{\"price\":79304.0,\"qty\":0.00006803},{\"price\":79303.4,\"qty\":0.00604988},{\"price\":79302.0,\"qty\":9.45750580},{\"price\":79300.0,\"qty\":0.00166963},{\"price\":79298.6,\"qty\":0.00021729},{\"price\":79298.4,\"qty\":0.03284239},{\"price\":79298.0,\"qty\":0.00006803},{\"price\":79292.0,\"qty\":0.00006803},{\"price\":79290.6,\"qty\":0.00210523},{\"price\":79288.5,\"qty\":4.41425702},{\"price\":79286.5,\"qty\":0.00011000},{\"price\":79285.9,\"qty\":0.00006803},{\"price\":79279.9,\"qty\":0.00006803},{\"price\":79274.6,\"qty\":4.41502852},{\"price\":79273.0,\"qty\":0.02202500},{\"price\":79271.3,\"qty\":1.81415787},{\"price\":79271.2,\"qty\":0.73156231},{\"price\":79266.4,\"qty\":0.02202500},{\"price\":79263.4,\"qty\":16.22006513},{\"price\":79259.4,\"qty\":25.23358757},{\"price\":79254.1,\"qty\":0.12516368},{\"price\":79250.0,\"qty\":0.30738234},{\"price\":79241.3,\"qty\":0.25239363},{\"price\":79229.6,\"qty\":1.72055205},{\"price\":79220.7,\"qty\":0.00005000},{\"price\":79208.9,\"qty\":0.02500000},{\"price\":79205.0,\"qty\":0.00019703},{\"price\":79200.0,\"qty\":0.01020900},{\"price\":79199.5,\"qty\":0.14000000},{\"price\":79184.9,\"qty\":3.57182000},{\"price\":79183.9,\"qty\":0.02500000},{\"price\":79172.2,\"qty\":0.00226858},{\"price\":79172.1,\"qty\":0.00011000},{\"price\":79162.9,\"qty\":0.00599796},{\"price\":79159.0,\"qty\":0.02500000},{\"price\":79150.1,\"qty\":0.00134550},{\"price\":79144.2,\"qty\":12.54132527},{\"price\":79138.2,\"qty\":0.50544490},{\"price\":79137.2,\"qty\":0.00200000},{\"price\":79120.1,\"qty\":0.00240694},{\"price\":79120.0,\"qty\":0.58778812},{\"price\":79111.4,\"qty\":0.00017867},{\"price\":79100.0,\"qty\":1.09292036},{\"price\":79095.7,\"qty\":0.03501443},{\"price\":79093.5,\"qty\":0.00005000},{\"price\":79092.5,\"qty\":1.23773996},{\"price\":79091.8,\"qty\":4.42523553},{\"price\":79081.0,\"qty\":0.30642105},{\"price\":79077.1,\"qty\":0.12645887},{\"price\":79058.0,\"qty\":0.00200000},{\"price\":79057.8,\"qty\":0.00011000},{\"price\":79055.3,\"qty\":0.00014255},{\"price\":79051.3,\"qty\":0.02081150},{\"price\":79051.2,\"qty\":0.27138320},{\"price\":79050.0,\"qty\":0.00100000},{\"price\":79043.7,\"qty\":0.01975570},{\"price\":79034.2,\"qty\":0.01975879},{\"price\":79028.8,\"qty\":0.35018271},{\"price\":79025.7,\"qty\":0.23769319},{\"price\":79024.9,\"qty\":2.11645000},{\"price\":79024.7,\"qty\":0.01976188},{\"price\":79017.9,\"qty\":0.00016201},{\"price\":79015.2,\"qty\":0.01976497},{\"price\":79011.0,\"qty\":0.51317872},{\"price\":79005.8,\"qty\":0.01955995},{\"price\":79005.0,\"qty\":10.00005000},{\"price\":79000.6,\"qty\":0.00047417},{\"price\":79000.1,\"qty\":0.10000000},{\"price\":79000.0,\"qty\":2.93148882},{\"price\":78999.9,\"qty\":0.00315190},{\"price\":78999.0,\"qty\":0.06341852},{\"price\":78996.3,\"qty\":0.05772383},{\"price\":78995.9,\"qty\":0.00126576},{\"price\":78990.0,\"qty\":0.00496894},{\"price\":78986.8,\"qty\":0.01977421},{\"price\":78984.6,\"qty\":0.00063303},{\"price\":78983.4,\"qty\":0.00005761},{\"price\":78980.4,\"qty\":0.42791797},{\"price\":78980.2,\"qty\":0.00206126},{\"price\":78980.0,\"qty\":0.02658470},{\"price\":78977.3,\"qty\":0.01977730},{\"price\":78977.2,\"qty\":0.50000000},{\"price\":78975.0,\"qty\":0.06331118},{\"price\":78973.5,\"qty\":0.00500000},{\"price\":78971.5,\"qty\":0.00063313},{\"price\":78969.3,\"qty\":0.39621630},{\"price\":78968.0,\"qty\":0.02500000},{\"price\":78967.9,\"qty\":0.02604745},{\"price\":78966.4,\"qty\":0.00005000},{\"price\":78963.0,\"qty\":0.00063320},{\"price\":78961.3,\"qty\":0.00070540},{\"price\":78960.5,\"qty\":0.00659800},{\"price\":78960.0,\"qty\":0.00031661},{\"price\":78958.4,\"qty\":0.01978346},{\"price\":78950.0,\"qty\":0.15000000},{\"price\":78948.9,\"qty\":0.01978655},{\"price\":78944.9,\"qty\":0.00005793},{\"price\":78943.8,\"qty\":0.00012000},{\"price\":78942.0,\"qty\":0.00012668},{\"price\":78940.9,\"qty\":0.00059538},{\"price\":78939.9,\"qty\":0.81710669},{\"price\":78939.4,\"qty\":0.01978965},{\"price\":78937.3,\"qty\":0.00253366},{\"price\":78930.0,\"qty\":0.01958438},{\"price\":78924.6,\"qty\":0.00014691},{\"price\":78920.5,\"qty\":0.01979581},{\"price\":78919.7,\"qty\":0.00633556},{\"price\":78916.6,\"qty\":0.04000000},{\"price\":78914.6,\"qty\":0.00014004},{\"price\":78913.5,\"qty\":0.00012671},{\"price\":78911.0,\"qty\":0.01979891},{\"price\":78910.0,\"qty\":0.02000000},{\"price\":78909.0,\"qty\":0.01267282},{\"price\":78905.0,\"qty\":0.00050000},{\"price\":78901.2,\"qty\":0.99364819},{\"price\":78901.1,\"qty\":0.00021213},{\"price\":78900.0,\"qty\":0.28259324},{\"price\":78899.0,\"qty\":0.26548257},{\"price\":78896.0,\"qty\":0.00017745},{\"price\":78891.8,\"qty\":0.00050701},{\"price\":78891.5,\"qty\":0.00007606},{\"price\":78890.0,\"qty\":0.00633793},{\"price\":78889.0,\"qty\":0.00006338},{\"price\":78888.0,\"qty\":0.07534647},{\"price\":78886.5,\"qty\":0.00009201},{\"price\":78886.4,\"qty\":0.00025353},{\"price\":78885.1,\"qty\":0.00306776},{\"price\":78881.0,\"qty\":0.10000000},{\"price\":78879.5,\"qty\":0.74000000},{\"price\":78877.2,\"qty\":0.00633897},{\"price\":78875.0,\"qty\":0.01440000},{\"price\":78871.2,\"qty\":1.00000000},{\"price\":78868.0,\"qty\":0.00050717},{\"price\":78859.9,\"qty\":0.00005045},{\"price\":78855.0,\"qty\":0.10000000},{\"price\":78852.9,\"qty\":0.00167539},{\"price\":78851.0,\"qty\":0.00031705},{\"price\":78850.0,\"qty\":0.00430470},{\"price\":78847.4,\"qty\":0.00100000},{\"price\":78840.2,\"qty\":0.00534035},{\"price\":78839.2,\"qty\":0.00006000},{\"price\":78831.3,\"qty\":0.00013322},{\"price\":78829.8,\"qty\":0.00012000},{\"price\":78827.9,\"qty\":4.44004885},{\"price\":78826.3,\"qty\":1.06351000},{\"price\":78823.7,\"qty\":0.01268654},{\"price\":78823.4,\"qty\":0.00874176},{\"price\":78822.9,\"qty\":0.00022810},{\"price\":78822.3,\"qty\":0.00200000},{\"price\":78820.6,\"qty\":0.00025374},{\"price\":78819.3,\"qty\":0.00100000},{\"price\":78818.0,\"qty\":0.02011194},{\"price\":78815.9,\"qty\":0.00055828},{\"price\":78814.2,\"qty\":0.01386425},{\"price\":78805.9,\"qty\":0.00047184},{\"price\":78800.0,\"qty\":0.06478392},{\"price\":78791.0,\"qty\":0.00317296},{\"price\":78790.0,\"qty\":0.06345983},{\"price\":78781.6,\"qty\":0.00248471},{\"price\":78780.0,\"qty\":0.01269358},{\"price\":78777.0,\"qty\":0.00300000},{\"price\":78773.6,\"qty\":0.00005776},{\"price\":78773.0,\"qty\":0.00140733},{\"price\":78772.0,\"qty\":0.00445323},{\"price\":78770.6,\"qty\":0.00012616},{\"price\":78768.8,\"qty\":0.00304688},{\"price\":78759.0,\"qty\":0.15000000},{\"price\":78757.0,\"qty\":0.99038816},{\"price\":78754.0,\"qty\":0.00800000},{\"price\":78751.1,\"qty\":0.05219595},{\"price\":78750.1,\"qty\":0.27243126},{\"price\":78750.0,\"qty\":2.27159898},{\"price\":78749.0,\"qty\":0.00005079},{\"price\":78748.2,\"qty\":0.00005808},{\"price\":78747.0,\"qty\":0.00126988},{\"price\":78743.5,\"qty\":0.00200000},{\"price\":78738.2,\"qty\":0.00012080},{\"price\":78736.0,\"qty\":0.00086491},{\"price\":78724.5,\"qty\":0.00025405},{\"price\":78716.1,\"qty\":0.00012000},{\"price\":78713.3,\"qty\":0.01270434},{\"price\":78711.0,\"qty\":0.00649441},{\"price\":78710.4,\"qty\":0.01270480},{\"price\":78710.0,\"qty\":0.00635243},{\"price\":78707.9,\"qty\":0.00008964},{\"price\":78703.9,\"qty\":0.00010164},{\"price\":78700.0,\"qty\":3.99143137},{\"price\":78694.0,\"qty\":0.00254148},{\"price\":78690.9,\"qty\":0.00177021},{\"price\":78688.3,\"qty\":0.00009225},{\"price\":78688.2,\"qty\":0.00006000},{\"price\":78681.6,\"qty\":0.00032112},{\"price\":78680.0,\"qty\":0.00100000},{\"price\":78675.7,\"qty\":0.07281262},{\"price\":78664.8,\"qty\":0.00200000},{\"price\":78655.0,\"qty\":0.00019071},{\"price\":78654.7,\"qty\":0.00063568},{\"price\":78650.0,\"qty\":0.02034327},{\"price\":78645.2,\"qty\":0.00010954},{\"price\":78640.0,\"qty\":1.00000000},{\"price\":78636.3,\"qty\":0.00127168},{\"price\":78635.0,\"qty\":0.00095377},{\"price\":78634.5,\"qty\":0.00635854},{\"price\":78633.8,\"qty\":0.00254343},{\"price\":78633.1,\"qty\":0.00007732},{\"price\":78632.3,\"qty\":0.00008043},{\"price\":78632.2,\"qty\":0.00508698},{\"price\":78631.2,\"qty\":0.00142056},{\"price\":78621.8,\"qty\":0.69594000},{\"price\":78619.4,\"qty\":0.00138239},{\"price\":78619.1,\"qty\":0.00350000},{\"price\":78619.0,\"qty\":0.00127195},{\"price\":78612.0,\"qty\":0.00005000},{\"price\":78606.0,\"qty\":0.00040000},{\"price\":78603.3,\"qty\":0.00010601},{\"price\":78602.5,\"qty\":0.00012000},{\"price\":78600.6,\"qty\":0.00031807},{\"price\":78600.0,\"qty\":1.06105125},{\"price\":78598.8,\"qty\":0.00031807},{\"price\":78597.0,\"qty\":0.00022875},{\"price\":78595.4,\"qty\":1.80000000},{\"price\":78591.3,\"qty\":0.00010603},{\"price\":78589.5,\"qty\":0.00009700},{\"price\":78586.1,\"qty\":0.00200000},{\"price\":78585.8,\"qty\":0.00189601},{\"price\":78584.8,\"qty\":0.25000000},{\"price\":78583.3,\"qty\":0.00098366},{\"price\":78579.4,\"qty\":0.00010604},{\"price\":78577.0,\"qty\":0.00064904},{\"price\":78572.4,\"qty\":0.00059900},{\"price\":78568.2,\"qty\":0.00009553},{\"price\":78564.4,\"qty\":0.00005792},{\"price\":78564.3,\"qty\":0.00636422},{\"price\":78562.5,\"qty\":0.00112240},{\"price\":78559.4,\"qty\":0.00038188},{\"price\":78559.0,\"qty\":0.02500000},{\"price\":78558.0,\"qty\":0.00636473},{\"price\":78556.0,\"qty\":0.00139060},{\"price\":78555.0,\"qty\":0.00259599},{\"price\":78553.2,\"qty\":0.02403654},{\"price\":78552.3,\"qty\":0.00038412},{\"price\":78552.0,\"qty\":0.00005822},{\"price\":78550.6,\"qty\":0.00031827},{\"price\":78547.0,\"qty\":0.01273124},{\"price\":78546.0,\"qty\":0.00171500},{\"price\":78540.1,\"qty\":0.00033598},{\"price\":78537.3,\"qty\":0.00130000},{\"price\":78537.2,\"qty\":0.00006000},{\"price\":78533.3,\"qty\":0.00038014},{\"price\":78531.5,\"qty\":0.01951917},{\"price\":78521.2,\"qty\":0.00005000},{\"price\":78513.7,\"qty\":0.60000000},{\"price\":78508.5,\"qty\":0.00025475},{\"price\":78507.1,\"qty\":0.00199001},{\"price\":78507.0,\"qty\":0.00641980},{\"price\":78505.9,\"qty\":0.00142282},{\"price\":78501.0,\"qty\":0.03008267},{\"price\":78500.6,\"qty\":0.00031847},{\"price\":78500.1,\"qty\":0.10000000},{\"price\":78500.0,\"qty\":1.03734035},{\"price\":78493.7,\"qty\":0.00031696},{\"price\":78490.6,\"qty\":0.00009248},{\"price\":78490.5,\"qty\":0.00244100},{\"price\":78489.1,\"qty\":0.00012000},{\"price\":78486.5,\"qty\":0.01000000},{\"price\":78479.2,\"qty\":0.00736105},{\"price\":78473.0,\"qty\":0.00800000},{\"price\":78458.2,\"qty\":0.00006554},{\"price\":78454.0,\"qty\":0.14285714},{\"price\":78450.6,\"qty\":0.00031868},{\"price\":78437.7,\"qty\":0.00204000},{\"price\":78433.3,\"qty\":0.00045899},{\"price\":78432.8,\"qty\":0.00045899},{\"price\":78432.0,\"qty\":0.60000000},{\"price\":78431.1,\"qty\":0.00045900},{\"price\":78428.5,\"qty\":0.00025500},{\"price\":78419.0,\"qty\":0.00536904},{\"price\":78417.1,\"qty\":0.00045908},{\"price\":78415.8,\"qty\":0.20000000},{\"price\":78411.9,\"qty\":0.00009309},{\"price\":78411.8,\"qty\":0.00038015},{\"price\":78410.0,\"qty\":0.05000000},{\"price\":78400.6,\"qty\":0.00031888},{\"price\":78400.0,\"qty\":0.06614732},{\"price\":78396.9,\"qty\":0.00637781},{\"price\":78395.5,\"qty\":0.00095324},{\"price\":78393.4,\"qty\":0.00129947},{\"price\":78391.7,\"qty\":0.00183006},{\"price\":78390.0,\"qty\":0.15000000},{\"price\":78386.2,\"qty\":0.00008000},{\"price\":78383.8,\"qty\":0.00005076},{\"price\":78383.6,\"qty\":0.00063788},{\"price\":78378.2,\"qty\":0.00012679},{\"price\":78375.8,\"qty\":0.00012000},{\"price\":78374.9,\"qty\":0.00022679},{\"price\":78373.2,\"qty\":0.04465812},{\"price\":78371.8,\"qty\":0.00022941},{\"price\":78369.0,\"qty\":0.00081320},{\"price\":78360.0,\"qty\":0.02552322},{\"price\":78359.0,\"qty\":0.04973949},{\"price\":78356.2,\"qty\":0.00005837},{\"price\":78355.7,\"qty\":0.00005807},{\"price\":78350.6,\"qty\":0.00031908},{\"price\":78350.0,\"qty\":0.01276324},{\"price\":78349.8,\"qty\":0.00193500},{\"price\":78347.6,\"qty\":0.00040104},{\"price\":78347.4,\"qty\":0.00063818},{\"price\":78328.9,\"qty\":0.00204027},{\"price\":78327.1,\"qty\":0.00028087},{\"price\":78327.0,\"qty\":0.00074022},{\"price\":78315.0,\"qty\":0.00005000},{\"price\":78312.2,\"qty\":0.00025539},{\"price\":78300.6,\"qty\":0.00031929},{\"price\":78300.0,\"qty\":0.15835558},{\"price\":78298.6,\"qty\":0.00326570},{\"price\":78298.2,\"qty\":0.00384031},{\"price\":78297.5,\"qty\":0.00246900},{\"price\":78293.4,\"qty\":0.00009271},{\"price\":78293.1,\"qty\":0.00314433},{\"price\":78292.5,\"qty\":0.00638631},{\"price\":78288.6,\"qty\":0.00012774},{\"price\":78281.4,\"qty\":0.05250914},{\"price\":78279.2,\"qty\":0.00264284},{\"price\":78277.8,\"qty\":0.00149008},{\"price\":78266.7,\"qty\":0.00031942},{\"price\":78265.6,\"qty\":0.00070905},{\"price\":78264.8,\"qty\":0.00095171},{\"price\":78262.7,\"qty\":0.00012000},{\"price\":78258.2,\"qty\":3.17007410},{\"price\":78257.0,\"qty\":0.03961307},{\"price\":78256.2,\"qty\":0.00852489},{\"price\":78250.6,\"qty\":0.00031949},{\"price\":78250.0,\"qty\":0.00658148},{\"price\":78247.7,\"qty\":0.00155787},{\"price\":78240.7,\"qty\":0.00103278},{\"price\":78233.3,\"qty\":1.00000000},{\"price\":78232.7,\"qty\":0.01111262},{\"price\":78229.9,\"qty\":0.00386004},{\"price\":78226.2,\"qty\":0.00653668},{\"price\":78225.9,\"qty\":0.00006391},{\"price\":78224.7,\"qty\":0.35749000},{\"price\":78224.2,\"qty\":0.11919209},{\"price\":78223.7,\"qty\":0.04474347},{\"price\":78222.3,\"qty\":0.00138941},{\"price\":78222.0,\"qty\":0.01924560},{\"price\":78219.3,\"qty\":0.00008000},{\"price\":78217.0,\"qty\":0.00137232},{\"price\":78215.4,\"qty\":0.00498621},{\"price\":78211.2,\"qty\":0.00350000},{\"price\":78210.0,\"qty\":0.10276396},{\"price\":78201.8,\"qty\":0.00010114},{\"price\":78200.6,\"qty\":0.00031970},{\"price\":78200.0,\"qty\":0.35148792},{\"price\":78191.6,\"qty\":0.00034609},{\"price\":78188.5,\"qty\":0.05678441},{\"price\":78182.5,\"qty\":0.14409888},{\"price\":78178.7,\"qty\":0.00537231},{\"price\":78177.2,\"qty\":0.00048721},{\"price\":78169.3,\"qty\":0.00063963},{\"price\":78165.1,\"qty\":0.01612878},{\"price\":78160.9,\"qty\":0.00005851},{\"price\":78156.9,\"qty\":0.00071266},{\"price\":78156.0,\"qty\":0.50000000},{\"price\":78155.7,\"qty\":0.00009027},{\"price\":78152.0,\"qty\":0.02822040},{\"price\":78150.6,\"qty\":0.00031990},{\"price\":78150.0,\"qty\":0.00704708},{\"price\":78149.8,\"qty\":0.00012000},{\"price\":78147.6,\"qty\":0.00005823},{\"price\":78147.2,\"qty\":0.04085127},{\"price\":78146.8,\"qty\":0.00147795},{\"price\":78143.0,\"qty\":0.02028566},{\"price\":78139.4,\"qty\":0.03701525},{\"price\":78130.3,\"qty\":0.00039075},{\"price\":78124.8,\"qty\":0.00307200},{\"price\":78123.0,\"qty\":0.50000000},{\"price\":78121.1,\"qty\":0.08025553},{\"price\":78121.0,\"qty\":0.00320017},{\"price\":78120.8,\"qty\":0.00255527},{\"price\":78119.9,\"qty\":0.00021425},{\"price\":78116.4,\"qty\":0.00025603},{\"price\":78116.0,\"qty\":0.00050000},{\"price\":78115.3,\"qty\":0.00025603},{\"price\":78111.0,\"qty\":0.03038406},{\"price\":78108.0,\"qty\":0.00195306},{\"price\":78104.0,\"qty\":3.93937011},{\"price\":78101.0,\"qty\":0.01318805},{\"price\":78100.6,\"qty\":0.00032010},{\"price\":78100.0,\"qty\":10.21988583},{\"price\":78096.7,\"qty\":0.00009295},{\"price\":78095.9,\"qty\":0.00064023},{\"price\":78085.7,\"qty\":0.00015502},{\"price\":78072.7,\"qty\":0.00014155},{\"price\":78069.3,\"qty\":0.00064046},{\"price\":78060.0,\"qty\":0.00102485},{\"price\":78052.4,\"qty\":0.00008000},{\"price\":78050.6,\"qty\":0.00032031},{\"price\":78050.0,\"qty\":0.01250595},{\"price\":78048.9,\"qty\":0.00130000},{\"price\":78038.3,\"qty\":0.00025628},{\"price\":78037.0,\"qty\":0.00013000},{\"price\":78033.0,\"qty\":0.04485281},{\"price\":78027.5,\"qty\":0.00123032},{\"price\":78025.0,\"qty\":0.12816405},{\"price\":78019.6,\"qty\":0.00038206},{\"price\":78017.0,\"qty\":0.01281772},{\"price\":78014.0,\"qty\":0.00634502},{\"price\":78010.9,\"qty\":0.00094400},{\"price\":78010.0,\"qty\":0.10956159},{\"price\":78009.6,\"qty\":0.00833230},{\"price\":78006.5,\"qty\":0.00538417},{\"price\":78005.0,\"qty\":0.06409846},{\"price\":78003.9,\"qty\":0.00009019},{\"price\":78003.6,\"qty\":0.00256399},{\"price\":78000.6,\"qty\":0.00080077},{\"price\":78000.1,\"qty\":0.10000000},{\"price\":78000.0,\"qty\":3.99990136},{\"price\":77997.4,\"qty\":0.00051187},{\"price\":77997.0,\"qty\":0.00383092},{\"price\":77989.0,\"qty\":0.10000000},{\"price\":77987.7,\"qty\":0.00276938},{\"price\":77986.1,\"qty\":0.00018430},{\"price\":77982.8,\"qty\":0.00362000},{\"price\":77980.0,\"qty\":0.00100000},{\"price\":77978.0,\"qty\":0.00120931},{\"price\":77974.0,\"qty\":0.01709392},{\"price\":77966.1,\"qty\":0.00005866},{\"price\":77964.9,\"qty\":0.01282628},{\"price\":77963.0,\"qty\":0.00064133},{\"price\":77950.6,\"qty\":0.00032072},{\"price\":77950.0,\"qty\":6.08204924},{\"price\":77949.5,\"qty\":0.00326000},{\"price\":77947.0,\"qty\":0.00064146},{\"price\":77945.5,\"qty\":0.01373500},{\"price\":77941.7,\"qty\":0.00006404},{\"price\":77940.1,\"qty\":0.00005838},{\"price\":77934.4,\"qty\":0.00105856},{\"price\":77933.2,\"qty\":0.01454004},{\"price\":77929.4,\"qty\":0.00050484},{\"price\":77926.9,\"qty\":0.01597651},{\"price\":77926.2,\"qty\":0.00257455},{\"price\":77924.4,\"qty\":0.00013000},{\"price\":77923.2,\"qty\":0.00023073},{\"price\":77921.2,\"qty\":0.00136549},{\"price\":77920.4,\"qty\":0.01000000},{\"price\":77912.0,\"qty\":0.00132971},{\"price\":77910.0,\"qty\":0.00060000},{\"price\":77907.8,\"qty\":0.00005107},{\"price\":77907.0,\"qty\":0.00025672},{\"price\":77905.4,\"qty\":0.03000000},{\"price\":77900.6,\"qty\":0.00032093},{\"price\":77900.5,\"qty\":0.01293006},{\"price\":77900.3,\"qty\":0.00005000},{\"price\":77900.0,\"qty\":0.05407015},{\"price\":77898.7,\"qty\":0.00156400},{\"price\":77894.7,\"qty\":0.00012674},{\"price\":77894.5,\"qty\":0.00039809},{\"price\":77890.0,\"qty\":0.00175953},{\"price\":77888.0,\"qty\":0.03851684},{\"price\":77887.2,\"qty\":0.00178848},{\"price\":77884.0,\"qty\":0.00025807},{\"price\":77877.1,\"qty\":0.00064203},{\"price\":77875.0,\"qty\":0.00070796},{\"price\":77872.0,\"qty\":1.00000000},{\"price\":77869.3,\"qty\":0.00064211},{\"price\":77868.6,\"qty\":0.00255224},{\"price\":77865.1,\"qty\":0.00009639},{\"price\":77855.0,\"qty\":0.00100000},{\"price\":77850.6,\"qty\":0.00032113},{\"price\":77850.0,\"qty\":0.10276173},{\"price\":77842.3,\"qty\":0.00159025},{\"price\":77840.0,\"qty\":0.02569373},{\"price\":77835.6,\"qty\":0.00030400},{\"price\":77830.5,\"qty\":0.06424216},{\"price\":77830.0,\"qty\":0.03212128},{\"price\":77826.0,\"qty\":0.00539666},{\"price\":77819.8,\"qty\":0.00311700},{\"price\":77818.2,\"qty\":0.00007402},{\"price\":77814.5,\"qty\":0.05282420},{\"price\":77813.5,\"qty\":0.00034260},{\"price\":77813.1,\"qty\":0.00015421},{\"price\":77812.0,\"qty\":0.00013000},{\"price\":77810.0,\"qty\":0.05000000},{\"price\":77805.5,\"qty\":0.15294548},{\"price\":77805.4,\"qty\":0.00350000},{\"price\":77803.5,\"qty\":0.00192793},{\"price\":77803.2,\"qty\":0.00006126},{\"price\":77800.6,\"qty\":0.00032134},{\"price\":77800.0,\"qty\":0.24086912},{\"price\":77797.2,\"qty\":0.00087535},{\"price\":77796.1,\"qty\":0.00036971},{\"price\":77789.2,\"qty\":0.01928289},{\"price\":77788.0,\"qty\":0.01671208},{\"price\":77785.9,\"qty\":0.00064279},{\"price\":77785.1,\"qty\":0.00006416},{\"price\":77784.2,\"qty\":0.00660943},{\"price\":77782.8,\"qty\":0.00064281},{\"price\":77779.2,\"qty\":0.00025713},{\"price\":77777.8,\"qty\":0.00234450},{\"price\":77777.7,\"qty\":0.03214288},{\"price\":77777.3,\"qty\":0.02437073},{\"price\":77777.0,\"qty\":0.03628322},{\"price\":77776.0,\"qty\":0.00127738},{\"price\":77771.8,\"qty\":0.00005881},{\"price\":77769.3,\"qty\":0.00064293},{\"price\":77763.5,\"qty\":0.04500826},{\"price\":77757.0,\"qty\":0.04115386},{\"price\":77755.3,\"qty\":0.00257218},{\"price\":77754.1,\"qty\":0.00900274},{\"price\":77754.0,\"qty\":0.01080329},{\"price\":77752.9,\"qty\":0.01575503},{\"price\":77750.6,\"qty\":0.00032155},{\"price\":77750.0,\"qty\":0.00147911},{\"price\":77748.4,\"qty\":0.00225084},{\"price\":77744.4,\"qty\":0.00360154},{\"price\":77744.3,\"qty\":0.00108046},{\"price\":77744.2,\"qty\":0.01080465},{\"price\":77742.6,\"qty\":0.15108942},{\"price\":77741.6,\"qty\":0.01445862},{\"price\":77740.7,\"qty\":0.01639035},{\"price\":77740.6,\"qty\":0.03511266},{\"price\":77740.5,\"qty\":0.01733019},{\"price\":77740.0,\"qty\":0.00643169},{\"price\":77739.1,\"qty\":0.00735904},{\"price\":77738.8,\"qty\":0.00360180},{\"price\":77736.5,\"qty\":0.00225119},{\"price\":77736.3,\"qty\":0.02305160},{\"price\":77733.2,\"qty\":0.08154984},{\"price\":77733.1,\"qty\":0.00005854},{\"price\":77731.7,\"qty\":0.00452750},{\"price\":77731.6,\"qty\":0.02750047},{\"price\":77729.6,\"qty\":0.01808141},{\"price\":77728.8,\"qty\":0.00184306},{\"price\":77728.7,\"qty\":0.00225141},{\"price\":77727.5,\"qty\":0.00450290},{\"price\":77726.3,\"qty\":0.00025731},{\"price\":77725.1,\"qty\":0.00093080},{\"price\":77724.6,\"qty\":0.00364044},{\"price\":77722.3,\"qty\":0.01808683},{\"price\":77718.3,\"qty\":0.00450344},{\"price\":77718.2,\"qty\":0.01007998},{\"price\":77716.9,\"qty\":0.00450352},{\"price\":77716.8,\"qty\":0.00241563},{\"price\":77716.0,\"qty\":0.00199444},{\"price\":77711.2,\"qty\":0.00099470},{\"price\":77707.7,\"qty\":0.70508442},{\"price\":77704.9,\"qty\":0.00900843},{\"price\":77704.8,\"qty\":0.00009341},{\"price\":77703.9,\"qty\":0.00997227},{\"price\":77702.7,\"qty\":0.02573913},{\"price\":77701.0,\"qty\":20.00000000},{\"price\":77700.9,\"qty\":31.96267580},{\"price\":77700.8,\"qty\":0.00225222},{\"price\":77700.6,\"qty\":0.00032175},{\"price\":77700.0,\"qty\":0.95937946},{\"price\":77699.9,\"qty\":0.00023139},{\"price\":77699.7,\"qty\":0.00013000},{\"price\":77699.1,\"qty\":0.00575298},{\"price\":77698.8,\"qty\":0.00119579},{\"price\":77696.1,\"qty\":0.00192636},{\"price\":77695.9,\"qty\":0.00189085},{\"price\":77695.3,\"qty\":0.00046335},{\"price\":77694.2,\"qty\":0.30000000},{\"price\":77693.4,\"qty\":0.06667672},{\"price\":77693.0,\"qty\":0.00064356},{\"price\":77691.9,\"qty\":0.00749479},{\"price\":77691.4,\"qty\":0.00499428},{\"price\":77689.9,\"qty\":0.00272558},{\"price\":77683.1,\"qty\":0.00225274},{\"price\":77676.6,\"qty\":0.02252930},{\"price\":77675.0,\"qty\":0.05328599},{\"price\":77673.6,\"qty\":0.00368347},{\"price\":77671.7,\"qty\":0.00180245},{\"price\":77671.6,\"qty\":0.05482311},{\"price\":77671.5,\"qty\":0.00666301},{\"price\":77671.0,\"qty\":0.00007827},{\"price\":77670.0,\"qty\":0.00672684},{\"price\":77668.5,\"qty\":0.32765182},{\"price\":77666.0,\"qty\":0.01287564},{\"price\":77664.1,\"qty\":0.00006428},{\"price\":77661.1,\"qty\":0.00204000},{\"price\":77660.5,\"qty\":0.14481942},{\"price\":77659.6,\"qty\":0.00022888},{\"price\":77657.4,\"qty\":0.02247030},{\"price\":77657.1,\"qty\":0.00812364},{\"price\":77656.8,\"qty\":0.00579471},{\"price\":77656.0,\"qty\":0.00643866},{\"price\":77654.9,\"qty\":0.00032193},{\"price\":77653.9,\"qty\":0.00670901},{\"price\":77653.2,\"qty\":0.00887349},{\"price\":77650.8,\"qty\":0.00063753},{\"price\":77650.6,\"qty\":0.00032196},{\"price\":77650.0,\"qty\":0.45334075},{\"price\":77648.7,\"qty\":0.00901494},{\"price\":77648.5,\"qty\":0.02259971},{\"price\":77647.2,\"qty\":0.00636301},{\"price\":77644.2,\"qty\":0.00009061},{\"price\":77641.8,\"qty\":0.01803809},{\"price\":77639.0,\"qty\":0.00064401},{\"price\":77636.3,\"qty\":0.00228656},{\"price\":77636.0,\"qty\":0.00210153},{\"price\":77630.8,\"qty\":0.00180340},{\"price\":77630.7,\"qty\":0.00737387},{\"price\":77629.4,\"qty\":0.00038398},{\"price\":77629.1,\"qty\":0.35140000},{\"price\":77627.7,\"qty\":0.00013318},{\"price\":77618.7,\"qty\":0.00090184},{\"price\":77618.6,\"qty\":0.00090184},{\"price\":77617.1,\"qty\":0.00876100},{\"price\":77615.0,\"qty\":0.00005063},{\"price\":77612.2,\"qty\":0.03540297},{\"price\":77610.8,\"qty\":0.00157983},{\"price\":77610.7,\"qty\":0.00901937},{\"price\":77610.0,\"qty\":0.02607554},{\"price\":77608.3,\"qty\":0.00450982},{\"price\":77607.4,\"qty\":0.00009091},{\"price\":77602.8,\"qty\":0.07183620},{\"price\":77600.7,\"qty\":0.00875100},{\"price\":77600.6,\"qty\":0.00032217},{\"price\":77600.0,\"qty\":0.87779142},{\"price\":77599.2,\"qty\":0.00012806},{\"price\":77597.2,\"qty\":0.00563808},{\"price\":77596.0,\"qty\":0.00816800},{\"price\":77591.8,\"qty\":0.01466005},{\"price\":77590.4,\"qty\":0.00208200},{\"price\":77588.7,\"qty\":0.00084355},{\"price\":77587.6,\"qty\":0.00013000},{\"price\":77586.1,\"qty\":0.33496335},{\"price\":77581.1,\"qty\":0.00106429},{\"price\":77580.4,\"qty\":0.00451144},{\"price\":77580.0,\"qty\":0.32209963},{\"price\":77579.0,\"qty\":0.00078278},{\"price\":77578.0,\"qty\":0.00005895},{\"price\":77575.0,\"qty\":0.19336127},{\"price\":77573.7,\"qty\":0.00128909},{\"price\":77572.3,\"qty\":0.00096683},{\"price\":77569.3,\"qty\":0.00064459},{\"price\":77562.9,\"qty\":0.00006438},{\"price\":77559.0,\"qty\":0.01051418},{\"price\":77558.0,\"qty\":0.00451275},{\"price\":77557.9,\"qty\":0.00451275},{\"price\":77556.2,\"qty\":0.00077361},{\"price\":77550.6,\"qty\":0.00032238},{\"price\":77550.1,\"qty\":0.00012894},{\"price\":77550.0,\"qty\":0.52270999},{\"price\":77544.9,\"qty\":0.00261200},{\"price\":77544.8,\"qty\":0.01707129},{\"price\":77543.1,\"qty\":0.00453830},{\"price\":77542.0,\"qty\":0.00428799},{\"price\":77537.7,\"qty\":0.00402335},{\"price\":77535.0,\"qty\":0.02558069},{\"price\":77532.0,\"qty\":0.00025796},{\"price\":77531.0,\"qty\":0.00644890},{\"price\":77529.6,\"qty\":0.00064491},{\"price\":77514.2,\"qty\":0.00451530},{\"price\":77510.8,\"qty\":0.00025802},{\"price\":77509.6,\"qty\":0.00009365},{\"price\":77507.7,\"qty\":0.00006442},{\"price\":77502.3,\"qty\":0.00124925},{\"price\":77500.6,\"qty\":0.00032258},{\"price\":77500.5,\"qty\":0.00800000},{\"price\":77500.1,\"qty\":0.10000000},{\"price\":77500.0,\"qty\":12.20556770},{\"price\":77494.6,\"qty\":0.00082651},{\"price\":77491.9,\"qty\":0.00046710},{\"price\":77491.5,\"qty\":0.00659866},{\"price\":77490.6,\"qty\":0.00225833},{\"price\":77482.0,\"qty\":0.01355153},{\"price\":77481.1,\"qty\":0.01806892},{\"price\":77477.2,\"qty\":0.00023206},{\"price\":77475.6,\"qty\":0.00013000},{\"price\":77473.7,\"qty\":0.02046091},{\"price\":77471.0,\"qty\":0.10859548},{\"price\":77470.5,\"qty\":0.00108600},{\"price\":77468.5,\"qty\":0.00451796},{\"price\":77462.0,\"qty\":0.00050000},{\"price\":77461.0,\"qty\":0.00032274},{\"price\":77459.9,\"qty\":0.00157371},{\"price\":77455.1,\"qty\":0.00122500},{\"price\":77451.9,\"qty\":0.00161390},{\"price\":77450.6,\"qty\":0.00032279},{\"price\":77450.0,\"qty\":0.00010073},{\"price\":77448.6,\"qty\":0.00034838},{\"price\":77447.9,\"qty\":0.00306833},{\"price\":77438.1,\"qty\":0.00064567},{\"price\":77434.4,\"qty\":0.00032285},{\"price\":77431.8,\"qty\":0.00005138},{\"price\":77429.7,\"qty\":0.00046511},{\"price\":77424.8,\"qty\":0.00069499},{\"price\":77423.4,\"qty\":0.00648588},{\"price\":77421.3,\"qty\":0.00226035},{\"price\":77420.2,\"qty\":0.00129165},{\"price\":77417.0,\"qty\":0.00645853},{\"price\":77401.6,\"qty\":0.00350000},{\"price\":77400.6,\"qty\":0.00032300},{\"price\":77400.0,\"qty\":0.00258398},{\"price\":77398.1,\"qty\":0.00035982},{\"price\":77396.0,\"qty\":0.00064603},{\"price\":77384.7,\"qty\":0.00005910},{\"price\":77380.0,\"qty\":0.00100000},{\"price\":77373.9,\"qty\":0.00038412},{\"price\":77371.3,\"qty\":0.00645589},{\"price\":77370.0,\"qty\":0.67850000},{\"price\":77369.0,\"qty\":0.00064626},{\"price\":77363.8,\"qty\":0.00013000},{\"price\":77360.6,\"qty\":0.00072000},{\"price\":77359.3,\"qty\":0.33594539},{\"price\":77354.3,\"qty\":0.01000000},{\"price\":77351.9,\"qty\":0.10118940},{\"price\":77350.6,\"qty\":0.00032321},{\"price\":77350.4,\"qty\":0.05314114},{\"price\":77350.0,\"qty\":0.00193924},{\"price\":77345.6,\"qty\":0.03878695},{\"price\":77338.2,\"qty\":0.00025860},{\"price\":77335.8,\"qty\":0.00129307},{\"price\":77334.2,\"qty\":0.00006455},{\"price\":77333.6,\"qty\":0.01034480},{\"price\":77333.0,\"qty\":1.03300000},{\"price\":77330.4,\"qty\":0.00024237},{\"price\":77330.2,\"qty\":0.00452604},{\"price\":77321.4,\"qty\":0.01598856},{\"price\":77320.6,\"qty\":0.02230466},{\"price\":77318.0,\"qty\":0.00032332},{\"price\":77317.5,\"qty\":0.00007449},{\"price\":77314.9,\"qty\":0.00009389},{\"price\":77308.9,\"qty\":0.00018592},{\"price\":77308.6,\"qty\":0.00012935},{\"price\":77306.4,\"qty\":0.11456104},{\"price\":77305.1,\"qty\":0.00036090},{\"price\":77300.6,\"qty\":0.00032342},{\"price\":77300.0,\"qty\":0.00035000},{\"price\":77290.8,\"qty\":0.00064690},{\"price\":77289.7,\"qty\":0.00020702},{\"price\":77288.0,\"qty\":0.07763171},{\"price\":77287.8,\"qty\":0.00026325},{\"price\":77280.0,\"qty\":0.00129399},{\"price\":77271.1,\"qty\":0.00032354},{\"price\":77268.7,\"qty\":0.00013886},{\"price\":77268.5,\"qty\":0.04445134},{\"price\":77266.0,\"qty\":0.00028474},{\"price\":77264.6,\"qty\":0.00582414},{\"price\":77264.1,\"qty\":0.00025885},{\"price\":77257.0,\"qty\":0.51747415},{\"price\":77256.0,\"qty\":0.00038832},{\"price\":77255.2,\"qty\":0.00023272},{\"price\":77252.2,\"qty\":0.00014000},{\"price\":77250.6,\"qty\":0.00032363},{\"price\":77250.0,\"qty\":0.38495146},{\"price\":77247.8,\"qty\":0.00005000},{\"price\":77241.1,\"qty\":0.00038591},{\"price\":77239.8,\"qty\":0.00014307},{\"price\":77235.0,\"qty\":0.00020980},{\"price\":77219.1,\"qty\":0.00031411},{\"price\":77214.7,\"qty\":0.00006126},{\"price\":77212.5,\"qty\":0.00012870},{\"price\":77210.3,\"qty\":0.00647582},{\"price\":77209.3,\"qty\":0.00071406},{\"price\":77204.3,\"qty\":0.01168445},{\"price\":77201.0,\"qty\":0.00099208},{\"price\":77200.6,\"qty\":0.00032384},{\"price\":77200.0,\"qty\":0.05120090},{\"price\":77178.0,\"qty\":0.00012957},{\"price\":77177.8,\"qty\":0.00006468},{\"price\":77175.1,\"qty\":0.00071784},{\"price\":77169.0,\"qty\":0.64792857},{\"price\":77168.3,\"qty\":0.00009726},{\"price\":77167.0,\"qty\":0.00908147},{\"price\":77161.1,\"qty\":0.00006013},{\"price\":77159.0,\"qty\":0.01386643},{\"price\":77157.5,\"qty\":0.00064802},{\"price\":77155.5,\"qty\":0.00006470},{\"price\":77152.4,\"qty\":0.00064806},{\"price\":77150.6,\"qty\":0.00032405},{\"price\":77148.9,\"qty\":0.00034310},{\"price\":77144.9,\"qty\":0.00025925},{\"price\":77140.7,\"qty\":0.00014000},{\"price\":77140.0,\"qty\":0.00012300},{\"price\":77139.4,\"qty\":0.03240885},{\"price\":77133.1,\"qty\":0.33693058},{\"price\":77123.6,\"qty\":0.00094995},{\"price\":77120.7,\"qty\":0.00009412},{\"price\":77120.0,\"qty\":0.00065741},{\"price\":77116.9,\"qty\":0.00140158},{\"price\":77113.1,\"qty\":0.00012900},{\"price\":77111.0,\"qty\":0.00038904},{\"price\":77107.0,\"qty\":0.00042551},{\"price\":77105.0,\"qty\":0.02921535},{\"price\":77103.9,\"qty\":0.00032423},{\"price\":77101.0,\"qty\":0.00250321},{\"price\":77100.6,\"qty\":0.00032426},{\"price\":77100.0,\"qty\":0.08569934},{\"price\":77099.0,\"qty\":0.00259406},{\"price\":77097.0,\"qty\":0.00590166},{\"price\":77091.7,\"qty\":0.00180693},{\"price\":77086.4,\"qty\":0.00025945},{\"price\":77079.0,\"qty\":0.00300000},{\"price\":77077.0,\"qty\":0.00940000},{\"price\":77075.0,\"qty\":0.01211521},{\"price\":77071.2,\"qty\":0.52130031},{\"price\":77069.1,\"qty\":0.00027248},{\"price\":77062.9,\"qty\":0.00009155},{\"price\":77056.0,\"qty\":0.04035678},{\"price\":77054.0,\"qty\":0.03643782},{\"price\":77050.6,\"qty\":0.00032447},{\"price\":77047.7,\"qty\":0.00104877},{\"price\":77039.0,\"qty\":0.00006481},{\"price\":77033.8,\"qty\":0.00023339},{\"price\":77033.5,\"qty\":0.34153000},{\"price\":77029.4,\"qty\":0.00014000},{\"price\":77025.0,\"qty\":0.45439793},{\"price\":77018.1,\"qty\":0.00050000},{\"price\":77015.8,\"qty\":0.00649218},{\"price\":77010.0,\"qty\":0.04175444},{\"price\":77006.0,\"qty\":0.00038959},{\"price\":77003.5,\"qty\":0.00649322},{\"price\":77003.0,\"qty\":0.00032467},{\"price\":77001.0,\"qty\":2.86812495},{\"price\":77000.6,\"qty\":0.00032468},{\"price\":77000.1,\"qty\":0.10000000},{\"price\":77000.0,\"qty\":2.98437866},{\"price\":76980.6,\"qty\":0.01818639},{\"price\":76980.0,\"qty\":0.10782022},{\"price\":76977.0,\"qty\":0.00065825},{\"price\":76973.0,\"qty\":0.00129064},{\"price\":76969.0,\"qty\":0.15000000},{\"price\":76967.0,\"qty\":0.00012775},{\"price\":76963.0,\"qty\":0.00032483},{\"price\":76955.8,\"qty\":0.00005170},{\"price\":76955.0,\"qty\":0.50000000},{\"price\":76952.0,\"qty\":0.00025990},{\"price\":76950.6,\"qty\":0.00032489},{\"price\":76950.2,\"qty\":0.00778558},{\"price\":76945.3,\"qty\":0.00044178},{\"price\":76945.2,\"qty\":0.00091212},{\"price\":76942.6,\"qty\":0.00061254},{\"price\":76938.7,\"qty\":0.00064986},{\"price\":76937.1,\"qty\":0.00010000},{\"price\":76936.0,\"qty\":0.00032495},{\"price\":76930.5,\"qty\":0.00064993},{\"price\":76926.9,\"qty\":0.00009436},{\"price\":76926.6,\"qty\":0.00050000},{\"price\":76924.1,\"qty\":0.04662110},{\"price\":76924.0,\"qty\":0.50000000},{\"price\":76918.2,\"qty\":0.00014000},{\"price\":76914.7,\"qty\":0.06500707},{\"price\":76911.0,\"qty\":0.00026004},{\"price\":76910.7,\"qty\":0.00039076},{\"price\":76907.5,\"qty\":0.33791893},{\"price\":76906.4,\"qty\":0.00065014},{\"price\":76903.0,\"qty\":0.10507548},{\"price\":76900.6,\"qty\":0.00032510},{\"price\":76900.0,\"qty\":0.03505000},{\"price\":76899.8,\"qty\":0.00012990},{\"price\":76899.7,\"qty\":0.00039700},{\"price\":76899.0,\"qty\":0.00250000},{\"price\":76896.9,\"qty\":0.00009438}],\"asks\":[{\"price\":79455.0,\"qty\":3.46043427},{\"price\":79455.1,\"qty\":0.62928644},{\"price\":79455.6,\"qty\":0.08811444},{\"price\":79456.0,\"qty\":0.03146396},{\"price\":79457.0,\"qty\":0.37570414},{\"price\":79457.1,\"qty\":0.62927107},{\"price\":79457.7,\"qty\":0.00006803},{\"price\":79459.7,\"qty\":0.62925023},{\"price\":79461.7,\"qty\":0.42553229},{\"price\":79461.8,\"qty\":0.71710200},{\"price\":79462.5,\"qty\":0.00005100},{\"price\":79462.6,\"qty\":0.01000000},{\"price\":79462.7,\"qty\":0.05440000},{\"price\":79463.0,\"qty\":0.00020100},{\"price\":79463.7,\"qty\":0.00006803},{\"price\":79464.0,\"qty\":0.74460814},{\"price\":79464.1,\"qty\":0.59868238},{\"price\":79464.3,\"qty\":0.02442689},{\"price\":79465.3,\"qty\":1.88761685},{\"price\":79466.5,\"qty\":0.00005100},{\"price\":79467.1,\"qty\":0.00016700},{\"price\":79468.8,\"qty\":0.09337439},{\"price\":79468.9,\"qty\":1.26196158},{\"price\":79469.0,\"qty\":0.50340500},{\"price\":79469.2,\"qty\":2.35037512},{\"price\":79469.7,\"qty\":0.11000000},{\"price\":79469.8,\"qty\":0.40006803},{\"price\":79470.4,\"qty\":0.00005100},{\"price\":79471.0,\"qty\":0.11225497},{\"price\":79471.9,\"qty\":6.29153737},{\"price\":79472.0,\"qty\":0.00998701},{\"price\":79472.7,\"qty\":0.29184317},{\"price\":79472.8,\"qty\":0.72024600},{\"price\":79473.0,\"qty\":0.11364277},{\"price\":79474.1,\"qty\":0.09425503},{\"price\":79475.8,\"qty\":0.00006803},{\"price\":79476.1,\"qty\":0.00013149},{\"price\":79476.2,\"qty\":0.01258238},{\"price\":79477.3,\"qty\":0.01251170},{\"price\":79477.5,\"qty\":0.22926563},{\"price\":79477.6,\"qty\":0.34487185},{\"price\":79477.7,\"qty\":0.13109402},{\"price\":79478.6,\"qty\":0.05440000},{\"price\":79479.3,\"qty\":0.23769319},{\"price\":79481.4,\"qty\":0.02397570},{\"price\":79481.5,\"qty\":2.09199175},{\"price\":79481.6,\"qty\":6.29076821},{\"price\":79481.8,\"qty\":0.00006803},{\"price\":79482.2,\"qty\":0.01251636},{\"price\":79482.4,\"qty\":0.14907512},{\"price\":79482.7,\"qty\":0.00050000},{\"price\":79483.3,\"qty\":0.02057681},{\"price\":79483.6,\"qty\":0.09337439},{\"price\":79483.7,\"qty\":0.70482800},{\"price\":79483.8,\"qty\":0.64635360},{\"price\":79485.1,\"qty\":0.00120000},{\"price\":79485.4,\"qty\":0.79157217},{\"price\":79485.5,\"qty\":2.50565337},{\"price\":79487.8,\"qty\":0.00006803},{\"price\":79489.1,\"qty\":0.00087814},{\"price\":79489.2,\"qty\":1.89498574},{\"price\":79489.3,\"qty\":0.05440000},{\"price\":79490.7,\"qty\":0.01251636},{\"price\":79491.4,\"qty\":0.07329839},{\"price\":79492.0,\"qty\":6.28994871},{\"price\":79492.5,\"qty\":0.00080000},{\"price\":79493.9,\"qty\":0.00006803},{\"price\":79497.6,\"qty\":0.00150000},{\"price\":79497.8,\"qty\":0.18890000},{\"price\":79499.9,\"qty\":0.00006803},{\"price\":79500.1,\"qty\":6.28930744},{\"price\":79501.0,\"qty\":0.05440000},{\"price\":79503.2,\"qty\":0.01251636},{\"price\":79503.4,\"qty\":0.00657023},{\"price\":79503.9,\"qty\":0.05022440},{\"price\":79504.9,\"qty\":6.85807354},{\"price\":79505.0,\"qty\":15.00100000},{\"price\":79505.8,\"qty\":6.88885668},{\"price\":79505.9,\"qty\":0.00006803},{\"price\":79506.1,\"qty\":0.00005100},{\"price\":79506.5,\"qty\":0.02518000},{\"price\":79506.9,\"qty\":0.10869789},{\"price\":79509.0,\"qty\":0.05440000},{\"price\":79510.1,\"qty\":0.00180000},{\"price\":79511.9,\"qty\":0.00006803},{\"price\":79513.1,\"qty\":0.00255617},{\"price\":79513.5,\"qty\":0.43877550},{\"price\":79517.0,\"qty\":0.05440000},{\"price\":79517.4,\"qty\":0.70266000},{\"price\":79517.5,\"qty\":0.00120000},{\"price\":79517.9,\"qty\":0.00006803},{\"price\":79518.9,\"qty\":4.40147032},{\"price\":79519.2,\"qty\":0.11225497},{\"price\":79520.7,\"qty\":0.44051700},{\"price\":79521.9,\"qty\":0.00005100},{\"price\":79522.6,\"qty\":0.57082800},{\"price\":79524.0,\"qty\":0.00006803},{\"price\":79524.3,\"qty\":0.12516368},{\"price\":79525.0,\"qty\":0.05440000},{\"price\":79528.8,\"qty\":0.29512255},{\"price\":79528.9,\"qty\":0.98320577},{\"price\":79529.9,\"qty\":0.00541145},{\"price\":79530.0,\"qty\":0.00006803},{\"price\":79533.1,\"qty\":0.63044829},{\"price\":79533.2,\"qty\":1.54434662},{\"price\":79534.5,\"qty\":0.00200000},{\"price\":79534.6,\"qty\":0.06016458},{\"price\":79536.0,\"qty\":0.00006803},{\"price\":79536.4,\"qty\":0.00246700},{\"price\":79538.4,\"qty\":0.01959760},{\"price\":79540.8,\"qty\":0.00326241},{\"price\":79540.9,\"qty\":0.83002044},{\"price\":79541.0,\"qty\":2.78063800},{\"price\":79542.0,\"qty\":0.00006803},{\"price\":79546.1,\"qty\":0.10993705},{\"price\":79548.0,\"qty\":0.01980080},{\"price\":79548.1,\"qty\":0.00006803},{\"price\":79548.3,\"qty\":0.12556100},{\"price\":79550.7,\"qty\":4.39971512},{\"price\":79554.1,\"qty\":0.00006803},{\"price\":79557.5,\"qty\":0.01959149},{\"price\":79558.0,\"qty\":0.00012501},{\"price\":79558.9,\"qty\":0.01166000},{\"price\":79559.1,\"qty\":4.39924976},{\"price\":79560.1,\"qty\":0.00006803},{\"price\":79560.3,\"qty\":1.41372000},{\"price\":79560.4,\"qty\":1.52423114},{\"price\":79560.5,\"qty\":4.39916985},{\"price\":79566.1,\"qty\":0.00006803},{\"price\":79567.1,\"qty\":0.01979462},{\"price\":79569.5,\"qty\":0.02467010},{\"price\":79570.2,\"qty\":0.03700900},{\"price\":79572.2,\"qty\":0.00006803},{\"price\":79572.8,\"qty\":1.20000000},{\"price\":79574.2,\"qty\":1.43423000},{\"price\":79575.3,\"qty\":0.00369981},{\"price\":79576.6,\"qty\":0.01958537},{\"price\":79578.2,\"qty\":0.00006803},{\"price\":79578.3,\"qty\":9.42467776},{\"price\":79580.6,\"qty\":4.43784300},{\"price\":79584.2,\"qty\":0.00006803},{\"price\":79586.2,\"qty\":0.01978844},{\"price\":79590.2,\"qty\":0.00006803},{\"price\":79593.9,\"qty\":0.12516368},{\"price\":79594.9,\"qty\":1.31842784},{\"price\":79595.0,\"qty\":4.39726441},{\"price\":79595.7,\"qty\":0.01957927},{\"price\":79596.3,\"qty\":0.00006803},{\"price\":79602.3,\"qty\":0.00006803},{\"price\":79603.7,\"qty\":0.01970741},{\"price\":79604.8,\"qty\":0.01000000},{\"price\":79605.3,\"qty\":0.01978227},{\"price\":79610.9,\"qty\":0.00025246},{\"price\":79612.8,\"qty\":4.39628067},{\"price\":79614.1,\"qty\":0.00200000},{\"price\":79614.8,\"qty\":0.01957316},{\"price\":79618.5,\"qty\":0.00125080},{\"price\":79621.8,\"qty\":25.11874108},{\"price\":79624.4,\"qty\":0.01977610},{\"price\":79624.8,\"qty\":4.39561834},{\"price\":79630.7,\"qty\":0.00011000},{\"price\":79632.7,\"qty\":0.72457689},{\"price\":79633.9,\"qty\":0.01956706},{\"price\":79634.3,\"qty\":0.03284463},{\"price\":79637.5,\"qty\":1.85155098},{\"price\":79638.5,\"qty\":5.58839100},{\"price\":79643.5,\"qty\":0.01976993},{\"price\":79645.1,\"qty\":0.12516368},{\"price\":79645.8,\"qty\":0.25111179},{\"price\":79653.1,\"qty\":0.01976684},{\"price\":79662.6,\"qty\":0.01955789},{\"price\":79664.0,\"qty\":4.99579284},{\"price\":79664.1,\"qty\":16.13632441},{\"price\":79664.8,\"qty\":0.36000000},{\"price\":79673.9,\"qty\":0.12516368},{\"price\":79677.9,\"qty\":0.00024768},{\"price\":79685.2,\"qty\":0.00026982},{\"price\":79693.4,\"qty\":3.09235909},{\"price\":79693.8,\"qty\":0.00200000},{\"price\":79694.4,\"qty\":0.00005000},{\"price\":79696.2,\"qty\":0.03746583},{\"price\":79700.0,\"qty\":0.00035000},{\"price\":79703.0,\"qty\":0.01970722},{\"price\":79722.1,\"qty\":0.00087814},{\"price\":79722.2,\"qty\":5.87015700},{\"price\":79727.5,\"qty\":0.00151427},{\"price\":79735.4,\"qty\":0.00005762},{\"price\":79737.1,\"qty\":0.03736136},{\"price\":79738.5,\"qty\":0.08228266},{\"price\":79749.9,\"qty\":0.00012564},{\"price\":79750.0,\"qty\":0.02523976},{\"price\":79756.1,\"qty\":0.01003058},{\"price\":79773.6,\"qty\":0.00200000},{\"price\":79776.0,\"qty\":0.00066975},{\"price\":79778.0,\"qty\":0.00545593},{\"price\":79783.3,\"qty\":12.43961723},{\"price\":79795.5,\"qty\":0.18857738},{\"price\":79799.4,\"qty\":6.82409200},{\"price\":79800.5,\"qty\":0.00005723},{\"price\":79804.0,\"qty\":0.00005000},{\"price\":79809.1,\"qty\":0.24386999},{\"price\":79809.9,\"qty\":1.23050329},{\"price\":79821.2,\"qty\":0.34358289},{\"price\":79827.6,\"qty\":0.10000000},{\"price\":79828.1,\"qty\":0.44379924},{\"price\":79832.0,\"qty\":0.50000000},{\"price\":79832.3,\"qty\":0.00015000},{\"price\":79847.4,\"qty\":0.00154218},{\"price\":79852.1,\"qty\":0.00200000},{\"price\":79880.6,\"qty\":11.33842800},{\"price\":79898.9,\"qty\":0.39759570},{\"price\":79910.1,\"qty\":4.37992592},{\"price\":79913.7,\"qty\":0.00005000},{\"price\":79922.4,\"qty\":0.00063186},{\"price\":79931.8,\"qty\":0.00010062},{\"price\":79933.4,\"qty\":0.00200000},{\"price\":79934.6,\"qty\":0.00005747},{\"price\":79934.7,\"qty\":0.02505794},{\"price\":79950.0,\"qty\":50.00000000},{\"price\":79957.2,\"qty\":0.00005000},{\"price\":79957.3,\"qty\":0.00025208},{\"price\":79958.3,\"qty\":0.00066092},{\"price\":79968.0,\"qty\":0.34838792},{\"price\":79972.6,\"qty\":0.41962115},{\"price\":79973.8,\"qty\":0.45618206},{\"price\":79979.0,\"qty\":0.00375099},{\"price\":79984.0,\"qty\":0.02855097},{\"price\":79984.1,\"qty\":0.05186390},{\"price\":80000.0,\"qty\":7.23103091},{\"price\":80008.7,\"qty\":0.00050497},{\"price\":80009.0,\"qty\":0.00025122},{\"price\":80011.0,\"qty\":0.00624915},{\"price\":80013.0,\"qty\":0.00005707},{\"price\":80013.3,\"qty\":0.00200000},{\"price\":80023.4,\"qty\":0.00006000},{\"price\":80024.2,\"qty\":0.01877245},{\"price\":80031.0,\"qty\":0.00027356},{\"price\":80046.0,\"qty\":4.37249070},{\"price\":80055.5,\"qty\":0.00124099},{\"price\":80092.0,\"qty\":0.00010000},{\"price\":80093.3,\"qty\":0.00200000},{\"price\":80102.0,\"qty\":0.00030175},{\"price\":80125.9,\"qty\":0.00012517},{\"price\":80134.3,\"qty\":0.00005733},{\"price\":80146.3,\"qty\":0.26829284},{\"price\":80147.0,\"qty\":0.00499083},{\"price\":80147.9,\"qty\":0.00006000},{\"price\":80150.0,\"qty\":0.14472742},{\"price\":80157.2,\"qty\":0.00006126},{\"price\":80162.5,\"qty\":0.07291087},{\"price\":80178.5,\"qty\":0.00031300},{\"price\":80178.8,\"qty\":0.00050000},{\"price\":80185.0,\"qty\":0.10000000},{\"price\":80188.0,\"qty\":0.15000000},{\"price\":80197.0,\"qty\":0.00623465},{\"price\":80201.6,\"qty\":0.00137545},{\"price\":80207.8,\"qty\":0.00010000},{\"price\":80211.0,\"qty\":0.00623356},{\"price\":80211.8,\"qty\":0.00031512},{\"price\":80220.3,\"qty\":0.00008888},{\"price\":80226.0,\"qty\":0.00005692},{\"price\":80231.6,\"qty\":0.00037524},{\"price\":80233.5,\"qty\":0.00005462},{\"price\":80248.9,\"qty\":0.00031200},{\"price\":80249.6,\"qty\":0.00996889},{\"price\":80260.3,\"qty\":7.93951993},{\"price\":80269.0,\"qty\":0.00622906},{\"price\":80272.4,\"qty\":0.00006000},{\"price\":80297.1,\"qty\":0.00125783},{\"price\":80300.0,\"qty\":1.71715000},{\"price\":80311.1,\"qty\":1.80000000},{\"price\":80322.9,\"qty\":0.02426168},{\"price\":80323.2,\"qty\":0.00175213},{\"price\":80323.5,\"qty\":0.00530119},{\"price\":80334.5,\"qty\":0.00005719},{\"price\":80342.0,\"qty\":0.90477646},{\"price\":80350.0,\"qty\":0.00960000},{\"price\":80357.0,\"qty\":0.00096195},{\"price\":80361.4,\"qty\":0.00031200},{\"price\":80363.0,\"qty\":0.05000000},{\"price\":80385.0,\"qty\":0.00070000},{\"price\":80392.8,\"qty\":0.60000000},{\"price\":80394.9,\"qty\":0.00009461},{\"price\":80396.9,\"qty\":0.00008000},{\"price\":80400.0,\"qty\":1.43921022},{\"price\":80405.1,\"qty\":0.00317700},{\"price\":80409.0,\"qty\":0.00024997},{\"price\":80412.0,\"qty\":0.00050000},{\"price\":80414.9,\"qty\":0.02323000},{\"price\":80421.0,\"qty\":0.00020000},{\"price\":80439.6,\"qty\":0.00005677},{\"price\":80463.7,\"qty\":0.03736136},{\"price\":80464.0,\"qty\":0.05155459},{\"price\":80474.5,\"qty\":0.60000000},{\"price\":80478.3,\"qty\":0.04324373},{\"price\":80485.0,\"qty\":0.00248493},{\"price\":80494.8,\"qty\":0.03196784},{\"price\":80500.0,\"qty\":2.01117263},{\"price\":80508.4,\"qty\":0.00069486},{\"price\":80528.0,\"qty\":0.05000000},{\"price\":80533.1,\"qty\":0.00512138},{\"price\":80535.2,\"qty\":0.00005704},{\"price\":80537.4,\"qty\":0.00031384},{\"price\":80541.3,\"qty\":0.00022653},{\"price\":80543.2,\"qty\":0.00196500},{\"price\":80543.6,\"qty\":0.00891329},{\"price\":80548.3,\"qty\":0.00009158},{\"price\":80549.8,\"qty\":0.00031379},{\"price\":80552.0,\"qty\":0.00031378},{\"price\":80553.1,\"qty\":0.00031378},{\"price\":80556.0,\"qty\":0.00011000},{\"price\":80569.3,\"qty\":0.00031372},{\"price\":80569.6,\"qty\":0.00075397},{\"price\":80571.7,\"qty\":0.00031371},{\"price\":80573.1,\"qty\":0.00031370},{\"price\":80574.8,\"qty\":0.00062054},{\"price\":80580.9,\"qty\":0.00025013},{\"price\":80588.7,\"qty\":0.04261998},{\"price\":80590.0,\"qty\":0.00099267},{\"price\":80592.9,\"qty\":0.00032112},{\"price\":80595.2,\"qty\":0.00069822},{\"price\":80598.5,\"qty\":0.00124072},{\"price\":80599.0,\"qty\":0.00031359},{\"price\":80599.6,\"qty\":0.00008000},{\"price\":80599.9,\"qty\":0.00010000},{\"price\":80600.0,\"qty\":1.00000000},{\"price\":80602.0,\"qty\":0.00031359},{\"price\":80607.6,\"qty\":0.00031356},{\"price\":80612.1,\"qty\":0.00031401},{\"price\":80615.6,\"qty\":0.00031354},{\"price\":80616.9,\"qty\":0.00018196},{\"price\":80621.4,\"qty\":0.00062019},{\"price\":80625.3,\"qty\":0.00009446},{\"price\":80625.6,\"qty\":0.00013854},{\"price\":80629.4,\"qty\":0.00151400},{\"price\":80634.9,\"qty\":0.00037335},{\"price\":80635.0,\"qty\":0.45000000},{\"price\":80640.2,\"qty\":0.15703096},{\"price\":80641.8,\"qty\":0.00126609},{\"price\":80645.3,\"qty\":0.00075047},{\"price\":80647.3,\"qty\":0.00068198},{\"price\":80647.5,\"qty\":0.00085460},{\"price\":80648.0,\"qty\":0.00083164},{\"price\":80650.0,\"qty\":0.00106654},{\"price\":80653.2,\"qty\":0.00177783},{\"price\":80653.8,\"qty\":0.00005662},{\"price\":80659.5,\"qty\":0.00152666},{\"price\":80661.1,\"qty\":0.00031336},{\"price\":80664.0,\"qty\":0.00015000},{\"price\":80665.5,\"qty\":0.00031334},{\"price\":80672.9,\"qty\":0.00024791},{\"price\":80678.7,\"qty\":0.00061974},{\"price\":80680.0,\"qty\":0.01259908},{\"price\":80681.6,\"qty\":0.00031328},{\"price\":80682.0,\"qty\":0.15000000},{\"price\":80682.3,\"qty\":0.00031328},{\"price\":80688.0,\"qty\":0.06120850},{\"price\":80689.2,\"qty\":0.00031325},{\"price\":80691.0,\"qty\":0.00350000},{\"price\":80691.2,\"qty\":0.00080964},{\"price\":80695.0,\"qty\":0.05502061},{\"price\":80700.0,\"qty\":1.90447740},{\"price\":80704.2,\"qty\":0.02414705},{\"price\":80716.7,\"qty\":0.00031311},{\"price\":80726.4,\"qty\":0.00091731},{\"price\":80727.2,\"qty\":0.19391712},{\"price\":80730.5,\"qty\":0.00010000},{\"price\":80734.1,\"qty\":0.00010000},{\"price\":80735.0,\"qty\":0.00031307},{\"price\":80736.4,\"qty\":0.00005690},{\"price\":80737.5,\"qty\":0.00013459},{\"price\":80742.0,\"qty\":0.01990975},{\"price\":80745.7,\"qty\":0.00006126},{\"price\":80746.2,\"qty\":0.00990759},{\"price\":80751.2,\"qty\":0.00009135},{\"price\":80755.0,\"qty\":0.00527182},{\"price\":80766.5,\"qty\":0.00031295},{\"price\":80767.6,\"qty\":0.00062525},{\"price\":80772.7,\"qty\":0.00055391},{\"price\":80772.8,\"qty\":0.00022589},{\"price\":80778.0,\"qty\":0.02500000},{\"price\":80780.0,\"qty\":0.00030000},{\"price\":80780.9,\"qty\":0.00648946},{\"price\":80782.1,\"qty\":0.00030947},{\"price\":80784.3,\"qty\":0.03060639},{\"price\":80787.0,\"qty\":0.00008826},{\"price\":80794.5,\"qty\":0.00126432},{\"price\":80798.9,\"qty\":0.00009144},{\"price\":80800.0,\"qty\":1.21685414},{\"price\":80802.2,\"qty\":0.00008000},{\"price\":80804.0,\"qty\":0.10000000},{\"price\":80804.9,\"qty\":0.00100000},{\"price\":80809.7,\"qty\":0.00031278},{\"price\":80811.0,\"qty\":0.00077239},{\"price\":80811.1,\"qty\":0.00024872},{\"price\":80820.5,\"qty\":0.00031274},{\"price\":80833.6,\"qty\":0.00031269},{\"price\":80836.7,\"qty\":0.00031268},{\"price\":80847.8,\"qty\":0.00031264},{\"price\":80850.5,\"qty\":0.00360639},{\"price\":80851.3,\"qty\":0.00092991},{\"price\":80855.0,\"qty\":0.00050000},{\"price\":80857.7,\"qty\":0.00031214},{\"price\":80868.6,\"qty\":0.00005647},{\"price\":80875.1,\"qty\":0.00024729},{\"price\":80878.5,\"qty\":0.00109193},{\"price\":80879.9,\"qty\":0.00031251},{\"price\":80880.0,\"qty\":0.01259908},{\"price\":80881.7,\"qty\":0.00010000},{\"price\":80883.4,\"qty\":0.00111604},{\"price\":80888.0,\"qty\":0.00049451},{\"price\":80900.0,\"qty\":0.00035000},{\"price\":80902.4,\"qty\":0.00198145},{\"price\":80920.1,\"qty\":0.04244543},{\"price\":80920.9,\"qty\":0.00031235},{\"price\":80925.3,\"qty\":0.00104276},{\"price\":80929.9,\"qty\":0.00083291},{\"price\":80932.3,\"qty\":0.00055391},{\"price\":80938.1,\"qty\":0.00005676},{\"price\":80940.1,\"qty\":0.00012561},{\"price\":80946.7,\"qty\":0.05124712},{\"price\":80948.7,\"qty\":0.00010294},{\"price\":80950.0,\"qty\":0.17767378},{\"price\":80954.6,\"qty\":0.00009112},{\"price\":80956.9,\"qty\":0.00011533},{\"price\":80960.7,\"qty\":0.00010293},{\"price\":80961.0,\"qty\":0.02000000},{\"price\":80961.5,\"qty\":0.00074222},{\"price\":80962.1,\"qty\":0.00123102},{\"price\":80972.6,\"qty\":0.00010291},{\"price\":80987.0,\"qty\":0.25000000},{\"price\":80998.0,\"qty\":7.67627107},{\"price\":80999.3,\"qty\":0.00125989},{\"price\":81000.0,\"qty\":0.25122360},{\"price\":81005.0,\"qty\":0.00022524},{\"price\":81007.3,\"qty\":0.06172200},{\"price\":81011.0,\"qty\":0.00493761},{\"price\":81020.0,\"qty\":0.00902143},{\"price\":81040.2,\"qty\":0.00037149},{\"price\":81040.9,\"qty\":0.00135783},{\"price\":81055.0,\"qty\":0.00050000},{\"price\":81062.7,\"qty\":0.00176885},{\"price\":81070.1,\"qty\":0.08187637},{\"price\":81077.8,\"qty\":0.00024668},{\"price\":81083.9,\"qty\":0.00005632},{\"price\":81091.9,\"qty\":0.00055393},{\"price\":81092.1,\"qty\":0.00120392},{\"price\":81099.0,\"qty\":0.12330609},{\"price\":81111.8,\"qty\":0.00080649},{\"price\":81111.9,\"qty\":0.00350000},{\"price\":81120.0,\"qty\":0.07495296},{\"price\":81121.4,\"qty\":0.00042400},{\"price\":81126.9,\"qty\":0.01323300},{\"price\":81129.4,\"qty\":0.00006256},{\"price\":81134.0,\"qty\":0.00006267},{\"price\":81140.3,\"qty\":0.00005662},{\"price\":81146.8,\"qty\":0.02997443},{\"price\":81147.2,\"qty\":0.01256974},{\"price\":81150.4,\"qty\":0.00013459},{\"price\":81151.4,\"qty\":0.00640485},{\"price\":81152.0,\"qty\":0.00173424},{\"price\":81155.0,\"qty\":0.00040000},{\"price\":81158.5,\"qty\":0.00009088},{\"price\":81161.0,\"qty\":0.01000000},{\"price\":81161.1,\"qty\":0.00804900},{\"price\":81168.0,\"qty\":0.00012320},{\"price\":81168.2,\"qty\":0.00915400},{\"price\":81173.1,\"qty\":0.00839600},{\"price\":81176.1,\"qty\":0.00554350},{\"price\":81180.3,\"qty\":0.00062152},{\"price\":81188.8,\"qty\":0.00524363},{\"price\":81190.2,\"qty\":0.00725300},{\"price\":81197.4,\"qty\":0.00009000},{\"price\":81200.0,\"qty\":0.27181375},{\"price\":81202.5,\"qty\":0.00068892},{\"price\":81205.0,\"qty\":0.00050000},{\"price\":81206.1,\"qty\":0.00019363},{\"price\":81206.2,\"qty\":0.00038412},{\"price\":81209.3,\"qty\":0.00024819},{\"price\":81211.2,\"qty\":0.13140971},{\"price\":81215.1,\"qty\":0.00024749},{\"price\":81217.6,\"qty\":0.00246253},{\"price\":81217.8,\"qty\":0.00093306},{\"price\":81222.9,\"qty\":0.00013100},{\"price\":81229.5,\"qty\":0.00980000},{\"price\":81237.8,\"qty\":0.00022458},{\"price\":81245.9,\"qty\":0.00984665},{\"price\":81250.0,\"qty\":0.00146032},{\"price\":81258.5,\"qty\":0.00959829},{\"price\":81258.8,\"qty\":0.00095128},{\"price\":81263.4,\"qty\":0.00125579},{\"price\":81280.0,\"qty\":0.01170154},{\"price\":81280.7,\"qty\":0.00060871},{\"price\":81281.0,\"qty\":0.00024606},{\"price\":81282.3,\"qty\":0.00229860},{\"price\":81283.9,\"qty\":0.00021215},{\"price\":81299.9,\"qty\":0.00005617},{\"price\":81300.0,\"qty\":0.01080000},{\"price\":81306.4,\"qty\":0.00007883},{\"price\":81307.8,\"qty\":0.33300701},{\"price\":81323.1,\"qty\":0.00018040},{\"price\":81330.2,\"qty\":0.07671508},{\"price\":81334.2,\"qty\":0.00006126},{\"price\":81343.0,\"qty\":0.00005649},{\"price\":81345.2,\"qty\":0.00012555},{\"price\":81353.3,\"qty\":0.00009361},{\"price\":81353.5,\"qty\":0.00100170},{\"price\":81357.7,\"qty\":0.00008764},{\"price\":81361.7,\"qty\":0.00239509},{\"price\":81362.9,\"qty\":0.00009066},{\"price\":81367.0,\"qty\":0.00614500},{\"price\":81370.9,\"qty\":0.00011533},{\"price\":81375.0,\"qty\":0.00190514},{\"price\":81376.0,\"qty\":0.00411289},{\"price\":81390.3,\"qty\":0.00276017},{\"price\":81390.4,\"qty\":0.00268131},{\"price\":81392.6,\"qty\":0.01249372},{\"price\":81397.0,\"qty\":0.00737128},{\"price\":81399.1,\"qty\":0.00239398},{\"price\":81399.9,\"qty\":20.00000000},{\"price\":81400.0,\"qty\":1.30724537},{\"price\":81403.5,\"qty\":0.00239387},{\"price\":81405.7,\"qty\":0.00055274},{\"price\":81410.5,\"qty\":0.06453453},{\"price\":81411.0,\"qty\":0.00491335},{\"price\":81412.7,\"qty\":0.00239359},{\"price\":81413.9,\"qty\":0.00239356},{\"price\":81414.2,\"qty\":0.00311161},{\"price\":81417.0,\"qty\":0.00150519},{\"price\":81420.7,\"qty\":0.00016982},{\"price\":81423.5,\"qty\":0.00049970},{\"price\":81424.0,\"qty\":0.08596973},{\"price\":81424.8,\"qty\":0.00069110},{\"price\":81430.1,\"qty\":0.00311101},{\"price\":81432.5,\"qty\":0.05094144},{\"price\":81434.4,\"qty\":0.00311085},{\"price\":81438.2,\"qty\":0.00239284},{\"price\":81439.6,\"qty\":0.01973921},{\"price\":81444.0,\"qty\":0.01500000},{\"price\":81444.2,\"qty\":0.00311046},{\"price\":81445.0,\"qty\":0.00375809},{\"price\":81447.6,\"qty\":0.00036962},{\"price\":81447.7,\"qty\":0.00239257},{\"price\":81450.0,\"qty\":0.00662982},{\"price\":81455.0,\"qty\":0.00176798},{\"price\":81456.0,\"qty\":0.00500000},{\"price\":81462.0,\"qty\":0.00135081},{\"price\":81467.5,\"qty\":0.00520261},{\"price\":81471.3,\"qty\":0.00022396},{\"price\":81472.0,\"qty\":0.00175997},{\"price\":81478.9,\"qty\":0.00061979},{\"price\":81479.9,\"qty\":0.00151129},{\"price\":81484.7,\"qty\":0.00024544},{\"price\":81490.0,\"qty\":0.00208064},{\"price\":81493.2,\"qty\":0.00239123},{\"price\":81495.0,\"qty\":0.00013707},{\"price\":81495.5,\"qty\":0.00015000},{\"price\":81498.0,\"qty\":0.00014962},{\"price\":81500.0,\"qty\":0.61732629},{\"price\":81501.5,\"qty\":0.00395590},{\"price\":81504.0,\"qty\":0.09940000},{\"price\":81510.6,\"qty\":0.00188617},{\"price\":81516.3,\"qty\":0.00005603},{\"price\":81521.6,\"qty\":0.00248800},{\"price\":81525.5,\"qty\":0.00032702},{\"price\":81535.0,\"qty\":0.00350000},{\"price\":81538.0,\"qty\":0.00311400},{\"price\":81540.4,\"qty\":0.00049718},{\"price\":81541.4,\"qty\":0.00010000},{\"price\":81546.2,\"qty\":0.00005633},{\"price\":81546.3,\"qty\":0.33398360},{\"price\":81550.0,\"qty\":0.01366505},{\"price\":81557.1,\"qty\":0.00319979},{\"price\":81563.3,\"qty\":0.00013459},{\"price\":81563.5,\"qty\":0.00860163},{\"price\":81567.9,\"qty\":0.00009044},{\"price\":81569.4,\"qty\":0.00198200},{\"price\":81572.8,\"qty\":0.00345700},{\"price\":81576.1,\"qty\":0.00625734},{\"price\":81583.8,\"qty\":0.06666667},{\"price\":81599.0,\"qty\":0.29304128},{\"price\":81601.1,\"qty\":0.00037843},{\"price\":81602.2,\"qty\":0.00098900},{\"price\":81616.6,\"qty\":0.02379659},{\"price\":81620.7,\"qty\":0.00084441},{\"price\":81621.2,\"qty\":0.00024625},{\"price\":81625.0,\"qty\":0.00521562},{\"price\":81632.6,\"qty\":0.02450002},{\"price\":81635.2,\"qty\":0.00101480},{\"price\":81639.4,\"qty\":0.00127337},{\"price\":81639.9,\"qty\":0.00638145},{\"price\":81640.0,\"qty\":0.12738854},{\"price\":81641.0,\"qty\":0.00050000},{\"price\":81648.2,\"qty\":0.00068603},{\"price\":81650.0,\"qty\":0.00510468},{\"price\":81650.4,\"qty\":0.00084333},{\"price\":81655.0,\"qty\":0.50000000},{\"price\":81667.0,\"qty\":0.00045950},{\"price\":81672.1,\"qty\":0.00035263},{\"price\":81672.5,\"qty\":0.06122000},{\"price\":81688.9,\"qty\":0.00024483},{\"price\":81700.0,\"qty\":4.82452249},{\"price\":81705.5,\"qty\":0.00022331},{\"price\":81720.0,\"qty\":0.00745463},{\"price\":81733.4,\"qty\":0.00005588},{\"price\":81735.1,\"qty\":0.03006775},{\"price\":81735.9,\"qty\":0.01267828},{\"price\":81740.4,\"qty\":0.00136624},{\"price\":81747.8,\"qty\":0.00261510},{\"price\":81748.6,\"qty\":0.00978610},{\"price\":81749.9,\"qty\":0.00005619},{\"price\":81750.0,\"qty\":0.01011009},{\"price\":81753.0,\"qty\":0.06250000},{\"price\":81773.3,\"qty\":0.00009021},{\"price\":81780.0,\"qty\":0.01838077},{\"price\":81785.0,\"qty\":0.00011533},{\"price\":81785.4,\"qty\":0.33496335},{\"price\":81800.0,\"qty\":0.93140972},{\"price\":81805.0,\"qty\":0.00050000},{\"price\":81810.6,\"qty\":0.00295600},{\"price\":81811.0,\"qty\":16.07618458},{\"price\":81815.3,\"qty\":0.00012577},{\"price\":81834.8,\"qty\":0.00087841},{\"price\":81835.6,\"qty\":0.00106000},{\"price\":81838.7,\"qty\":0.49093194},{\"price\":81842.6,\"qty\":0.00024627},{\"price\":81845.0,\"qty\":0.01041799},{\"price\":81851.9,\"qty\":0.00102700},{\"price\":81853.9,\"qty\":0.00124735},{\"price\":81857.0,\"qty\":0.00103969},{\"price\":81858.5,\"qty\":0.00068739},{\"price\":81860.2,\"qty\":0.00013854},{\"price\":81867.9,\"qty\":0.00676031},{\"price\":81870.0,\"qty\":0.00007444},{\"price\":81873.0,\"qty\":0.00610702},{\"price\":81888.0,\"qty\":0.18664110},{\"price\":81893.5,\"qty\":0.00156800},{\"price\":81893.6,\"qty\":0.00024422},{\"price\":81900.0,\"qty\":0.39614913},{\"price\":81902.5,\"qty\":0.00068303},{\"price\":81920.0,\"qty\":0.45000000},{\"price\":81920.9,\"qty\":0.00634470},{\"price\":81921.0,\"qty\":0.05063764},{\"price\":81922.6,\"qty\":0.00049207},{\"price\":81932.1,\"qty\":0.01000000},{\"price\":81932.6,\"qty\":0.00008701},{\"price\":81938.6,\"qty\":0.00076564},{\"price\":81940.2,\"qty\":0.00022266},{\"price\":81945.1,\"qty\":0.00307603},{\"price\":81946.6,\"qty\":0.00048812},{\"price\":81948.0,\"qty\":10.00000000},{\"price\":81951.0,\"qty\":0.00005573},{\"price\":81954.1,\"qty\":0.00005605},{\"price\":81957.8,\"qty\":0.00130000},{\"price\":81960.2,\"qty\":0.00350000},{\"price\":81968.7,\"qty\":0.00524524},{\"price\":81974.0,\"qty\":0.01000000},{\"price\":81975.0,\"qty\":0.03252953},{\"price\":81976.3,\"qty\":0.00013459},{\"price\":81976.8,\"qty\":0.00115897},{\"price\":81979.2,\"qty\":0.00008998},{\"price\":81985.6,\"qty\":0.00403733},{\"price\":81987.0,\"qty\":0.00012572},{\"price\":81989.4,\"qty\":0.00171653},{\"price\":81994.4,\"qty\":0.00133641},{\"price\":81995.0,\"qty\":0.01906160},{\"price\":81995.8,\"qty\":0.00093081},{\"price\":81998.0,\"qty\":0.00174493},{\"price\":81999.0,\"qty\":0.10012195},{\"price\":81999.9,\"qty\":0.00010000},{\"price\":82000.0,\"qty\":7.85641664},{\"price\":82001.0,\"qty\":0.00031598},{\"price\":82010.0,\"qty\":25.00000000},{\"price\":82012.6,\"qty\":0.00168582},{\"price\":82024.0,\"qty\":0.00192850},{\"price\":82024.2,\"qty\":0.00121916},{\"price\":82025.3,\"qty\":0.33594539},{\"price\":82029.3,\"qty\":0.00024502},{\"price\":82035.5,\"qty\":0.00017883},{\"price\":82040.1,\"qty\":0.03757549},{\"price\":82063.3,\"qty\":0.00025158},{\"price\":82063.5,\"qty\":0.00518775},{\"price\":82063.8,\"qty\":0.00059201},{\"price\":82069.3,\"qty\":0.00167151},{\"price\":82072.0,\"qty\":0.00011702},{\"price\":82074.0,\"qty\":0.00063875},{\"price\":82074.3,\"qty\":0.00012595},{\"price\":82076.4,\"qty\":0.00523858},{\"price\":82081.6,\"qty\":0.43381581},{\"price\":82085.7,\"qty\":0.00005000},{\"price\":82087.8,\"qty\":0.00009271},{\"price\":82091.3,\"qty\":0.00154543},{\"price\":82092.6,\"qty\":0.00044416},{\"price\":82096.3,\"qty\":0.00276017},{\"price\":82096.4,\"qty\":0.00268131},{\"price\":82096.8,\"qty\":0.00021005},{\"price\":82098.9,\"qty\":0.00024361},{\"price\":82100.0,\"qty\":0.79955492},{\"price\":82101.0,\"qty\":0.08526083},{\"price\":82101.3,\"qty\":0.00011834},{\"price\":82107.0,\"qty\":0.00121792},{\"price\":82125.0,\"qty\":0.25000000},{\"price\":82126.7,\"qty\":0.00060881},{\"price\":82135.2,\"qty\":0.00017942},{\"price\":82143.1,\"qty\":0.01957015},{\"price\":82148.8,\"qty\":0.00209051},{\"price\":82150.0,\"qty\":0.00132596},{\"price\":82154.4,\"qty\":0.00082803},{\"price\":82155.0,\"qty\":0.00012596},{\"price\":82158.0,\"qty\":0.00070000},{\"price\":82158.9,\"qty\":0.00005592},{\"price\":82160.0,\"qty\":0.00374344},{\"price\":82163.5,\"qty\":0.02096612},{\"price\":82169.3,\"qty\":0.00005557},{\"price\":82170.7,\"qty\":0.00094072},{\"price\":82175.0,\"qty\":0.20148826},{\"price\":82175.7,\"qty\":0.00637931},{\"price\":82175.8,\"qty\":0.00022203},{\"price\":82185.7,\"qty\":0.00008975},{\"price\":82191.9,\"qty\":0.00102372},{\"price\":82199.1,\"qty\":0.00011533},{\"price\":82200.0,\"qty\":1.91915276},{\"price\":82216.0,\"qty\":0.00234349},{\"price\":82219.7,\"qty\":0.00800000},{\"price\":82224.5,\"qty\":0.00045485},{\"price\":82233.8,\"qty\":0.00012596},{\"price\":82236.2,\"qty\":0.00154283},{\"price\":82240.0,\"qty\":0.00135716},{\"price\":82243.0,\"qty\":0.02531418},{\"price\":82247.2,\"qty\":0.00123567},{\"price\":82254.5,\"qty\":0.00972591},{\"price\":82257.0,\"qty\":0.09600000},{\"price\":82262.9,\"qty\":0.00068406},{\"price\":82268.4,\"qty\":0.00036593},{\"price\":82284.4,\"qty\":0.00030653},{\"price\":82288.1,\"qty\":0.00151905},{\"price\":82291.0,\"qty\":0.00033732},{\"price\":82291.2,\"qty\":0.00058549},{\"price\":82295.0,\"qty\":0.10000000},{\"price\":82297.3,\"qty\":0.00084544},{\"price\":82300.0,\"qty\":0.37763736},{\"price\":82304.7,\"qty\":0.00024300},{\"price\":82306.2,\"qty\":0.03069922},{\"price\":82308.6,\"qty\":0.00149607},{\"price\":82309.2,\"qty\":0.00050262},{\"price\":82312.0,\"qty\":0.00282000},{\"price\":82312.8,\"qty\":0.00232700},{\"price\":82315.0,\"qty\":0.00030226},{\"price\":82318.1,\"qty\":0.00009225},{\"price\":82320.0,\"qty\":0.15000000},{\"price\":82320.5,\"qty\":0.00060848},{\"price\":82320.7,\"qty\":0.00062973},{\"price\":82325.0,\"qty\":0.03535000},{\"price\":82327.1,\"qty\":0.00015000},{\"price\":82327.8,\"qty\":0.00030633},{\"price\":82333.0,\"qty\":0.00250000},{\"price\":82335.3,\"qty\":0.00012899},{\"price\":82336.5,\"qty\":0.00061580},{\"price\":82337.5,\"qty\":0.03477008},{\"price\":82338.0,\"qty\":0.00079345},{\"price\":82339.0,\"qty\":0.00030208},{\"price\":82340.0,\"qty\":0.01000000},{\"price\":82341.0,\"qty\":0.00245697},{\"price\":82344.2,\"qty\":0.01800000},{\"price\":82345.0,\"qty\":0.32430435},{\"price\":82348.4,\"qty\":0.00977943},{\"price\":82350.0,\"qty\":0.96637315},{\"price\":82353.3,\"qty\":0.00135551},{\"price\":82359.8,\"qty\":0.00457269},{\"price\":82361.3,\"qty\":0.03254055},{\"price\":82363.0,\"qty\":0.00030191},{\"price\":82364.1,\"qty\":0.00191951},{\"price\":82367.7,\"qty\":0.00182300},{\"price\":82370.0,\"qty\":0.00607018},{\"price\":82372.3,\"qty\":0.00120492},{\"price\":82373.8,\"qty\":0.00013560},{\"price\":82375.3,\"qty\":0.00100000},{\"price\":82375.6,\"qty\":0.00019103},{\"price\":82386.0,\"qty\":0.00030173},{\"price\":82387.8,\"qty\":0.00350000},{\"price\":82388.0,\"qty\":0.00005552},{\"price\":82389.4,\"qty\":0.00055187},{\"price\":82392.6,\"qty\":0.00008947},{\"price\":82395.6,\"qty\":0.00014732},{\"price\":82398.6,\"qty\":1.00000000},{\"price\":82400.0,\"qty\":2.02404350},{\"price\":82410.0,\"qty\":0.00030156},{\"price\":82412.0,\"qty\":0.00022051},{\"price\":82412.6,\"qty\":0.05040851},{\"price\":82418.0,\"qty\":0.00282962},{\"price\":82419.7,\"qty\":0.00093306},{\"price\":82425.0,\"qty\":0.00019109},{\"price\":82426.0,\"qty\":0.00624422},{\"price\":82427.9,\"qty\":0.00013341},{\"price\":82433.0,\"qty\":0.00181966},{\"price\":82434.0,\"qty\":0.00030138},{\"price\":82435.4,\"qty\":0.00076955},{\"price\":82437.9,\"qty\":0.00019435},{\"price\":82438.8,\"qty\":0.00200000},{\"price\":82439.4,\"qty\":0.00024381},{\"price\":82443.0,\"qty\":0.00121295},{\"price\":82444.0,\"qty\":0.67444083},{\"price\":82444.3,\"qty\":0.00054588},{\"price\":82445.6,\"qty\":0.00019289},{\"price\":82445.9,\"qty\":0.00066755},{\"price\":82450.0,\"qty\":1.88963837},{\"price\":82450.5,\"qty\":0.00295308},{\"price\":82451.3,\"qty\":0.00005000},{\"price\":82455.0,\"qty\":0.10000000},{\"price\":82456.9,\"qty\":0.00012694},{\"price\":82457.0,\"qty\":0.00295373},{\"price\":82458.0,\"qty\":0.00030121},{\"price\":82458.5,\"qty\":0.00063451},{\"price\":82464.0,\"qty\":0.00036496},{\"price\":82464.1,\"qty\":0.00025547},{\"price\":82464.2,\"qty\":0.00373839},{\"price\":82468.0,\"qty\":0.01000000},{\"price\":82469.8,\"qty\":0.00295327},{\"price\":82472.9,\"qty\":0.31559082},{\"price\":82474.0,\"qty\":0.00353808},{\"price\":82480.0,\"qty\":0.06672016},{\"price\":82480.6,\"qty\":0.03232834},{\"price\":82480.9,\"qty\":0.00024437},{\"price\":82481.4,\"qty\":0.00084514},{\"price\":82482.0,\"qty\":0.00030103},{\"price\":82482.6,\"qty\":0.00005000},{\"price\":82488.0,\"qty\":4.15362765},{\"price\":82488.6,\"qty\":0.00061308},{\"price\":82498.3,\"qty\":0.00026794},{\"price\":82499.0,\"qty\":0.05256673},{\"price\":82500.0,\"qty\":9.28506790},{\"price\":82500.1,\"qty\":0.00576457},{\"price\":82504.3,\"qty\":0.00516108},{\"price\":82505.7,\"qty\":0.00037739},{\"price\":82506.0,\"qty\":0.00030086},{\"price\":82508.1,\"qty\":0.00030637},{\"price\":82511.4,\"qty\":0.00008982},{\"price\":82515.7,\"qty\":0.00229400},{\"price\":82520.9,\"qty\":0.00037455},{\"price\":82522.1,\"qty\":0.01289684},{\"price\":82523.6,\"qty\":0.00005075},{\"price\":82530.0,\"qty\":0.05000000},{\"price\":82540.0,\"qty\":0.00100000},{\"price\":82540.4,\"qty\":0.00018906},{\"price\":82544.3,\"qty\":0.00159203},{\"price\":82548.4,\"qty\":0.00021892},{\"price\":82554.7,\"qty\":0.00060566},{\"price\":82555.0,\"qty\":0.00268400},{\"price\":82558.2,\"qty\":0.00005000},{\"price\":82560.0,\"qty\":0.00024000},{\"price\":82563.5,\"qty\":0.00033914},{\"price\":82565.4,\"qty\":0.00130000},{\"price\":82565.9,\"qty\":0.05000000},{\"price\":82567.0,\"qty\":0.00242227},{\"price\":82567.5,\"qty\":0.00150000},{\"price\":82567.8,\"qty\":0.00143155},{\"price\":82568.5,\"qty\":0.07741218},{\"price\":82569.8,\"qty\":0.00005546},{\"price\":82573.4,\"qty\":0.00210114},{\"price\":82574.0,\"qty\":0.00161200},{\"price\":82578.4,\"qty\":2.51634399},{\"price\":82588.0,\"qty\":0.15750501},{\"price\":82590.6,\"qty\":0.00018135},{\"price\":82598.6,\"qty\":0.00009701},{\"price\":82599.0,\"qty\":0.01000000},{\"price\":82599.9,\"qty\":0.00010000},{\"price\":82600.0,\"qty\":1.32814227},{\"price\":82600.1,\"qty\":0.00008923},{\"price\":82600.5,\"qty\":0.03100000},{\"price\":82605.5,\"qty\":0.00083434},{\"price\":82607.4,\"qty\":0.00131104},{\"price\":82608.7,\"qty\":0.00067584},{\"price\":82620.0,\"qty\":0.00121036},{\"price\":82621.7,\"qty\":0.00012165},{\"price\":82623.4,\"qty\":0.01269032},{\"price\":82624.9,\"qty\":0.00030817},{\"price\":82630.0,\"qty\":0.00084023},{\"price\":82632.9,\"qty\":0.00061201},{\"price\":82633.0,\"qty\":0.00250000},{\"price\":82635.0,\"qty\":0.00632296},{\"price\":82639.1,\"qty\":0.06100000},{\"price\":82639.7,\"qty\":0.00204107},{\"price\":82644.2,\"qty\":0.00098710},{\"price\":82648.7,\"qty\":0.00021987},{\"price\":82650.0,\"qty\":0.00623457},{\"price\":82650.5,\"qty\":0.06600000},{\"price\":82651.6,\"qty\":0.00024198},{\"price\":82658.0,\"qty\":0.02419608},{\"price\":82660.0,\"qty\":0.25294600},{\"price\":82660.5,\"qty\":0.00294600},{\"price\":82666.3,\"qty\":0.00294592},{\"price\":82675.3,\"qty\":0.00502169},{\"price\":82682.0,\"qty\":0.00036430},{\"price\":82683.3,\"qty\":0.00025151},{\"price\":82688.0,\"qty\":0.02229058},{\"price\":82695.0,\"qty\":0.05000000},{\"price\":82697.5,\"qty\":0.00627567},{\"price\":82698.6,\"qty\":0.00294510},{\"price\":82698.9,\"qty\":0.00086772},{\"price\":82699.9,\"qty\":0.00011115},{\"price\":82700.0,\"qty\":0.50834108},{\"price\":82700.7,\"qty\":0.00084652},{\"price\":82701.0,\"qty\":0.00800000},{\"price\":82703.2,\"qty\":0.01000000},{\"price\":82705.6,\"qty\":0.00018900},{\"price\":82706.0,\"qty\":0.00015000},{\"price\":82708.7,\"qty\":0.00006465},{\"price\":82710.6,\"qty\":0.00008762},{\"price\":82712.5,\"qty\":0.01209008},{\"price\":82718.8,\"qty\":0.00012151},{\"price\":82725.0,\"qty\":0.00005078},{\"price\":82727.4,\"qty\":0.01269031},{\"price\":82733.4,\"qty\":0.00027815},{\"price\":82742.3,\"qty\":0.00009508},{\"price\":82743.8,\"qty\":0.00237640},{\"price\":82744.1,\"qty\":0.00040720},{\"price\":82747.7,\"qty\":0.00009191},{\"price\":82750.0,\"qty\":0.17077446},{\"price\":82754.1,\"qty\":0.00017692},{\"price\":82759.0,\"qty\":0.00025100},{\"price\":82761.8,\"qty\":0.00006666},{\"price\":82763.2,\"qty\":0.00025013},{\"price\":82763.5,\"qty\":0.00966610},{\"price\":82765.3,\"qty\":0.00267404},{\"price\":82766.5,\"qty\":0.00180000},{\"price\":82768.0,\"qty\":0.00005202},{\"price\":82768.2,\"qty\":0.00022501},{\"price\":82768.8,\"qty\":0.00006616},{\"price\":82769.1,\"qty\":0.00020245},{\"price\":82772.8,\"qty\":0.00030899},{\"price\":82776.2,\"qty\":0.00005533},{\"price\":82777.0,\"qty\":0.00866655},{\"price\":82782.4,\"qty\":0.00036855},{\"price\":82789.7,\"qty\":0.00051000},{\"price\":82790.0,\"qty\":0.24162830},{\"price\":82790.9,\"qty\":0.00614458},{\"price\":82792.0,\"qty\":0.00630200},{\"price\":82792.7,\"qty\":0.00846545},{\"price\":82799.2,\"qty\":0.00183800},{\"price\":82800.0,\"qty\":1.10153716},{\"price\":82802.2,\"qty\":0.00276017},{\"price\":82802.4,\"qty\":0.00268131},{\"price\":82802.6,\"qty\":0.00011702},{\"price\":82808.2,\"qty\":0.00008873},{\"price\":82815.2,\"qty\":0.00123118},{\"price\":82817.5,\"qty\":0.00350000},{\"price\":82820.0,\"qty\":0.00018670},{\"price\":82827.3,\"qty\":0.00017574},{\"price\":82827.4,\"qty\":0.00005513},{\"price\":82828.2,\"qty\":0.00013370},{\"price\":82832.1,\"qty\":0.00072356},{\"price\":82835.4,\"qty\":0.00168164},{\"price\":82839.0,\"qty\":0.00060166},{\"price\":82843.8,\"qty\":0.00037843},{\"price\":82845.0,\"qty\":0.08093151},{\"price\":82849.1,\"qty\":0.00061199},{\"price\":82850.0,\"qty\":0.99424520},{\"price\":82852.7,\"qty\":0.01943169},{\"price\":82857.9,\"qty\":0.00036433},{\"price\":82865.7,\"qty\":0.00513658},{\"price\":82867.0,\"qty\":0.00604583},{\"price\":82871.2,\"qty\":0.00018306},{\"price\":82873.1,\"qty\":0.00052723},{\"price\":82875.0,\"qty\":0.15264312},{\"price\":82879.8,\"qty\":0.00035911},{\"price\":82879.9,\"qty\":0.00007211},{\"price\":82880.7,\"qty\":0.18000000},{\"price\":82882.5,\"qty\":0.00005825},{\"price\":82882.7,\"qty\":0.00126686},{\"price\":82886.4,\"qty\":0.00021924},{\"price\":82888.0,\"qty\":0.05120644},{\"price\":82888.8,\"qty\":0.02000000},{\"price\":82891.2,\"qty\":0.00024128},{\"price\":82894.2,\"qty\":2.00000000},{\"price\":82896.6,\"qty\":0.00018877},{\"price\":82899.3,\"qty\":0.00099772},{\"price\":82900.0,\"qty\":2.92461690},{\"price\":82905.2,\"qty\":0.00067381},{\"price\":82907.1,\"qty\":0.04998031},{\"price\":82915.0,\"qty\":0.00550000},{\"price\":82917.7,\"qty\":0.00020797},{\"price\":82919.4,\"qty\":0.00008599},{\"price\":82932.2,\"qty\":0.00012119},{\"price\":82936.3,\"qty\":0.00005151},{\"price\":82938.0,\"qty\":0.00025094},{\"price\":82940.0,\"qty\":0.00038420},{\"price\":82950.0,\"qty\":0.04342151},{\"price\":82952.4,\"qty\":0.00091484},{\"price\":82964.2,\"qty\":0.01177600},{\"price\":82964.9,\"qty\":0.00011702},{\"price\":82966.6,\"qty\":0.00046018},{\"price\":82973.0,\"qty\":0.00013718},{\"price\":82974.0,\"qty\":0.00212965},{\"price\":82974.6,\"qty\":0.00007779},{\"price\":82975.3,\"qty\":0.00012359},{\"price\":82978.0,\"qty\":0.50000000},{\"price\":82982.2,\"qty\":0.00053013},{\"price\":82984.0,\"qty\":0.00111619},{\"price\":82986.0,\"qty\":0.00166300},{\"price\":82987.9,\"qty\":0.00012145}],\"checksum\":623583640,\"timestamp\":\"2026-09-07T08:51:28.839636Z\"}]}"}
{"stream":"book:BTC/USD","kind":"frame","seq":2,"receive_ts":1788771088968654000,"monotonic_ts":3188830798593083,"payload":"{\"channel\":\"book\",\"type\":\"update\",\"data\":[{\"symbol\":\"BTC/USD\",\"bids\":[{\"price\":78182.5,\"qty\":0.00000000},{\"price\":76894.7,\"qty\":0.00260096}],\"asks\":[],\"checksum\":623583640,\"timestamp\":\"2026-09-07T08:51:29.000002Z\"}]}"}
{"stream":"book:BTC/USD","kind":"frame","seq":3,"receive_ts":1788771088979322000,"monotonic_ts":3188830809260083,"payload":"{\"channel\":\"book\",\"type\":\"update\",\"data\":[{\"symbol\":\"BTC/USD\",\"bids\":[],\"asks\":[{\"price\":80384.9,\"qty\":0.12146123}],\"checksum\":623583640,\"timestamp\":\"2026-09-07T08:51:29.011764Z\"}]}"}
{"stream":"book:BTC/USD","kind":"frame","seq":4,"receive_ts":1788771089249728000,"monotonic_ts":3188831079665208,"payload":"{\"channel\":\"book\",\"type\":\"update\",\"data\":[{\"symbol\":\"BTC/USD\",\"bids\":[],\"asks\":[{\"price\":79481.4,\"qty\":0.01027530},{\"price\":79469.1,\"qty\":0.01370040}],\"checksum\":623583640,\"timestamp\":\"2026-09-07T08:51:29.232491Z\"}]}"}
{"stream":"book:BTC/USD","kind":"frame","seq":5,"receive_ts":1788771089249768000,"monotonic_ts":3188831079703375,"payload":"{\"channel\":\"book\",\"type\":\"update\",\"data\":[{\"symbol\":\"BTC/USD\",\"bids\":[{\"price\":79427.1,\"qty\":0.62498125}],\"asks\":[],\"checksum\":623583640,\"timestamp\":\"2026-09-07T08:51:29.233228Z\"}]}"}
{"stream":"book:BTC/USD","kind":"frame","seq":6,"receive_ts":1788771089249839000,"monotonic_ts":3188831079774750,"payload":"{\"channel\":\"book\",\"type\":\"update\",\"data\":[{\"symbol\":\"BTC/USD\",\"bids\":[{\"price\":79425.5,\"qty\":0.00000000},{\"price\":76893.7,\"qty\":0.01280000}],\"asks\":[],\"checksum\":623583640,\"timestamp\":\"2026-09-07T08:51:29.234060Z\"}]}"}
{"stream":"book:BTC/USD","kind":"frame","seq":7,"receive_ts":1788771089249850000,"monotonic_ts":3188831079785416,"payload":"{\"channel\":\"book\",\"type\":\"update\",\"data\":[{\"symbol\":\"BTC/USD\",\"bids\":[{\"price\":79422.8,\"qty\":0.93846728},{\"price\":79416.7,\"qty\":1.97759578}],\"asks\":[],\"checksum\":623583640,\"timestamp\":\"2026-09-07T08:51:29.234713Z\"}]}"}
{"stream":"book:BTC/USD","kind":"frame","seq":8,"receive_ts":1788771089261884000,"monotonic_ts":3188831091821041,"payload":"{\"channel\":\"book\",\"type\":\"update\",\"data\":[{\"symbol\":\"BTC/USD\",\"bids\":[],\"asks\":[{\"price\":79632.7,\"qty\":0.00000000},{\"price\":82986.0,\"qty\":0.00166300},{\"price\":79631.7,\"qty\":0.72441526}],\"checksum\":623583640,\"timestamp\":\"2026-09-07T08:51:29.296868Z\"}]}"}
{"stream":"book:BTC/USD","kind":"control","seq":9,"receive_ts":1788771089487105000,"monotonic_ts":3188831317041416,"payload":"{\"channel\":\"heartbeat\"}"}
{"stream":"book:BTC/USD","kind":"frame","seq":10,"receive_ts":1788771089498011000,"monotonic_ts":3188831327947666,"payload":"{\"channel\":\"book\",\"type\":\"update\",\"data\":[{\"symbol\":\"BTC/USD\",\"bids\":[],\"asks\":[{\"price\":79481.4,\"qty\":0.00342510},{\"price\":79468.7,\"qty\":0.00685020}],\"checksum\":623583640,\"timestamp\":\"2026-09-07T08:51:29.532498Z\"}]}"}
{"stream":"book:BTC/USD","kind":"frame","seq":11,"receive_ts":1788771089503464000,"monotonic_ts":3188831333399375,"payload":"{\"channel\":\"book\",\"type\":\"update\",\"data\":[{\"symbol\":\"BTC/USD\",\"bids\":[],\"asks\":[{\"price\":79525.0,\"qty\":0.00000000},{\"price\":82984.0,\"qty\":0.00111619}],\"checksum\":623583640,\"timestamp\":\"2026-09-07T08:51:29.538993Z\"}]}"}
{"stream":"book:BTC/USD","kind":"frame","seq":12,"receive_ts":1788771089523453000,"monotonic_ts":3188831353389125,"payload":"{\"channel\":\"book\",\"type\":\"update\",\"data\":[{\"symbol\":\"BTC/USD\",\"bids\":[],\"asks\":[{\"price\":80392.7,\"qty\":0.20568503}],\"checksum\":623583640,\"timestamp\":\"2026-09-07T08:51:29.558979Z\"}]}"}
{"stream":"book:BTC/USD","kind":"frame","seq":13,"receive_ts":1788771089571687000,"monotonic_ts":3188831401622583,"payload":"{\"channel\":\"book\",\"type\":\"update\",\"data\":[{\"symbol\":\"BTC/USD\",\"bids\":[{\"price\":78901.2,\"qty\":0.82622633},{\"price\":78827.9,\"qty\":4.60742678}],\"asks\":[],\"checksum\":623583640,\"timestamp\":\"2026-09-07T08:51:29.606108Z\"}]}"}
{"stream":"book:BTC/USD","kind":"frame","seq":14,"receive_ts":1788771089805027000,"monotonic_ts":3188831634961250,"payload":"{\"channel\":\"book\",\"type\":\"update\",\"data\":[{\"symbol\":\"BTC/USD\",\"bids\":[{\"price\":79416.7,\"qty\":1.88422139},{\"price\":79422.9,\"qty\":0.09337439}],\"asks\":[],\"checksum\":623583640,\"timestamp\":\"2026-09-07T08:51:29.839959Z\"}]}"}
{"stream":"book:BTC/USD","kind":"frame","seq":15,"receive_ts":1788771089880795000,"monotonic_ts":3188831710730250,"payload":"{\"channel\":\"book\",\"type\":\"update\",\"data\":[{\"symbol\":\"BTC/USD\",\"bids\":[{\"price\":79271.2,\"qty\":0.00000000},{\"price\":76893.7,\"qty\":0.01280000},{\"price\":79270.7,\"qty\":0.73141487}],\"asks\":[],\"checksum\":623583640,\"timestamp\":\"2026-09-07T08:51:29.915813Z\"}]}"}
{"stream":"book:BTC/USD","kind":"frame","seq":16,"receive_ts":1788771090136914000,"monotonic_ts":3188831966848250,"payload":"{\"channel\":\"book\",\"type\":\"update\",\"data\":[{\"symbol\":\"BTC/USD\",\"bids\":[{\"price\":79386.0,\"qty\":0.00000000},{\"price\":76893.7,\"qty\":0.01280000}],\"asks\":[],\"checksum\":623583640,\"timestamp\":\"2026-09-07T08:51:30.143942Z\"}]}"}
{"stream":"book:BTC/USD","kind":"frame","seq":17,"receive_ts":1788771090136939000,"monotonic_ts":3188831966871166,"payload":"{\"channel\":\"book\",\"type\":\"update\",\"data\":[{\"symbol\":\"BTC/USD\",\"bids\":[{\"price\":79422.7,\"qty\":0.00000000},{\"price\":76892.1,\"qty\":0.00204000}],\"asks\":[],\"checksum\":623583640,\"timestamp\":\"2026-09-07T08:51:30.144184Z\"}]}"}
{"stream":"book:BTC/USD","kind":"frame","seq":18,"receive_ts":1788771090137075000,"monotonic_ts":3188831967007708,"payload":"{\"channel\":\"book\",\"type\":\"update\",\"data\":[{\"symbol\":\"BTC/USD\",\"bids\":[{\"price\":79362.7,\"qty\":0.44051800}],\"asks\":[],\"checksum\":623583640,\"timestamp\":\"2026-09-07T08:51:30.145544Z\"}]}"}
{"stream":"book:BTC/USD","kind":"frame","seq":19,"receive_ts":1788771090137085000,"monotonic_ts":3188831967017000,"payload":"{\"channel\":\"book\",\"type\":\"update\",\"data\":[{\"symbol\":\"BTC/USD\",\"bids\":[{\"price\":79406.4,\"qty\":0.50347603}],\"asks\":[],\"checksum\":623583640,\"timestamp\":\"2026-09-07T08:51:30.146538Z\"}]}"}
{"stream":"book:BTC/USD","kind":"frame","seq":20,"receive_ts":1788771090137268000,"monotonic_ts":3188831967199833,"payload":"{\"channel\":\"book\",\"type\":\"update\",\"data\":[{\"symbol\":\"BTC/USD\",\"bids\":[{\"price\":79426.5,\"qty\":0.00125903}],\"asks\":[],\"checksum\":623583640,\"timestamp\":\"2026-09-07T08:51:30.170193Z\"}]}"}
{"stream":"book:BTC/USD","kind":"frame","seq":21,"receive_ts":1788771090257858000,"monotonic_ts":3188832087791625,"payload":"{\"channel\":\"book\",\"type\":\"update\",\"data\":[{\"symbol\":\"BTC/USD\",\"bids\":[{\"price\":79422.8,\"qty\":0.00000000},{\"price\":76893.7,\"qty\":0.01280000},{\"price\":79416.8,\"qty\":0.93853818}],\"asks\":[],\"checksum\":623583640,\"timestamp\":\"2026-09-07T08:51:30.290248Z\"}]}"}
{"stream":"book:BTC/USD","kind":"frame","seq":22,"receive_ts":1788771090270926000,"monotonic_ts":3188832100859791,"payload":"{\"channel\":\"book\",\"type\":\"update\",\"data\":[{\"symbol\":\"BTC/USD\",\"bids\":[{\"price\":79092.5,\"qty\":0.00000000},{\"price\":76893.7,\"qty\":0.01280000},{\"price\":79091.8,\"qty\":5.66266610}],\"asks\":[],\"checksum\":623583640,\"timestamp\":\"2026-09-07T08:51:30.302924Z\"}]}"}
{"stream":"book:BTC/USD","kind":"frame","seq":23,"receive_ts":1788771090270955000,"monotonic_ts":3188832100886750,"payload":"{\"channel\":\"book\",\"type\":\"update\",\"data\":[{\"symbol\":\"BTC/USD\",\"bids\":[],\"asks\":[{\"price\":79809.9,\"qty\":0.00000000},{\"price\":82984.0,\"qty\":0.00111619},{\"price\":79810.6,\"qty\":1.23019263}],\"checksum\":623583640,\"timestamp\":\"2026-09-07T08:51:30.303076Z\"}]}"}
{"stream":"book:BTC/USD","kind":"frame","seq":24,"receive_ts":1788771090316460000,"monotonic_ts":3188832146393291,"payload":"{\"channel\":\"book\",\"type\":\"update\",\"data\":[{\"symbol\":\"BTC/USD\",\"bids\":[{\"price\":79422.9,\"qty\":0.00000000},{\"price\":76892.1,\"qty\":0.00204000},{\"price\":79416.9,\"qty\":0.09337439}],\"asks\":[],\"checksum\":623583640,\"timestamp\":\"2026-09-07T08:51:30.351441Z\"}]}"}
{"stream":"book:BTC/USD","kind":"frame","seq":25,"receive_ts":1788771090449056000,"monotonic_ts":3188832278988541,"payload":"{\"channel\":\"book\",\"type\":\"update\",\"data\":[{\"symbol\":\"BTC/USD\",\"bids\":[],\"asks\":[{\"price\":80349.9,\"qty\":0.02431069}],\"checksum\":623583640,\"timestamp\":\"2026-09-07T08:51:30.483480Z\"}]}"}
{"stream":"book:BTC/USD","kind":"frame","seq":26,"receive_ts":1788771090449225000,"monotonic_ts":3188832279156000,"payload":"{\"channel\":\"book\",\"type\":\"update\",\"data\":[{\"symbol\":\"BTC/USD\",\"bids\":[],\"asks\":[{\"price\":80392.7,\"qty\":0.20823955}],\"checksum\":623583640,\"timestamp\":\"2026-09-07T08:51:30.483720Z\"}]}"}
{"stream":"book:BTC/USD","kind":"control","seq":27,"receive_ts":1788771090488345000,"monotonic_ts":3188832318277875,"payload":"{\"channel\":\"heartbeat\"}"}
{"stream":"book:BTC/USD","kind":"frame","seq":28,"receive_ts":1788771091234078000,"monotonic_ts":3188833064008375,"payload":"{\"channel\":\"book\",\"type\":\"update\",\"data\":[{\"symbol\":\"BTC/USD\",\"bids\":[{\"price\":79298.4,\"qty\":0.00000000},{\"price\":76892.1,\"qty\":0.00204000}],\"asks\":[],\"checksum\":623583640,\"timestamp\":\"2026-09-07T08:51:30.995438Z\"}]}"}
{"stream":"book:BTC/USD","kind":"frame","seq":29,"receive_ts":1788771091235177000,"monotonic_ts":3188833065106000,"payload":"{\"channel\":\"book\",\"type\":\"update\",\"data\":[{\"symbol\":\"BTC/USD\",\"bids\":[],\"asks\":[{\"price\":81838.7,\"qty\":0.47005146}],\"checksum\":623583640,\"timestamp\":\"2026-09-07T08:51:31.121516Z\"}]}"}
{"stream":"book:BTC/USD","kind":"frame","seq":30,"receive_ts":1788771091235280000,"monotonic_ts":3188833065207916,"payload":"{\"channel\":\"book\",\"type\":\"update\",\"data\":[{\"symbol\":\"BTC/USD\",\"bids\":[],\"asks\":[{\"price\":81838.7,\"qty\":0.49093194}],\"checksum\":623583640,\"timestamp\":\"2026-09-07T08:51:31.128312Z\"}]}"}
{"stream":"book:BTC/USD","kind":"frame","seq":31,"receive_ts":1788771091235358000,"monotonic_ts":3188833065286208,"payload":"{\"channel\":\"book\",\"type\":\"update\",\"data\":[{\"symbol\":\"BTC/USD\",\"bids\":[{\"price\":79303.2,\"qty\":0.03284488}],\"asks\":[],\"checksum\":623583640,\"timestamp\":\"2026-09-07T08:51:31.220463Z\"}]}"}
{"stream":"book:BTC/USD","kind":"frame","seq":32,"receive_ts":1788771091235449000,"monotonic_ts":3188833065376708,"payload":"{\"channel\":\"book\",\"type\":\"update\",\"data\":[{\"symbol\":\"BTC/USD\",\"bids\":[],\"asks\":[{\"price\":79481.4,\"qty\":0.00000000},{\"price\":82982.2,\"qty\":0.00053013},{\"price\":79468.7,\"qty\":0.01027530}],\"checksum\":623583640,\"timestamp\":\"2026-09-07T08:51:31.257704Z\"}]}"}
{"stream":"book:BTC/USD","kind":"frame","seq":33,"receive_ts":1788771091235604000,"monotonic_ts":3188833065531958,"payload":"{\"channel\":\"book\",\"type\":\"update\",\"data\":[{\"symbol\":\"BTC/USD\",\"bids\":[],\"asks\":[{\"price\":79525.0,\"qty\":0.05440000}],\"checksum\":623583640,\"timestamp\":\"2026-09-07T08:51:31.260084Z\"}]}"}
{"stream":"book:BTC/USD","kind":"frame","seq":34,"receive_ts":1788771091276052000,"monotonic_ts":3188833105982708,"payload":"{\"channel\":\"book\",\"type\":\"update\",\"data\":[{\"symbol\":\"BTC/USD\",\"bids\":[],\"asks\":[{\"price\":79631.7,\"qty\":0.00000000},{\"price\":82982.2,\"qty\":0.00053013},{\"price\":79631.9,\"qty\":0.72434344}],\"checksum\":623583640,\"timestamp\":\"2026-09-07T08:51:31.309613Z\"}]}"}
{"stream":"book:BTC/USD","kind":"frame","seq":35,"receive_ts":1788771091368625000,"monotonic_ts":3188833198554583,"payload":"{\"channel\":\"book\",\"type\":\"update\",\"data\":[{\"symbol\":\"BTC/USD\",\"bids\":[{\"price\":79426.3,\"qty\":0.00000000},{\"price\":76892.1,\"qty\":0.00204000},{\"price\":79427.1,\"qty\":0.66274451}],\"asks\":[],\"checksum\":623583640,\"timestamp\":\"2026-09-07T08:51:31.401410Z\"}]}"}
{"stream":"book:BTC/USD","kind":"frame","seq":36,"receive_ts":1788771091368657000,"monotonic_ts":3188833198584041,"payload":"{\"channel\":\"book\",\"type\":\"update\",\"data\":[{\"symbol\":\"BTC/USD\",\"bids\":[{\"price\":79429.1,\"qty\":0.02517593}],\"asks\":[],\"checksum\":623583640,\"timestamp\":\"2026-09-07T08:51:31.401662Z\"}]}"}
{"stream":"book:BTC/USD","kind":"frame","seq":37,"receive_ts":1788771091479185000,"monotonic_ts":3188833309113916,"payload":"{\"channel\":\"book\",\"type\":\"update\",\"data\":[{\"symbol\":\"BTC/USD\",\"bids\":[],\"asks\":[{\"price\":79482.7,\"qty\":0.00000000},{\"price\":82982.2,\"qty\":0.00053013}],\"checksum\":623583640,\"timestamp\":\"2026-09-07T08:51:31.508125Z\"}]}"}
{"stream":"book:BTC/USD","kind":"frame","seq":38,"receive_ts":1788771091479214000,"monotonic_ts":3188833309140625,"payload":"{\"channel\":\"book\",\"type\":\"update\",\"data\":[{\"symbol\":\"BTC/USD\",\"bids\":[{\"price\":79404.5,\"qty\":0.00000000},{\"price\":76892.1,\"qty\":0.00204000}],\"asks\":[],\"checksum\":623583640,\"timestamp\":\"2026-09-07T08:51:31.508135Z\"}]}"}
{"stream":"book:BTC/USD","kind":"control","seq":39,"receive_ts":1788771091496888000,"monotonic_ts":3188833326818000,"payload":"{\"channel\":\"heartbeat\"}"}
{"stream":"book:BTC/USD","kind":"frame","seq":40,"receive_ts":1788771091746299000,"monotonic_ts":3188833576229875,"payload":"{\"channel\":\"book\",\"type\":\"update\",\"data\":[{\"symbol\":\"BTC/USD\",\"bids\":[{\"price\":79454.9,\"qty\":0.03628712}],\"asks\":[],\"checksum\":1095953007,\"timestamp\":\"2026-09-07T08:51:31.744749Z\"}]}"}
{"stream":"book:BTC/USD","kind":"frame","seq":41,"receive_ts":1788771091768950000,"monotonic_ts":3188833598877500,"payload":"{\"channel\":\"book\",\"type\":\"update\",\"data\":[{\"symbol\":\"BTC/USD\",\"bids\":[],\"asks\":[{\"price\":79455.0,\"qty\":3.41615641}],\"checksum\":1456718264,\"timestamp\":\"2026-09-07T08:51:31.803904Z\"}]}"}
{"stream":"book:BTC/USD","kind":"frame","seq":42,"receive_ts":1788771091779919000,"monotonic_ts":3188833609846958,"payload":"{\"channel\":\"book\",\"type\":\"update\",\"data\":[{\"symbol\":\"BTC/USD\",\"bids\":[{\"price\":79454.9,\"qty\":0.03581515}],\"asks\":[],\"checksum\":3217313727,\"timestamp\":\"2026-09-07T08:51:31.813369Z\"}]}"}
{"stream":"book:BTC/USD","kind":"frame","seq":43,"receive_ts":1788771091849085000,"monotonic_ts":3188833679012291,"payload":"{\"channel\":\"book\",\"type\":\"update\",\"data\":[{\"symbol\":\"BTC/USD\",\"bids\":[{\"price\":79454.9,\"qty\":0.03534318}],\"asks\":[],\"checksum\":3267187528,\"timestamp\":\"2026-09-07T08:51:31.882815Z\"}]}"}
{"stream":"book:BTC/USD","kind":"frame","seq":44,"receive_ts":1788771091883807000,"monotonic_ts":3188833713733958,"payload":"{\"channel\":\"book\",\"type\":\"update\",\"data\":[{\"symbol\":\"BTC/USD\",\"bids\":[{\"price\":79371.0,\"qty\":0.00000000},{\"price\":76889.1,\"qty\":0.05345997},{\"price\":79368.5,\"qty\":0.86700883}],\"asks\":[],\"checksum\":3267187528,\"timestamp\":\"2026-09-07T08:51:31.916489Z\"}]}"}
{"stream":"book:BTC/USD","kind":"frame","seq":45,"receive_ts":1788771091883836000,"monotonic_ts":3188833713761833,"payload":"{\"channel\":\"book\",\"type\":\"update\",\"data\":[{\"symbol\":\"BTC/USD\",\"bids\":[{\"price\":79367.2,\"qty\":0.00000000},{\"price\":76883.0,\"qty\":0.04075090},{\"price\":79364.7,\"qty\":0.34006000}],\"asks\":[],\"checksum\":3267187528,\"timestamp\":\"2026-09-07T08:51:31.916752Z\"}]}"}
{"stream":"book:BTC/USD","kind":"frame","seq":46,"receive_ts":1788771091883842000,"monotonic_ts":3188833713767708,"payload":"{\"channel\":\"book\",\"type\":\"update\",\"data\":[{\"symbol\":\"BTC/USD\",\"bids\":[{\"price\":79418.0,\"qty\":0.00000000},{\"price\":76883.0,\"qty\":0.04075090}],\"asks\":[],\"checksum\":3267187528,\"timestamp\":\"2026-09-07T08:51:31.917041Z\"}]}"}
{"stream":"book:BTC/USD","kind":"frame","seq":47,"receive_ts":1788771091886527000,"monotonic_ts":3188833716453333,"payload":"{\"channel\":\"book\",\"type\":\"update\",\"data\":[{\"symbol\":\"BTC/USD\",\"bids\":[{\"price\":79416.6,\"qty\":6.29590771}],\"asks\":[],\"checksum\":3267187528,\"timestamp\":\"2026-09-07T08:51:31.917999Z\"}]}"}
{"stream":"book:BTC/USD","kind":"frame","seq":48,"receive_ts":1788771091886550000,"monotonic_ts":3188833716475791,"payload":"{\"channel\":\"book\",\"type\":\"update\",\"data\":[{\"symbol\":\"BTC/USD\",\"bids\":[{\"price\":79408.7,\"qty\":0.00000000},{\"price\":76880.0,\"qty\":0.00100000}],\"asks\":[],\"checksum\":3267187528,\"timestamp\":\"2026-09-07T08:51:31.918036Z\"}]}"}
{"stream":"book:BTC/USD","kind":"frame","seq":49,"receive_ts":1788771091888442000,"monotonic_ts":3188833718368250,"payload":"{\"channel\":\"book\",\"type\":\"update\",\"data\":[{\"symbol\":\"BTC/USD\",\"bids\":[],\"asks\":[{\"price\":79459.5,\"qty\":0.04379642}],\"checksum\":4027416697,\"timestamp\":\"2026-09-07T08:51:31.924096Z\"}]}"}
{"stream":"book:BTC/USD","kind":"frame","seq":50,"receive_ts":1788771091896959000,"monotonic_ts":3188833726886000,"payload":"{\"channel\":\"book\",\"type\":\"update\",\"data\":[{\"symbol\":\"BTC/USD\",\"bids\":[{\"price\":79426.4,\"qty\":0.00341403},{\"price\":79427.2,\"qty\":0.00685020}],\"asks\":[],\"checksum\":4027416697,\"timestamp\":\"2026-09-07T08:51:31.928567Z\"}]}"}
{"stream":"book:BTC/USD","kind":"frame","seq":51,"receive_ts":1788771091902033000,"monotonic_ts":3188833731960083,"payload":"{\"channel\":\"book\",\"type\":\"update\",\"data\":[{\"symbol\":\"BTC/USD\",\"bids\":[{\"price\":79270.7,\"qty\":0.00000000},{\"price\":76880.0,\"qty\":0.00100000},{\"price\":79270.5,\"qty\":0.73134299}],\"asks\":[],\"checksum\":4027416697,\"timestamp\":\"2026-09-07T08:51:31.930813Z\"}]}"}
{"stream":"book:BTC/USD","kind":"frame","seq":52,"receive_ts":1788771091917732000,"monotonic_ts":3188833747658583,"payload":"{\"channel\":\"book\",\"type\":\"update\",\"data\":[{\"symbol\":\"BTC/USD\",\"bids\":[{\"price\":79436.6,\"qty\":0.00000000},{\"price\":76880.0,\"qty\":0.00100000}],\"asks\":[],\"checksum\":4027416697,\"timestamp\":\"2026-09-07T08:51:31.951594Z\"}]}"}
{"stream":"book:BTC/USD","kind":"frame","seq":53,"receive_ts":1788771091917763000,"monotonic_ts":3188833747688041,"payload":"{\"channel\":\"book\",\"type\":\"update\",\"data\":[{\"symbol\":\"BTC/USD\",\"bids\":[{\"price\":79439.3,\"qty\":0.62941111}],\"asks\":[],\"checksum\":4027416697,\"timestamp\":\"2026-09-07T08:51:31.952563Z\"}]}"}
{"stream":"book:BTC/USD","kind":"frame","seq":54,"receive_ts":1788771091920600000,"monotonic_ts":3188833750526416,"payload":"{\"channel\":\"book\",\"type\":\"update\",\"data\":[{\"symbol\":\"BTC/USD\",\"bids\":[{\"price\":79416.9,\"qty\":0.00000000},{\"price\":76880.0,\"qty\":0.00100000},{\"price\":79416.8,\"qty\":1.03191988}],\"asks\":[],\"checksum\":4027416697,\"timestamp\":\"2026-09-07T08:51:31.953308Z\"}]}"}
{"stream":"book:BTC/USD","kind":"frame","seq":55,"receive_ts":1788771091923024000,"monotonic_ts":3188833752949333,"payload":"{\"channel\":\"book\",\"type\":\"update\",\"data\":[{\"symbol\":\"BTC/USD\",\"bids\":[{\"price\":79172.2,\"qty\":0.00000000},{\"price\":76872.0,\"qty\":0.10000000}],\"asks\":[],\"checksum\":4027416697,\"timestamp\":\"2026-09-07T08:51:31.959020Z\"}]}"}
{"stream":"book:BTC/USD","kind":"frame","seq":56,"receive_ts":1788771091923034000,"monotonic_ts":3188833752959583,"payload":"{\"channel\":\"book\",\"type\":\"update\",\"data\":[{\"symbol\":\"BTC/USD\",\"bids\":[{\"price\":79411.3,\"qty\":0.00000000},{\"price\":76869.7,\"qty\":0.00088591}],\"asks\":[],\"checksum\":4027416697,\"timestamp\":\"2026-09-07T08:51:31.959097Z\"}]}"}
{"stream":"book:BTC/USD","kind":"frame","seq":57,"receive_ts":1788771091926588000,"monotonic_ts":3188833756513708,"payload":"{\"channel\":\"book\",\"type\":\"update\",\"data\":[{\"symbol\":\"BTC/USD\",\"bids\":[{\"price\":79454.9,\"qty\":0.03487121}],\"asks\":[],\"checksum\":2501015862,\"timestamp\":\"2026-09-07T08:51:31.960739Z\"}]}"}
{"stream":"book:BTC/USD","kind":"frame","seq":58,"receive_ts":1788771091992777000,"monotonic_ts":3188833822704083,"payload":"{\"channel\":\"book\",\"type\":\"update\",\"data\":[{\"symbol\":\"BTC/USD\",\"bids\":[{\"price\":79454.9,\"qty\":0.03439924}],\"asks\":[],\"checksum\":2923882139,\"timestamp\":\"2026-09-07T08:51:32.027854Z\"}]}"}
{"stream":"book:BTC/USD","kind":"frame","seq":59,"receive_ts":1788771091996949000,"monotonic_ts":3188833826875500,"payload":"{\"channel\":\"book\",\"type\":\"update\",\"data\":[{\"symbol\":\"BTC/USD\",\"bids\":[],\"asks\":[{\"price\":79462.5,\"qty\":0.00000000},{\"price\":82982.2,\"qty\":0.00053013}],\"checksum\":2923882139,\"timestamp\":\"2026-09-07T08:51:32.031101Z\"}]}"}
{"stream":"book:BTC/USD","kind":"frame","seq":60,"receive_ts":1788771091996970000,"monotonic_ts":3188833826895333,"payload":"{\"channel\":\"book\",\"type\":\"update\",\"data\":[{\"symbol\":\"BTC/USD\",\"bids\":[],\"asks\":[{\"price\":79458.6,\"qty\":0.00005100}],\"checksum\":1865153085,\"timestamp\":\"2026-09-07T08:51:32.031118Z\"}]}"}
{"stream":"book:BTC/USD","kind":"frame","seq":61,"receive_ts":1788771092060462000,"monotonic_ts":3188833890389125,"payload":"{\"channel\":\"book\",\"type\":\"update\",\"data\":[{\"symbol\":\"BTC/USD\",\"bids\":[{\"price\":79454.9,\"qty\":0.03392727}],\"asks\":[],\"checksum\":3528967398,\"timestamp\":\"2026-09-07T08:51:32.094868Z\"}]}"}
{"stream":"book:BTC/USD","kind":"frame","seq":62,"receive_ts":1788771092129766000,"monotonic_ts":3188833959693166,"payload":"{\"channel\":\"book\",\"type\":\"update\",\"data\":[{\"symbol\":\"BTC/USD\",\"bids\":[{\"price\":79454.9,\"qty\":0.03345530}],\"asks\":[],\"checksum\":3232588654,\"timestamp\":\"2026-09-07T08:51:32.163272Z\"}]}"}
{"stream":"book:BTC/USD","kind":"frame","seq":63,"receive_ts":1788771092152469000,"monotonic_ts":3188833982395000,"payload":"{\"channel\":\"book\",\"type\":\"update\",\"data\":[{\"symbol\":\"BTC/USD\",\"bids\":[{\"price\":79172.2,\"qty\":0.00226856}],\"asks\":[],\"checksum\":3232588654,\"timestamp\":\"2026-09-07T08:51:32.186676Z\"}]}"}
{"stream":"book:BTC/USD","kind":"frame","seq":64,"receive_ts":1788771092152502000,"monotonic_ts":3188833982426583,"payload":"{\"channel\":\"book\",\"type\":\"update\",\"data\":[{\"symbol\":\"BTC/USD\",\"bids\":[{\"price\":79411.3,\"qty\":0.00226856}],\"asks\":[],\"checksum\":3232588654,\"timestamp\":\"2026-09-07T08:51:32.186715Z\"}]}"}
{"stream":"book:BTC/USD","kind":"frame","seq":65,"receive_ts":1788771092194649000,"monotonic_ts":3188834024575916,"payload":"{\"channel\":\"book\",\"type\":\"update\",\"data\":[{\"symbol\":\"BTC/USD\",\"bids\":[{\"price\":79454.9,\"qty\":0.03298333}],\"asks\":[],\"checksum\":2017880293,\"timestamp\":\"2026-09-07T08:51:32.228695Z\"}]}"}
{"stream":"book:BTC/USD","kind":"frame","seq":66,"receive_ts":1788771092242080000,"monotonic_ts":3188834072006458,"payload":"{\"channel\":\"book\",\"type\":\"update\",\"data\":[{\"symbol\":\"BTC/USD\",\"bids\":[{\"price\":77071.2,\"qty\":0.45947211}],\"asks\":[],\"checksum\":2017880293,\"timestamp\":\"2026-09-07T08:51:32.274280Z\"}]}"}
{"stream":"book:BTC/USD","kind":"frame","seq":67,"receive_ts":1788771092247324000,"monotonic_ts":3188834077249666,"payload":"{\"channel\":\"book\",\"type\":\"update\",\"data\":[{\"symbol\":\"BTC/USD\",\"bids\":[{\"price\":77071.2,\"qty\":0.52130031}],\"asks\":[],\"checksum\":2017880293,\"timestamp\":\"2026-09-07T08:51:32.281137Z\"}]}"}
{"stream":"book:BTC/USD","kind":"frame","seq":68,"receive_ts":1788771092262011000,"monotonic_ts":3188834091936541,"payload":"{\"channel\":\"book\",\"type\":\"update\",\"data\":[{\"symbol\":\"BTC/USD\",\"bids\":[{\"price\":79454.9,\"qty\":0.03251136}],\"asks\":[],\"checksum\":360307505,\"timestamp\":\"2026-09-07T08:51:32.296675Z\"}]}"}
{"stream":"book:BTC/USD","kind":"frame","seq":69,"receive_ts":1788771092327649000,"monotonic_ts":3188834157574541,"payload":"{\"channel\":\"book\",\"type\":\"update\",\"data\":[{\"symbol\":\"BTC/USD\",\"bids\":[{\"price\":79454.9,\"qty\":0.03203939}],\"asks\":[],\"checksum\":2082755422,\"timestamp\":\"2026-09-07T08:51:32.363433Z\"}]}"}
{"stream":"book:BTC/USD","kind":"frame","seq":70,"receive_ts":1788771092347565000,"monotonic_ts":3188834177490125,"payload":"{\"channel\":\"book\",\"type\":\"update\",\"data\":[{\"symbol\":\"BTC/USD\",\"bids\":[{\"price\":78912.2,\"qty\":0.03392727}],\"asks\":[],\"checksum\":2082755422,\"timestamp\":\"2026-09-07T08:51:32.382448Z\"}]}"}
{"stream":"book:BTC/USD","kind":"frame","seq":71,"receive_ts":1788771092361569000,"monotonic_ts":3188834191494041,"payload":"{\"channel\":\"book\",\"type\":\"update\",\"data\":[{\"symbol\":\"BTC/USD\",\"bids\":[],\"asks\":[{\"price\":81838.7,\"qty\":0.47005146}],\"checksum\":2082755422,\"timestamp\":\"2026-09-07T08:51:32.394451Z\"}]}"}
{"stream":"book:BTC/USD","kind":"frame","seq":72,"receive_ts":1788771092366856000,"monotonic_ts":3188834196781541,"payload":"{\"channel\":\"book\",\"type\":\"update\",\"data\":[{\"symbol\":\"BTC/USD\",\"bids\":[],\"asks\":[{\"price\":81838.7,\"qty\":0.49093194}],\"checksum\":2082755422,\"timestamp\":\"2026-09-07T08:51:32.400404Z\"}]}"}
{"stream":"book:BTC/USD","kind":"frame","seq":73,"receive_ts":1788771092385361000,"monotonic_ts":3188834215286291,"payload":"{\"channel\":\"book\",\"type\":\"update\",\"data\":[{\"symbol\":\"BTC/USD\",\"bids\":[{\"price\":79426.5,\"qty\":0.00000000},{\"price\":76880.0,\"qty\":0.00100000}],\"asks\":[],\"checksum\":2082755422,\"timestamp\":\"2026-09-07T08:51:32.420162Z\"}]}"}
{"stream":"book:BTC/USD","kind":"frame","seq":74,"receive_ts":1788771092387563000,"monotonic_ts":3188834217487416,"payload":"{\"channel\":\"book\",\"type\":\"update\",\"data\":[{\"symbol\":\"BTC/USD\",\"bids\":[{\"price\":79427.3,\"qty\":0.00125902}],\"asks\":[],\"checksum\":2082755422,\"timestamp\":\"2026-09-07T08:51:32.420288Z\"}]}"}
{"stream":"book:BTC/USD","kind":"frame","seq":75,"receive_ts":1788771092390713000,"monotonic_ts":3188834220637750,"payload":"{\"channel\":\"book\",\"type\":\"update\",\"data\":[{\"symbol\":\"BTC/USD\",\"bids\":[{\"price\":79416.4,\"qty\":0.04313162}],\"asks\":[],\"checksum\":2082755422,\"timestamp\":\"2026-09-07T08:51:32.423651Z\"}]}"}
{"stream":"book:BTC/USD","kind":"frame","seq":76,"receive_ts":1788771092390732000,"monotonic_ts":3188834220656041,"payload":"{\"channel\":\"book\",\"type\":\"update\",\"data\":[{\"symbol\":\"BTC/USD\",\"bids\":[{\"price\":79415.1,\"qty\":0.09096372}],\"asks\":[],\"checksum\":2082755422,\"timestamp\":\"2026-09-07T08:51:32.423684Z\"}]}"}
{"stream":"book:BTC/USD","kind":"frame","seq":77,"receive_ts":1788771092390881000,"monotonic_ts":3188834220805041,"payload":"{\"channel\":\"book\",\"type\":\"update\",\"data\":[{\"symbol\":\"BTC/USD\",\"bids\":[{\"price\":79407.1,\"qty\":0.14692533}],\"asks\":[],\"checksum\":2082755422,\"timestamp\":\"2026-09-07T08:51:32.424030Z\"}]}"}
{"stream":"book:BTC/USD","kind":"frame","seq":78,"receive_ts":1788771092393738000,"monotonic_ts":3188834223662083,"payload":"{\"channel\":\"book\",\"type\":\"update\",\"data\":[{\"symbol\":\"BTC/USD\",\"bids\":[{\"price\":79333.3,\"qty\":0.00000000},{\"price\":76892.1,\"qty\":0.00204000}],\"asks\":[],\"checksum\":2082755422,\"timestamp\":\"2026-09-07T08:51:32.426484Z\"}]}"}
{"stream":"book:BTC/USD","kind":"frame","seq":79,"receive_ts":1788771092397193000,"monotonic_ts":3188834227117708,"payload":"{\"channel\":\"book\",\"type\":\"update\",\"data\":[{\"symbol\":\"BTC/USD\",\"bids\":[{\"price\":79454.9,\"qty\":0.03156742}],\"asks\":[],\"checksum\":2862498162,\"timestamp\":\"2026-09-07T08:51:32.430811Z\"}]}"}
{"stream":"book:BTC/USD","kind":"frame","seq":80,"receive_ts":1788771092408394000,"monotonic_ts":3188834238318500,"payload":"{\"channel\":\"book\",\"type\":\"update\",\"data\":[{\"symbol\":\"BTC/USD\",\"bids\":[],\"asks\":[{\"price\":80392.7,\"qty\":0.21312995}],\"checksum\":2862498162,\"timestamp\":\"2026-09-07T08:51:32.442946Z\"}]}"}
{"stream":"book:BTC/USD","kind":"frame","seq":81,"receive_ts":1788771092443704000,"monotonic_ts":3188834273629500,"payload":"{\"channel\":\"book\",\"type\":\"update\",\"data\":[{\"symbol\":\"BTC/USD\",\"bids\":[{\"price\":79416.8,\"qty\":0.93853818},{\"price\":79416.7,\"qty\":1.97760309}],\"asks\":[],\"checksum\":2862498162,\"timestamp\":\"2026-09-07T08:51:32.478951Z\"}]}"}
{"stream":"book:BTC/USD","kind":"control","seq":82,"receive_ts":1788771092492724000,"monotonic_ts":3188834322649416,"payload":"{\"channel\":\"heartbeat\"}"}
{"stream":"book:BTC/USD","kind":"frame","seq":83,"receive_ts":1788771092509116000,"monotonic_ts":3188834339041166,"payload":"{\"channel\":\"book\",\"type\":\"update\",\"data\":[{\"symbol\":\"BTC/USD\",\"bids\":[],\"asks\":[{\"price\":79809.1,\"qty\":0.00000000},{\"price\":82982.2,\"qty\":0.00053013}],\"checksum\":2862498162,\"timestamp\":\"2026-09-07T08:51:32.520893Z\"}]}"}
{"stream":"book:BTC/USD","kind":"frame","seq":84,"receive_ts":1788771092509141000,"monotonic_ts":3188834339063666,"payload":"{\"channel\":\"book\",\"type\":\"update\",\"data\":[{\"symbol\":\"BTC/USD\",\"bids\":[],\"asks\":[{\"price\":79821.2,\"qty\":0.00000000},{\"price\":82984.0,\"qty\":0.00111619}],\"checksum\":2862498162,\"timestamp\":\"2026-09-07T08:51:32.520942Z\"}]}"}
{"stream":"book:BTC/USD","kind":"frame","seq":85,"receive_ts":1788771092509146000,"monotonic_ts":3188834339069375,"payload":"{\"channel\":\"book\",\"type\":\"update\",\"data\":[{\"symbol\":\"BTC/USD\",\"bids\":[],\"asks\":[{\"price\":79795.5,\"qty\":0.14420623}],\"checksum\":2862498162,\"timestamp\":\"2026-09-07T08:51:32.520954Z\"}]}"}
{"stream":"book:BTC/USD","kind":"frame","seq":86,"receive_ts":1788771092509151000,"monotonic_ts":3188834339073875,"payload":"{\"channel\":\"book\",\"type\":\"update\",\"data\":[{\"symbol\":\"BTC/USD\",\"bids\":[],\"asks\":[{\"price\":79828.1,\"qty\":0.88709368}],\"checksum\":2862498162,\"timestamp\":\"2026-09-07T08:51:32.521056Z\"}]}"}
{"stream":"book:BTC/USD","kind":"frame","seq":87,"receive_ts":1788771092509155000,"monotonic_ts":3188834339077750,"payload":"{\"channel\":\"book\",\"type\":\"update\",\"data\":[{\"symbol\":\"BTC/USD\",\"bids\":[],\"asks\":[{\"price\":79795.5,\"qty\":0.00000000},{\"price\":82986.0,\"qty\":0.00166300}],\"checksum\":2862498162,\"timestamp\":\"2026-09-07T08:51:32.521344Z\"}]}"}
{"stream":"book:BTC/USD","kind":"frame","seq":88,"receive_ts":1788771092509161000,"monotonic_ts":3188834339083833,"payload":"{\"channel\":\"book\",\"type\":\"update\",\"data\":[{\"symbol\":\"BTC/USD\",\"bids\":[],\"asks\":[{\"price\":79795.5,\"qty\":0.24391155}],\"checksum\":2862498162,\"timestamp\":\"2026-09-07T08:51:32.521696Z\"}]}"}
{"stream":"book:BTC/USD","kind":"frame","seq":89,"receive_ts":1788771092509165000,"monotonic_ts":3188834339087833,"payload":"{\"channel\":\"book\",\"type\":\"update\",\"data\":[{\"symbol\":\"BTC/USD\",\"bids\":[],\"asks\":[{\"price\":79779.4,\"qty\":0.04435650}],\"checksum\":2862498162,\"timestamp\":\"2026-09-07T08:51:32.522163Z\"}]}"}
{"stream":"book:BTC/USD","kind":"frame","seq":90,"receive_ts":1788771092509169000,"monotonic_ts":3188834339092208,"payload":"{\"channel\":\"book\",\"type\":\"update\",\"data\":[{\"symbol\":\"BTC/USD\",\"bids\":[],\"asks\":[{\"price\":79779.4,\"qty\":0.18851514}],\"checksum\":2862498162,\"timestamp\":\"2026-09-07T08:51:32.522213Z\"}]}"}
{"stream":"book:BTC/USD","kind":"frame","seq":91,"receive_ts":1788771092509176000,"monotonic_ts":3188834339098750,"payload":"{\"channel\":\"book\",\"type\":\"update\",\"data\":[{\"symbol\":\"BTC/USD\",\"bids\":[],\"asks\":[{\"price\":79828.1,\"qty\":0.44329444}],\"checksum\":2862498162,\"timestamp\":\"2026-09-07T08:51:32.522313Z\"}]}"}
{"stream":"book:BTC/USD","kind":"frame","seq":92,"receive_ts":1788771092509180000,"monotonic_ts":3188834339103125,"payload":"{\"channel\":\"book\",\"type\":\"update\",\"data\":[{\"symbol\":\"BTC/USD\",\"bids\":[],\"asks\":[{\"price\":79806.7,\"qty\":0.34364531}],\"checksum\":2862498162,\"timestamp\":\"2026-09-07T08:51:32.522575Z\"}]}"}
{"stream":"book:BTC/USD","kind":"frame","seq":93,"receive_ts":1788771092522220000,"monotonic_ts":3188834352145208,"payload":"{\"channel\":\"book\",\"type\":\"update\",\"data\":[{\"symbol\":\"BTC/USD\",\"bids\":[],\"asks\":[{\"price\":79469.1,\"qty\":0.00000000},{\"price\":82982.2,\"qty\":0.00053013},{\"price\":79468.7,\"qty\":0.02397570}],\"checksum\":2862498162,\"timestamp\":\"2026-09-07T08:51:32.556796Z\"}]}"}
{"stream":"book:BTC/USD","kind":"frame","seq":94,"receive_ts":1788771092579627000,"monotonic_ts":3188834409551833,"payload":"{\"channel\":\"book\",\"type\":\"update\",\"data\":[{\"symbol\":\"BTC/USD\",\"bids\":[{\"price\":77071.2,\"qty\":0.45478394}],\"asks\":[],\"checksum\":2862498162,\"timestamp\":\"2026-09-07T08:51:32.614771Z\"}]}"}
{"stream":"book:BTC/USD","kind":"frame","seq":95,"receive_ts":1788771092585235000,"monotonic_ts":3188834415159416,"payload":"{\"channel\":\"book\",\"type\":\"update\",\"data\":[{\"symbol\":\"BTC/USD\",\"bids\":[{\"price\":77071.2,\"qty\":0.52130031}],\"asks\":[],\"checksum\":2862498162,\"timestamp\":\"2026-09-07T08:51:32.620838Z\"}]}"}
{"stream":"book:BTC/USD","kind":"frame","seq":96,"receive_ts":1788771092627596000,"monotonic_ts":3188834457520500,"payload":"{\"channel\":\"book\",\"type\":\"update\",\"data\":[{\"symbol\":\"BTC/USD\",\"bids\":[{\"price\":79323.3,\"qty\":0.01970739}],\"asks\":[],\"checksum\":2862498162,\"timestamp\":\"2026-09-07T08:51:32.661075Z\"}]}"}
{"stream":"book:BTC/USD","kind":"frame","seq":97,"receive_ts":1788771092712288000,"monotonic_ts":3188834542211625,"payload":"{\"channel\":\"book\",\"type\":\"update\",\"data\":[{\"symbol\":\"BTC/USD\",\"bids\":[{\"price\":79330.8,\"qty\":0.00000000},{\"price\":76892.1,\"qty\":0.00204000}],\"asks\":[],\"checksum\":2862498162,\"timestamp\":\"2026-09-07T08:51:32.745953Z\"}]}"}
{"stream":"book:BTC/USD","kind":"frame","seq":98,"receive_ts":1788771092712463000,"monotonic_ts":3188834542386208,"payload":"{\"channel\":\"book\",\"type\":\"update\",\"data\":[{\"symbol\":\"BTC/USD\",\"bids\":[{\"price\":79317.5,\"qty\":0.03700300}],\"asks\":[],\"checksum\":2862498162,\"timestamp\":\"2026-09-07T08:51:32.747322Z\"}]}"}
{"stream":"book:BTC/USD","kind":"frame","seq":99,"receive_ts":1788771092843765000,"monotonic_ts":3188834673688416,"payload":"{\"channel\":\"book\",\"type\":\"update\",\"data\":[{\"symbol\":\"BTC/USD\",\"bids\":[{\"price\":79435.1,\"qty\":0.00000000},{\"price\":76892.1,\"qty\":0.00204000}],\"asks\":[],\"checksum\":2862498162,\"timestamp\":\"2026-09-07T08:51:32.878940Z\"}]}"}
{"stream":"book:BTC/USD","kind":"frame","seq":100,"receive_ts":1788771092913012000,"monotonic_ts":3188834742935208,"payload":"{\"channel\":\"book\",\"type\":\"update\",\"data\":[{\"symbol\":\"BTC/USD\",\"bids\":[{\"price\":79091.8,\"qty\":4.42523553},{\"price\":79091.6,\"qty\":1.23732789}],\"asks\":[],\"checksum\":2862498162,\"timestamp\":\"2026-09-07T08:51:32.940586Z\"}]}"}
{"stream":"book:BTC/USD","kind":"frame","seq":101,"receive_ts":1788771092913038000,"monotonic_ts":3188834742959958,"payload":"{\"channel\":\"book\",\"type\":\"update\",\"data\":[{\"symbol\":\"BTC/USD\",\"bids\":[],\"asks\":[{\"price\":79810.6,\"qty\":0.00000000},{\"price\":82984.0,\"qty\":0.00111619},{\"price\":79810.8,\"qty\":1.23009183}],\"checksum\":2862498162,\"timestamp\":\"2026-09-07T08:51:32.940659Z\"}]}"}
{"stream":"book:BTC/USD","kind":"frame","seq":102,"receive_ts":1788771092922783000,"monotonic_ts":3188834752705625,"payload":"{\"channel\":\"book\",\"type\":\"update\",\"data\":[{\"symbol\":\"BTC/USD\",\"bids\":[{\"price\":79446.1,\"qty\":0.00000000},{\"price\":76892.1,\"qty\":0.00204000}],\"asks\":[],\"checksum\":868981097,\"timestamp\":\"2026-09-07T08:51:32.954292Z\"}]}"}
{"stream":"book:BTC/USD","kind":"frame","seq":103,"receive_ts":1788771092926347000,"monotonic_ts":3188834756269166,"payload":"{\"channel\":\"book\",\"type\":\"update\",\"data\":[{\"symbol\":\"BTC/USD\",\"bids\":[{\"price\":79446.9,\"qty\":0.62935071}],\"asks\":[],\"checksum\":898357557,\"timestamp\":\"2026-09-07T08:51:32.955073Z\"}]}"}
{"stream":"book:BTC/USD","kind":"frame","seq":104,"receive_ts":1788771092926358000,"monotonic_ts":3188834756279500,"payload":"{\"channel\":\"book\",\"type\":\"update\",\"data\":[{\"symbol\":\"BTC/USD\",\"bids\":[{\"price\":79407.0,\"qty\":2.15985841}],\"asks\":[],\"checksum\":898357557,\"timestamp\":\"2026-09-07T08:51:32.955469Z\"}]}"}
{"stream":"book:BTC/USD","kind":"frame","seq":105,"receive_ts":1788771092926363000,"monotonic_ts":3188834756284833,"payload":"{\"channel\":\"book\",\"type\":\"update\",\"data\":[{\"symbol\":\"BTC/USD\",\"bids\":[{\"price\":79446.2,\"qty\":0.00000000},{\"price\":76892.1,\"qty\":0.00204000},{\"price\":79444.0,\"qty\":0.07015840}],\"asks\":[],\"checksum\":2549120306,\"timestamp\":\"2026-09-07T08:51:32.955650Z\"}]}"}
{"stream":"book:BTC/USD","kind":"frame","seq":106,"receive_ts":1788771092929725000,"monotonic_ts":3188834759649125,"payload":"{\"channel\":\"book\",\"type\":\"update\",\"data\":[{\"symbol\":\"BTC/USD\",\"bids\":[{\"price\":79426.4,\"qty\":0.00000000},{\"price\":76892.1,\"qty\":0.00204000},{\"price\":79427.4,\"qty\":0.00341403}],\"asks\":[],\"checksum\":2549120306,\"timestamp\":\"2026-09-07T08:51:32.958633Z\"}]}"}
{"stream":"book:BTC/USD","kind":"frame","seq":107,"receive_ts":1788771092988072000,"monotonic_ts":3188834817995041,"payload":"{\"channel\":\"book\",\"type\":\"update\",\"data\":[{\"symbol\":\"BTC/USD\",\"bids\":[],\"asks\":[{\"price\":79463.0,\"qty\":0.00000000},{\"price\":82984.0,\"qty\":0.00111619},{\"price\":79463.1,\"qty\":0.00020100}],\"checksum\":2549120306,\"timestamp\":\"2026-09-07T08:51:33.023273Z\"}]}"}
{"stream":"book:BTC/USD","kind":"frame","seq":108,"receive_ts":1788771092992122000,"monotonic_ts":3188834822044875,"payload":"{\"channel\":\"book\",\"type\":\"update\",\"data\":[{\"symbol\":\"BTC/USD\",\"bids\":[{\"price\":79323.3,\"qty\":0.00000000},{\"price\":76892.1,\"qty\":0.00204000}],\"asks\":[],\"checksum\":2549120306,\"timestamp\":\"2026-09-07T08:51:33.026839Z\"}]}"}
{"stream":"book:BTC/USD","kind":"frame","seq":109,"receive_ts":1788771093092335000,"monotonic_ts":3188834922257875,"payload":"{\"channel\":\"book\",\"type\":\"update\",\"data\":[{\"symbol\":\"BTC/USD\",\"bids\":[{\"price\":79444.0,\"qty\":0.00000000},{\"price\":76889.1,\"qty\":0.05345997},{\"price\":79447.0,\"qty\":0.07015007}],\"asks\":[],\"checksum\":1360984322,\"timestamp\":\"2026-09-07T08:51:33.126742Z\"}]}"}
{"stream":"book:BTC/USD","kind":"frame","seq":110,"receive_ts":1788771093135395000,"monotonic_ts":3188834965317625,"payload":"{\"channel\":\"book\",\"type\":\"update\",\"data\":[{\"symbol\":\"BTC/USD\",\"bids\":[{\"price\":79435.2,\"qty\":0.34010887}],\"asks\":[],\"checksum\":1360984322,\"timestamp\":\"2026-09-07T08:51:33.170473Z\"}]}"}
{"stream":"book:BTC/USD","kind":"frame","seq":111,"receive_ts":1788771093173659000,"monotonic_ts":3188835003581375,"payload":"{\"channel\":\"book\",\"type\":\"update\",\"data\":[{\"symbol\":\"BTC/USD\",\"bids\":[],\"asks\":[{\"price\":81838.7,\"qty\":0.47005146}],\"checksum\":1360984322,\"timestamp\":\"2026-09-07T08:51:33.208535Z\"}]}"}
{"stream":"book:BTC/USD","kind":"frame","seq":112,"receive_ts":1788771093182018000,"monotonic_ts":3188835011939916,"payload":"{\"channel\":\"book\",\"type\":\"update\",\"data\":[{\"symbol\":\"BTC/USD\",\"bids\":[],\"asks\":[{\"price\":81838.7,\"qty\":0.49093194}],\"checksum\":1360984322,\"timestamp\":\"2026-09-07T08:51:33.215068Z\"}]}"}
{"stream":"book:BTC/USD","kind":"frame","seq":113,"receive_ts":1788771093206454000,"monotonic_ts":3188835036375875,"payload":"{\"channel\":\"book\",\"type\":\"update\",\"data\":[{\"symbol\":\"BTC/USD\",\"bids\":[{\"price\":79324.5,\"qty\":0.01970739}],\"asks\":[],\"checksum\":1360984322,\"timestamp\":\"2026-09-07T08:51:33.241175Z\"}]}"}
{"stream":"book:BTC/USD","kind":"frame","seq":114,"receive_ts":1788771093253668000,"monotonic_ts":3188835083589875,"payload":"{\"channel\":\"book\",\"type\":\"update\",\"data\":[{\"symbol\":\"BTC/USD\",\"bids\":[{\"price\":79439.4,\"qty\":0.00000000},{\"price\":76892.1,\"qty\":0.00204000}],\"asks\":[],\"checksum\":1360984322,\"timestamp\":\"2026-09-07T08:51:33.285400Z\"}]}"}
{"stream":"book:BTC/USD","kind":"frame","seq":115,"receive_ts":1788771093255457000,"monotonic_ts":3188835085378333,"payload":"{\"channel\":\"book\",\"type\":\"update\",\"data\":[{\"symbol\":\"BTC/USD\",\"bids\":[],\"asks\":[{\"price\":79464.3,\"qty\":0.00000000},{\"price\":82984.0,\"qty\":0.00111619}],\"checksum\":1360984322,\"timestamp\":\"2026-09-07T08:51:33.286313Z\"}]}"}
{"stream":"book:BTC/USD","kind":"frame","seq":116,"receive_ts":1788771093255551000,"monotonic_ts":3188835085471708,"payload":"{\"channel\":\"book\",\"type\":\"update\",\"data\":[{\"symbol\":\"BTC/USD\",\"bids\":[{\"price\":79416.7,\"qty\":1.88422139},{\"price\":79416.9,\"qty\":0.09338170}],\"asks\":[],\"checksum\":1360984322,\"timestamp\":\"2026-09-07T08:51:33.286929Z\"}]}"}
{"stream":"book:BTC/USD","kind":"frame","seq":117,"receive_ts":1788771093282034000,"monotonic_ts":3188835111955500,"payload":"{\"channel\":\"book\",\"type\":\"update\",\"data\":[{\"symbol\":\"BTC/USD\",\"bids\":[],\"asks\":[{\"price\":80384.9,\"qty\":0.12317549}],\"checksum\":1360984322,\"timestamp\":\"2026-09-07T08:51:33.315722Z\"}]}"}
{"stream":"book:BTC/USD","kind":"frame","seq":118,"receive_ts":1788771093282053000,"monotonic_ts":3188835111972958,"payload":"{\"channel\":\"book\",\"type\":\"update\",\"data\":[{\"symbol\":\"BTC/USD\",\"bids\":[],\"asks\":[{\"price\":80392.7,\"qty\":0.23359916}],\"checksum\":1360984322,\"timestamp\":\"2026-09-07T08:51:33.315759Z\"}]}"}
{"stream":"book:BTC/USD","kind":"frame","seq":119,"receive_ts":1788771093294748000,"monotonic_ts":3188835124670375,"payload":"{\"channel\":\"book\",\"type\":\"update\",\"data\":[{\"symbol\":\"BTC/USD\",\"bids\":[],\"asks\":[{\"price\":79631.9,\"qty\":0.00000000},{\"price\":82986.0,\"qty\":0.00166300},{\"price\":79632.2,\"qty\":0.72429829}],\"checksum\":1360984322,\"timestamp\":\"2026-09-07T08:51:33.329738Z\"}]}"}
{"stream":"book:BTC/USD","kind":"frame","seq":120,"receive_ts":1788771093466628000,"monotonic_ts":3188835296549666,"payload":"{\"channel\":\"book\",\"type\":\"update\",\"data\":[{\"symbol\":\"BTC/USD\",\"bids\":[{\"price\":79407.0,\"qty\":2.25324011}],\"asks\":[],\"checksum\":1360984322,\"timestamp\":\"2026-09-07T08:51:33.501417Z\"}]}"}
{"stream":"book:BTC/USD","kind":"control","seq":121,"receive_ts":1788771093487982000,"monotonic_ts":3188835317902666,"payload":"{\"channel\":\"heartbeat\"}"}
{"stream":"book:BTC/USD","kind":"frame","seq":122,"receive_ts":1788771093532128000,"monotonic_ts":3188835362048250,"payload":"{\"channel\":\"book\",\"type\":\"update\",\"data\":[{\"symbol\":\"BTC/USD\",\"bids\":[],\"asks\":[{\"price\":79469.2,\"qty\":2.34695002},{\"price\":79468.7,\"qty\":0.02740080}],\"checksum\":1360984322,\"timestamp\":\"2026-09-07T08:51:33.557010Z\"}]}"}
{"stream":"book:BTC/USD","kind":"frame","seq":123,"receive_ts":1788771093761773000,"monotonic_ts":3188835591692541,"payload":"{\"channel\":\"book\",\"type\":\"update\",\"data\":[{\"symbol\":\"BTC/USD\",\"bids\":[{\"price\":79439.1,\"qty\":0.07352497}],\"asks\":[],\"checksum\":1360984322,\"timestamp\":\"2026-09-07T08:51:33.797251Z\"}]}"}
{"stream":"book:BTC/USD","kind":"frame","seq":124,"receive_ts":1788771093763675000,"monotonic_ts":3188835593594250,"payload":"{\"channel\":\"book\",\"type\":\"update\",\"data\":[{\"symbol\":\"BTC/USD\",\"bids\":[],\"asks\":[{\"price\":79458.3,\"qty\":0.02627693}],\"checksum\":2136010495,\"timestamp\":\"2026-09-07T08:51:33.798068Z\"}]}"}
{"stream":"book:BTC/USD","kind":"frame","seq":125,"receive_ts":1788771093777050000,"monotonic_ts":3188835606969625,"payload":"{\"channel\":\"book\",\"type\":\"update\",\"data\":[{\"symbol\":\"BTC/USD\",\"bids\":[],\"asks\":[{\"price\":79556.4,\"qty\":1.20000000}],\"checksum\":2136010495,\"timestamp\":\"2026-09-07T08:51:33.811283Z\"}]}"}
{"stream":"book:BTC/USD","kind":"frame","seq":126,"receive_ts":1788771093777189000,"monotonic_ts":3188835607107333,"payload":"{\"channel\":\"book\",\"type\":\"update\",\"data\":[{\"symbol\":\"BTC/USD\",\"bids\":[],\"asks\":[{\"price\":79572.8,\"qty\":0.00000000},{\"price\":82982.2,\"qty\":0.00053013}],\"checksum\":2136010495,\"timestamp\":\"2026-09-07T08:51:33.811524Z\"}]}"}
{"stream":"book:BTC/USD","kind":"frame","seq":127,"receive_ts":1788771093783929000,"monotonic_ts":3188835613848541,"payload":"{\"channel\":\"book\",\"type\":\"update\",\"data\":[{\"symbol\":\"BTC/USD\",\"bids\":[],\"asks\":[{\"price\":79556.4,\"qty\":0.00000000},{\"price\":82984.0,\"qty\":0.00111619}],\"checksum\":2136010495,\"timestamp\":\"2026-09-07T08:51:33.819305Z\"}]}"}
{"stream":"book:BTC/USD","kind":"frame","seq":128,"receive_ts":1788771093834280000,"monotonic_ts":3188835664200583,"payload":"{\"channel\":\"book\",\"type\":\"update\",\"data\":[{\"symbol\":\"BTC/USD\",\"bids\":[{\"price\":79443.2,\"qty\":0.00000000},{\"price\":76893.7,\"qty\":0.01280000}],\"asks\":[],\"checksum\":2972028102,\"timestamp\":\"2026-09-07T08:51:33.867726Z\"}]}"}
{"stream":"book:BTC/USD","kind":"frame","seq":129,"receive_ts":1788771093836116000,"monotonic_ts":3188835666035541,"payload":"{\"channel\":\"book\",\"type\":\"update\",\"data\":[{\"symbol\":\"BTC/USD\",\"bids\":[],\"asks\":[{\"price\":79572.8,\"qty\":1.20000000}],\"checksum\":2972028102,\"timestamp\":\"2026-09-07T08:51:33.871182Z\"}]}"}
{"stream":"book:BTC/USD","kind":"frame","seq":130,"receive_ts":1788771093913731000,"monotonic_ts":3188835743649708,"payload":"{\"channel\":\"book\",\"type\":\"update\",\"data\":[{\"symbol\":\"BTC/USD\",\"bids\":[],\"asks\":[{\"price\":81599.0,\"qty\":0.21181630},{\"price\":81598.5,\"qty\":0.08118594}],\"checksum\":2972028102,\"timestamp\":\"2026-09-07T08:51:33.949240Z\"}]}"}
{"stream":"book:BTC/USD","kind":"frame","seq":131,"receive_ts":1788771093913761000,"monotonic_ts":3188835743678958,"payload":"{\"channel\":\"book\",\"type\":\"update\",\"data\":[{\"symbol\":\"BTC/USD\",\"bids\":[{\"price\":77306.4,\"qty\":0.00000000},{\"price\":76892.1,\"qty\":0.00204000},{\"price\":77304.0,\"qty\":0.11452175}],\"asks\":[],\"checksum\":2972028102,\"timestamp\":\"2026-09-07T08:51:33.949259Z\"}]}"}
{"stream":"book:BTC/USD","kind":"frame","seq":132,"receive_ts":1788771093913838000,"monotonic_ts":3188835743756500,"payload":"{\"channel\":\"book\",\"type\":\"update\",\"data\":[{\"symbol\":\"BTC/USD\",\"bids\":[{\"price\":79270.5,\"qty\":0.00000000},{\"price\":76892.1,\"qty\":0.00204000},{\"price\":79270.3,\"qty\":0.73129719}],\"asks\":[],\"checksum\":2972028102,\"timestamp\":\"2026-09-07T08:51:33.949272Z\"}]}"}
{"stream":"book:BTC/USD","kind":"frame","seq":133,"receive_ts":1788771093923825000,"monotonic_ts":3188835753744041,"payload":"{\"channel\":\"book\",\"type\":\"update\",\"data\":[{\"symbol\":\"BTC/USD\",\"bids\":[{\"price\":79446.9,\"qty\":0.00000000},{\"price\":76892.1,\"qty\":0.00204000}],\"asks\":[],\"checksum\":3609329776,\"timestamp\":\"2026-09-07T08:51:33.956835Z\"}]}"}
{"stream":"book:BTC/USD","kind":"frame","seq":134,"receive_ts":1788771093926500000,"monotonic_ts":3188835756418166,"payload":"{\"channel\":\"book\",\"type\":\"update\",\"data\":[{\"symbol\":\"BTC/USD\",\"bids\":[{\"price\":79445.8,\"qty\":0.62935977}],\"asks\":[],\"checksum\":2814915648,\"timestamp\":\"2026-09-07T08:51:33.957983Z\"}]}"}
{"stream":"book:BTC/USD","kind":"frame","seq":135,"receive_ts":1788771093926515000,"monotonic_ts":3188835756432541,"payload":"{\"channel\":\"book\",\"type\":\"update\",\"data\":[{\"symbol\":\"BTC/USD\",\"bids\":[{\"price\":79447.0,\"qty\":0.00000000},{\"price\":76892.1,\"qty\":0.00204000},{\"price\":79444.0,\"qty\":0.07015840}],\"asks\":[],\"checksum\":3283599913,\"timestamp\":\"2026-09-07T08:51:33.958338Z\"}]}"}
{"stream":"book:BTC/USD","kind":"frame","seq":136,"receive_ts":1788771093926522000,"monotonic_ts":3188835756439291,"payload":"{\"channel\":\"book\",\"type\":\"update\",\"data\":[{\"symbol\":\"BTC/USD\",\"bids\":[{\"price\":79445.8,\"qty\":0.00000000},{\"price\":76892.1,\"qty\":0.00204000}],\"asks\":[],\"checksum\":1852873866,\"timestamp\":\"2026-09-07T08:51:33.958455Z\"}]}"}
{"stream":"book:BTC/USD","kind":"frame","seq":137,"receive_ts":1788771093929311000,"monotonic_ts":3188835759228916,"payload":"{\"channel\":\"book\",\"type\":\"update\",\"data\":[{\"symbol\":\"BTC/USD\",\"bids\":[],\"asks\":[{\"price\":81838.7,\"qty\":0.47152314}],\"checksum\":1852873866,\"timestamp\":\"2026-09-07T08:51:33.963251Z\"}]}"}
{"stream":"book:BTC/USD","kind":"frame","seq":138,"receive_ts":1788771093933760000,"monotonic_ts":3188835763678583,"payload":"{\"channel\":\"book\",\"type\":\"update\",\"data\":[{\"symbol\":\"BTC/USD\",\"bids\":[],\"asks\":[{\"price\":81838.7,\"qty\":0.49093194}],\"checksum\":1852873866,\"timestamp\":\"2026-09-07T08:51:33.969197Z\"}]}"}
{"stream":"book:BTC/USD","kind":"frame","seq":139,"receive_ts":1788771093996937000,"monotonic_ts":3188835826855625,"payload":"{\"channel\":\"book\",\"type\":\"update\",\"data\":[{\"symbol\":\"BTC/USD\",\"bids\":[],\"asks\":[{\"price\":79455.3,\"qty\":0.04259891}],\"checksum\":223904467,\"timestamp\":\"2026-09-07T08:51:34.028620Z\"}]}"}
{"stream":"book:BTC/USD","kind":"frame","seq":140,"receive_ts":1788771093997090000,"monotonic_ts":3188835827008375,"payload":"{\"channel\":\"book\",\"type\":\"update\",\"data\":[{\"symbol\":\"BTC/USD\",\"bids\":[],\"asks\":[{\"price\":79459.5,\"qty\":0.00000000},{\"price\":82978.0,\"qty\":0.50000000}],\"checksum\":223904467,\"timestamp\":\"2026-09-07T08:51:34.030706Z\"}]}"}
{"stream":"book:BTC/USD","kind":"frame","seq":141,"receive_ts":1788771093997103000,"monotonic_ts":3188835827020041,"payload":"{\"channel\":\"book\",\"type\":\"update\",\"data\":[{\"symbol\":\"BTC/USD\",\"bids\":[],\"asks\":[{\"price\":79468.8,\"qty\":0.00000000},{\"price\":82982.2,\"qty\":0.00053013},{\"price\":79465.2,\"qty\":0.09338170}],\"checksum\":223904467,\"timestamp\":\"2026-09-07T08:51:34.030976Z\"}]}"}
{"stream":"book:BTC/USD","kind":"frame","seq":142,"receive_ts":1788771094013051000,"monotonic_ts":3188835842969500,"payload":"{\"channel\":\"book\",\"type\":\"update\",\"data\":[{\"symbol\":\"BTC/USD\",\"bids\":[{\"price\":79427.2,\"qty\":0.00000000},{\"price\":76889.1,\"qty\":0.05345997},{\"price\":79427.4,\"qty\":0.01026423}],\"asks\":[],\"checksum\":223904467,\"timestamp\":\"2026-09-07T08:51:34.048773Z\"}]}"}
{"stream":"book:BTC/USD","kind":"frame","seq":143,"receive_ts":1788771094017524000,"monotonic_ts":3188835847443041,"payload":"{\"channel\":\"book\",\"type\":\"update\",\"data\":[{\"symbol\":\"BTC/USD\",\"bids\":[],\"asks\":[{\"price\":79556.4,\"qty\":1.20000000}],\"checksum\":223904467,\"timestamp\":\"2026-09-07T08:51:34.051469Z\"}]}"}
{"stream":"book:BTC/USD","kind":"frame","seq":144,"receive_ts":1788771094017697000,"monotonic_ts":3188835847614625,"payload":"{\"channel\":\"book\",\"type\":\"update\",\"data\":[{\"symbol\":\"BTC/USD\",\"bids\":[],\"asks\":[{\"price\":79572.8,\"qty\":0.00000000},{\"price\":82978.0,\"qty\":0.50000000}],\"checksum\":223904467,\"timestamp\":\"2026-09-07T08:51:34.051729Z\"}]}"}
{"stream":"book:BTC/USD","kind":"frame","seq":145,"receive_ts":1788771094038281000,"monotonic_ts":3188835868200291,"payload":"{\"channel\":\"book\",\"type\":\"update\",\"data\":[{\"symbol\":\"BTC/USD\",\"bids\":[{\"price\":79443.3,\"qty\":0.00009600}],\"asks\":[],\"checksum\":1558634381,\"timestamp\":\"2026-09-07T08:51:34.073465Z\"}]}"}
{"stream":"book:BTC/USD","kind":"frame","seq":146,"receive_ts":1788771094063840000,"monotonic_ts":3188835893758541,"payload":"{\"channel\":\"book\",\"type\":\"update\",\"data\":[{\"symbol\":\"BTC/USD\",\"bids\":[{\"price\":79416.9,\"qty\":0.00000000},{\"price\":76889.1,\"qty\":0.05345997},{\"price\":79416.8,\"qty\":1.03191988}],\"asks\":[],\"checksum\":1558634381,\"timestamp\":\"2026-09-07T08:51:34.097959Z\"}]}"}
{"stream":"book:BTC/USD","kind":"frame","seq":147,"receive_ts":1788771094089090000,"monotonic_ts":3188835919009291,"payload":"{\"channel\":\"book\",\"type\":\"update\",\"data\":[{\"symbol\":\"BTC/USD\",\"bids\":[{\"price\":79445.7,\"qty\":0.62936037}],\"asks\":[],\"checksum\":1744965540,\"timestamp\":\"2026-09-07T08:51:34.123107Z\"}]}"}
{"stream":"book:BTC/USD","kind":"frame","seq":148,"receive_ts":1788771094143387000,"monotonic_ts":3188835973306541,"payload":"{\"channel\":\"book\",\"type\":\"update\",\"data\":[{\"symbol\":\"BTC/USD\",\"bids\":[{\"price\":79445.7,\"qty\":0.00000000},{\"price\":76889.1,\"qty\":0.05345997}],\"asks\":[],\"checksum\":1558634381,\"timestamp\":\"2026-09-07T08:51:34.175973Z\"}]}"}
{"stream":"book:BTC/USD","kind":"frame","seq":149,"receive_ts":1788771094161317000,"monotonic_ts":3188835991237125,"payload":"{\"channel\":\"book\",\"type\":\"update\",\"data\":[{\"symbol\":\"BTC/USD\",\"bids\":[{\"price\":79415.1,\"qty\":0.00000000},{\"price\":76883.0,\"qty\":0.04075090}],\"asks\":[],\"checksum\":1558634381,\"timestamp\":\"2026-09-07T08:51:34.189218Z\"}]}"}
{"stream":"book:BTC/USD","kind":"frame","seq":150,"receive_ts":1788771094201960000,"monotonic_ts":3188836031878750,"payload":"{\"channel\":\"book\",\"type\":\"update\",\"data\":[{\"symbol\":\"BTC/USD\",\"bids\":[],\"asks\":[{\"price\":79458.6,\"qty\":0.00000000},{\"price\":82982.2,\"qty\":0.00053013}],\"checksum\":506035964,\"timestamp\":\"2026-09-07T08:51:34.236294Z\"}]}"}
{"stream":"book:BTC/USD","kind":"frame","seq":151,"receive_ts":1788771094201986000,"monotonic_ts":3188836031902500,"payload":"{\"channel\":\"book\",\"type\":\"update\",\"data\":[{\"symbol\":\"BTC/USD\",\"bids\":[],\"asks\":[{\"price\":79462.5,\"qty\":0.00005100}],\"checksum\":506035964,\"timestamp\":\"2026-09-07T08:51:34.236387Z\"}]}"}
{"stream":"book:BTC/USD","kind":"frame","seq":152,"receive_ts":1788771094289826000,"monotonic_ts":3188836119744541,"payload":"{\"channel\":\"book\",\"type\":\"update\",\"data\":[{\"symbol\":\"BTC/USD\",\"bids\":[],\"asks\":[{\"price\":81838.7,\"qty\":0.47152314}],\"checksum\":506035964,\"timestamp\":\"2026-09-07T08:51:34.323506Z\"}]}"}
{"stream":"book:BTC/USD","kind":"frame","seq":153,"receive_ts":1788771094292965000,"monotonic_ts":3188836122881916,"payload":"{\"channel\":\"book\",\"type\":\"update\",\"data\":[{\"symbol\":\"BTC/USD\",\"bids\":[],\"asks\":[{\"price\":81838.7,\"qty\":0.49093194}],\"checksum\":506035964,\"timestamp\":\"2026-09-07T08:51:34.329647Z\"}]}"}
{"stream":"book:BTC/USD","kind":"frame","seq":154,"receive_ts":1788771094305866000,"monotonic_ts":3188836135783833,"payload":"{\"channel\":\"book\",\"type\":\"update\",\"data\":[{\"symbol\":\"BTC/USD\",\"bids\":[],\"asks\":[{\"price\":80392.7,\"qty\":0.22870876},{\"price\":80260.2,\"qty\":0.00266960}],\"checksum\":506035964,\"timestamp\":\"2026-09-07T08:51:34.338544Z\"}]}"}
{"stream":"book:BTC/USD","kind":"frame","seq":155,"receive_ts":1788771094306081000,"monotonic_ts":3188836135997916,"payload":"{\"channel\":\"book\",\"type\":\"update\",\"data\":[{\"symbol\":\"BTC/USD\",\"bids\":[],\"asks\":[{\"price\":80392.7,\"qty\":0.22615424}],\"checksum\":506035964,\"timestamp\":\"2026-09-07T08:51:34.338854Z\"}]}"}
{"stream":"book:BTC/USD","kind":"frame","seq":156,"receive_ts":1788771094321969000,"monotonic_ts":3188836151886791,"payload":"{\"channel\":\"book\",\"type\":\"update\",\"data\":[{\"symbol\":\"BTC/USD\",\"bids\":[],\"asks\":[{\"price\":80392.7,\"qty\":0.27259099}],\"checksum\":506035964,\"timestamp\":\"2026-09-07T08:51:34.357750Z\"}]}"}
{"stream":"book:BTC/USD","kind":"control","seq":157,"receive_ts":1788771094488586000,"monotonic_ts":3188836318503708,"payload":"{\"channel\":\"heartbeat\"}"}
{"stream":"book:BTC/USD","kind":"frame","seq":158,"receive_ts":1788771094498906000,"monotonic_ts":3188836328822125,"payload":"{\"channel\":\"book\",\"type\":\"update\",\"data\":[{\"symbol\":\"BTC/USD\",\"bids\":[],\"asks\":[{\"price\":79465.2,\"qty\":0.00000000},{\"price\":82978.0,\"qty\":0.50000000},{\"price\":79468.8,\"qty\":0.09338170}],\"checksum\":506035964,\"timestamp\":\"2026-09-07T08:51:34.533906Z\"}]}"}
{"stream":"book:BTC/USD","kind":"frame","seq":159,"receive_ts":1788771094502311000,"monotonic_ts":3188836332226916,"payload":"{\"channel\":\"book\",\"type\":\"update\",\"data\":[{\"symbol\":\"BTC/USD\",\"bids\":[],\"asks\":[{\"price\":79468.7,\"qty\":0.01370040},{\"price\":79463.6,\"qty\":0.01370040}],\"checksum\":506035964,\"timestamp\":\"2026-09-07T08:51:34.538245Z\"}]}"}
{"stream":"book:BTC/USD","kind":"frame","seq":160,"receive_ts":1788771094609757000,"monotonic_ts":3188836439673375,"payload":"{\"channel\":\"book\",\"type\":\"update\",\"data\":[{\"symbol\":\"BTC/USD\",\"bids\":[],\"asks\":[{\"price\":79468.7,\"qty\":0.00685020},{\"price\":79463.6,\"qty\":0.02055060}],\"checksum\":506035964,\"timestamp\":\"2026-09-07T08:51:34.644125Z\"}]}"}
{"stream":"book:BTC/USD","kind":"frame","seq":161,"receive_ts":1788771094654459000,"monotonic_ts":3188836484375750,"payload":"{\"channel\":\"book\",\"type\":\"update\",\"data\":[{\"symbol\":\"BTC/USD\",\"bids\":[{\"price\":79415.0,\"qty\":0.09243694}],\"asks\":[],\"checksum\":506035964,\"timestamp\":\"2026-09-07T08:51:34.689505Z\"}]}"}
{"stream":"book:BTC/USD","kind":"frame","seq":162,"receive_ts":1788771094681553000,"monotonic_ts":3188836511470125,"payload":"{\"channel\":\"book\",\"type\":\"update\",\"data\":[{\"symbol\":\"BTC/USD\",\"bids\":[{\"price\":79446.3,\"qty\":0.62935532}],\"asks\":[],\"checksum\":1659045638,\"timestamp\":\"2026-09-07T08:51:34.715569Z\"}]}"}
{"stream":"book:BTC/USD","kind":"frame","seq":163,"receive_ts":1788771094681760000,"monotonic_ts":3188836511674958,"payload":"{\"channel\":\"book\",\"type\":\"update\",\"data\":[{\"symbol\":\"BTC/USD\",\"bids\":[{\"price\":79444.0,\"qty\":0.00000000},{\"price\":76889.1,\"qty\":0.05345997},{\"price\":79446.4,\"qty\":0.07015625}],\"asks\":[],\"checksum\":3768655129,\"timestamp\":\"2026-09-07T08:51:34.716875Z\"}]}"}
{"stream":"book:BTC/USD","kind":"frame","seq":164,"receive_ts":1788771094747024000,"monotonic_ts":3188836576939750,"payload":"{\"channel\":\"book\",\"type\":\"update\",\"data\":[{\"symbol\":\"BTC/USD\",\"bids\":[],\"asks\":[{\"price\":80392.7,\"qty\":0.25212178},{\"price\":80356.9,\"qty\":0.01210004}],\"checksum\":3768655129,\"timestamp\":\"2026-09-07T08:51:34.780854Z\"}]}"}
{"stream":"book:BTC/USD","kind":"frame","seq":165,"receive_ts":1788771094747070000,"monotonic_ts":3188836576984833,"payload":"{\"channel\":\"book\",\"type\":\"update\",\"data\":[{\"symbol\":\"BTC/USD\",\"bids\":[],\"asks\":[{\"price\":80392.7,\"qty\":0.20568503},{\"price\":80349.9,\"qty\":0.02588383}],\"checksum\":3768655129,\"timestamp\":\"2026-09-07T08:51:34.781102Z\"}]}"}
{"stream":"book:BTC/USD","kind":"frame","seq":166,"receive_ts":1788771094754279000,"monotonic_ts":3188836584193916,"payload":"{\"channel\":\"book\",\"type\":\"update\",\"data\":[{\"symbol\":\"BTC/USD\",\"bids\":[],\"asks\":[{\"price\":79603.7,\"qty\":0.00000000},{\"price\":82974.6,\"qty\":0.00007779}],\"checksum\":3768655129,\"timestamp\":\"2026-09-07T08:51:34.789639Z\"}]}"}
{"stream":"book:BTC/USD","kind":"frame","seq":167,"receive_ts":1788771094832564000,"monotonic_ts":3188836662480791,"payload":"{\"channel\":\"book\",\"type\":\"update\",\"data\":[{\"symbol\":\"BTC/USD\",\"bids\":[{\"price\":79416.8,\"qty\":0.93853818},{\"price\":79416.7,\"qty\":1.97760309}],\"asks\":[{\"price\":81838.7,\"qty\":0.47160921}],\"checksum\":3768655129,\"timestamp\":\"2026-09-07T08:51:34.867432Z\"}]}"}
{"stream":"book:BTC/USD","kind":"frame","seq":168,"receive_ts":1788771094836727000,"monotonic_ts":3188836666641750,"payload":"{\"channel\":\"book\",\"type\":\"update\",\"data\":[{\"symbol\":\"BTC/USD\",\"bids\":[],\"asks\":[{\"price\":81838.7,\"qty\":0.45228648}],\"checksum\":3768655129,\"timestamp\":\"2026-09-07T08:51:34.870707Z\"}]}"}
{"stream":"book:BTC/USD","kind":"frame","seq":169,"receive_ts":1788771094844100000,"monotonic_ts":3188836674015083,"payload":"{\"channel\":\"book\",\"type\":\"update\",\"data\":[{\"symbol\":\"BTC/USD\",\"bids\":[],\"asks\":[{\"price\":81838.7,\"qty\":0.47160921}],\"checksum\":3768655129,\"timestamp\":\"2026-09-07T08:51:34.879078Z\"}]}"}
{"stream":"book:BTC/USD","kind":"frame","seq":170,"receive_ts":1788771094848096000,"monotonic_ts":3188836678010250,"payload":"{\"channel\":\"book\",\"type\":\"update\",\"data\":[{\"symbol\":\"BTC/USD\",\"bids\":[{\"price\":78912.2,\"qty\":0.00000000},{\"price\":76889.1,\"qty\":0.05345997}],\"asks\":[],\"checksum\":3768655129,\"timestamp\":\"2026-09-07T08:51:34.880131Z\"}]}"}
{"stream":"book:BTC/USD","kind":"frame","seq":171,"receive_ts":1788771094848103000,"monotonic_ts":3188836678017750,"payload":"{\"channel\":\"book\",\"type\":\"update\",\"data\":[{\"symbol\":\"BTC/USD\",\"bids\":[],\"asks\":[{\"price\":81838.7,\"qty\":0.49093194}],\"checksum\":3768655129,\"timestamp\":\"2026-09-07T08:51:34.882251Z\"}]}"}
{"stream":"book:BTC/USD","kind":"frame","seq":172,"receive_ts":1788771094908696000,"monotonic_ts":3188836738611166,"payload":"{\"channel\":\"book\",\"type\":\"update\",\"data\":[{\"symbol\":\"BTC/USD\",\"bids\":[],\"asks\":[{\"price\":79455.0,\"qty\":3.41499460}],\"checksum\":883392308,\"timestamp\":\"2026-09-07T08:51:34.942182Z\"}]}"}
{"stream":"book:BTC/USD","kind":"frame","seq":173,"receive_ts":1788771094913239000,"monotonic_ts":3188836743154000,"payload":"{\"channel\":\"book\",\"type\":\"update\",\"data\":[{\"symbol\":\"BTC/USD\",\"bids\":[],\"asks\":[{\"price\":79475.0,\"qty\":0.00050000}],\"checksum\":883392308,\"timestamp\":\"2026-09-07T08:51:34.944552Z\"}]}"}
{"stream":"book:BTC/USD","kind":"frame","seq":174,"receive_ts":1788771094913255000,"monotonic_ts":3188836743169166,"payload":"{\"channel\":\"book\",\"type\":\"update\",\"data\":[{\"symbol\":\"BTC/USD\",\"bids\":[{\"price\":79405.8,\"qty\":0.00050000}],\"asks\":[],\"checksum\":883392308,\"timestamp\":\"2026-09-07T08:51:34.944660Z\"}]}"}
{"stream":"book:BTC/USD","kind":"frame","seq":175,"receive_ts":1788771094913264000,"monotonic_ts":3188836743177875,"payload":"{\"channel\":\"book\",\"type\":\"update\",\"data\":[{\"symbol\":\"BTC/USD\",\"bids\":[],\"asks\":[{\"price\":79525.0,\"qty\":0.00000000},{\"price\":82974.6,\"qty\":0.00007779}],\"checksum\":883392308,\"timestamp\":\"2026-09-07T08:51:34.946644Z\"}]}"}
{"stream":"book:BTC/USD","kind":"frame","seq":176,"receive_ts":1788771094988304000,"monotonic_ts":3188836818218500,"payload":"{\"channel\":\"book\",\"type\":\"update\",\"data\":[{\"symbol\":\"BTC/USD\",\"bids\":[],\"asks\":[{\"price\":79721.3,\"qty\":0.01970782}],\"checksum\":883392308,\"timestamp\":\"2026-09-07T08:51:35.023734Z\"}]}"}
{"stream":"book:BTC/USD","kind":"frame","seq":177,"receive_ts":1788771095030005000,"monotonic_ts":3188836859920083,"payload":"{\"channel\":\"book\",\"type\":\"update\",\"data\":[{\"symbol\":\"BTC/USD\",\"bids\":[{\"price\":77071.2,\"qty\":0.45974630}],\"asks\":[],\"checksum\":883392308,\"timestamp\":\"2026-09-07T08:51:35.065394Z\"}]}"}
{"stream":"book:BTC/USD","kind":"frame","seq":178,"receive_ts":1788771095037342000,"monotonic_ts":3188836867255708,"payload":"{\"channel\":\"book\",\"type\":\"update\",\"data\":[{\"symbol\":\"BTC/USD\",\"bids\":[{\"price\":77071.2,\"qty\":0.52130031}],\"asks\":[],\"checksum\":883392308,\"timestamp\":\"2026-09-07T08:51:35.071071Z\"}]}"}
{"stream":"book:BTC/USD","kind":"frame","seq":179,"receive_ts":1788771095070300000,"monotonic_ts":3188836900214041,"payload":"{\"channel\":\"book\",\"type\":\"update\",\"data\":[{\"symbol\":\"BTC/USD\",\"bids\":[{\"price\":79368.5,\"qty\":0.17428883},{\"price\":79367.0,\"qty\":0.69272000}],\"asks\":[],\"checksum\":883392308,\"timestamp\":\"2026-09-07T08:51:35.105603Z\"}]}"}
{"stream":"book:BTC/USD","kind":"frame","seq":180,"receive_ts":1788771095070315000,"monotonic_ts":3188836900228916,"payload":"{\"channel\":\"book\",\"type\":\"update\",\"data\":[{\"symbol\":\"BTC/USD\",\"bids\":[{\"price\":79364.7,\"qty\":0.00000000},{\"price\":76892.1,\"qty\":0.00204000},{\"price\":79363.2,\"qty\":0.34006000}],\"asks\":[],\"checksum\":883392308,\"timestamp\":\"2026-09-07T08:51:35.105620Z\"}]}"}
{"stream":"book:BTC/USD","kind":"frame","seq":181,"receive_ts":1788771095310557000,"monotonic_ts":3188837140471958,"payload":"{\"channel\":\"book\",\"type\":\"update\",\"data\":[{\"symbol\":\"BTC/USD\",\"bids\":[],\"asks\":[{\"price\":79632.2,\"qty\":0.00000000},{\"price\":82974.6,\"qty\":0.00007779},{\"price\":79632.3,\"qty\":0.72426548}],\"checksum\":883392308,\"timestamp\":\"2026-09-07T08:51:35.345592Z\"}]}"}
{"stream":"book:BTC/USD","kind":"frame","seq":182,"receive_ts":1788771095317731000,"monotonic_ts":3188837147644166,"payload":"{\"channel\":\"book\",\"type\":\"update\",\"data\":[{\"symbol\":\"BTC/USD\",\"bids\":[],\"asks\":[{\"price\":80349.9,\"qty\":0.02431069},{\"price\":80356.9,\"qty\":0.01367308}],\"checksum\":883392308,\"timestamp\":\"2026-09-07T08:51:35.352628Z\"}]}"}
{"stream":"book:BTC/USD","kind":"frame","seq":183,"receive_ts":1788771095320497000,"monotonic_ts":3188837150410208,"payload":"{\"channel\":\"book\",\"type\":\"update\",\"data\":[{\"symbol\":\"BTC/USD\",\"bids\":[],\"asks\":[{\"price\":80392.7,\"qty\":0.11882341}],\"checksum\":883392308,\"timestamp\":\"2026-09-07T08:51:35.352790Z\"}]}"}
{"stream":"book:BTC/USD","kind":"frame","seq":184,"receive_ts":1788771095364864000,"monotonic_ts":3188837194778708,"payload":"{\"channel\":\"book\",\"type\":\"update\",\"data\":[{\"symbol\":\"BTC/USD\",\"bids\":[{\"price\":79416.7,\"qty\":1.88422139},{\"price\":79416.9,\"qty\":0.09338170}],\"asks\":[],\"checksum\":883392308,\"timestamp\":\"2026-09-07T08:51:35.400766Z\"}]}"}
{"stream":"book:BTC/USD","kind":"control","seq":185,"receive_ts":1788771095488896000,"monotonic_ts":3188837318810708,"payload":"{\"channel\":\"heartbeat\"}"}
{"stream":"book:BTC/USD","kind":"frame","seq":186,"receive_ts":1788771095572580000,"monotonic_ts":3188837402494125,"payload":"{\"channel\":\"book\",\"type\":\"update\",\"data\":[{\"symbol\":\"BTC/USD\",\"bids\":[],\"asks\":[{\"price\":81838.7,\"qty\":0.47152314}],\"checksum\":883392308,\"timestamp\":\"2026-09-07T08:51:35.605545Z\"}]}"}
{"stream":"book:BTC/USD","kind":"frame","seq":187,"receive_ts":1788771095577895000,"monotonic_ts":3188837407807583,"payload":"{\"channel\":\"book\",\"type\":\"update\",\"data\":[{\"symbol\":\"BTC/USD\",\"bids\":[],\"asks\":[{\"price\":81838.7,\"qty\":0.49093194}],\"checksum\":883392308,\"timestamp\":\"2026-09-07T08:51:35.612787Z\"}]}"}
{"stream":"book:BTC/USD","kind":"frame","seq":188,"receive_ts":1788771095625515000,"monotonic_ts":3188837455427916,"payload":"{\"channel\":\"book\",\"type\":\"update\",\"data\":[{\"symbol\":\"BTC/USD\",\"bids\":[],\"asks\":[{\"price\":79810.8,\"qty\":0.00000000},{\"price\":82974.6,\"qty\":0.00007779},{\"price\":79811.0,\"qty\":1.23000050}],\"checksum\":883392308,\"timestamp\":\"2026-09-07T08:51:35.657943Z\"}]}"}
{"stream":"book:BTC/USD","kind":"frame","seq":189,"receive_ts":1788771095625536000,"monotonic_ts":3188837455447416,"payload":"{\"channel\":\"book\",\"type\":\"update\",\"data\":[{\"symbol\":\"BTC/USD\",\"bids\":[{\"price\":79091.6,\"qty\":0.00000000},{\"price\":76893.7,\"qty\":0.01280000},{\"price\":79091.4,\"qty\":1.23723675}],\"asks\":[],\"checksum\":883392308,\"timestamp\":\"2026-09-07T08:51:35.658383Z\"}]}"}
{"stream":"book:BTC/USD","kind":"frame","seq":190,"receive_ts":1788771095708956000,"monotonic_ts":3188837538869541,"payload":"{\"channel\":\"book\",\"type\":\"update\",\"data\":[{\"symbol\":\"BTC/USD\",\"bids\":[],\"asks\":[{\"price\":80384.9,\"qty\":0.05528453}],\"checksum\":883392308,\"timestamp\":\"2026-09-07T08:51:35.743948Z\"}]}"}
{"stream":"book:BTC/USD","kind":"frame","seq":191,"receive_ts":1788771095712798000,"monotonic_ts":3188837542709750,"payload":"{\"channel\":\"book\",\"type\":\"update\",\"data\":[{\"symbol\":\"BTC/USD\",\"bids\":[],\"asks\":[{\"price\":80384.9,\"qty\":0.05357027}],\"checksum\":883392308,\"timestamp\":\"2026-09-07T08:51:35.748162Z\"}]}"}
{"stream":"book:BTC/USD","kind":"frame","seq":192,"receive_ts":1788771095765693000,"monotonic_ts":3188837595606208,"payload":"{\"channel\":\"book\",\"type\":\"update\",\"data\":[{\"symbol\":\"BTC/USD\",\"bids\":[{\"price\":79446.3,\"qty\":0.00000000},{\"price\":76893.7,\"qty\":0.01280000}],\"asks\":[],\"checksum\":1221958174,\"timestamp\":\"2026-09-07T08:51:35.801017Z\"}]}"}
{"stream":"book:BTC/USD","kind":"frame","seq":193,"receive_ts":1788771095768201000,"monotonic_ts":3188837598112708,"payload":"{\"channel\":\"book\",\"type\":\"update\",\"data\":[{\"symbol\":\"BTC/USD\",\"bids\":[{\"price\":79446.9,\"qty\":0.62935066}],\"asks\":[],\"checksum\":3496491610,\"timestamp\":\"2026-09-07T08:51:35.801822Z\"}]}"}
{"stream":"book:BTC/USD","kind":"frame","seq":194,"receive_ts":1788771095768377000,"monotonic_ts":3188837598287458,"payload":"{\"channel\":\"book\",\"type\":\"update\",\"data\":[{\"symbol\":\"BTC/USD\",\"bids\":[{\"price\":79446.4,\"qty\":0.00000000},{\"price\":76893.7,\"qty\":0.01280000},{\"price\":79444.0,\"qty\":0.07015840}],\"asks\":[],\"checksum\":3543436703,\"timestamp\":\"2026-09-07T08:51:35.802585Z\"}]}"}
{"stream":"book:BTC/USD","kind":"frame","seq":195,"receive_ts":1788771095878547000,"monotonic_ts":3188837708459375,"payload":"{\"channel\":\"book\",\"type\":\"update\",\"data\":[{\"symbol\":\"BTC/USD\",\"bids\":[],\"asks\":[{\"price\":81838.7,\"qty\":0.47160921}],\"checksum\":3543436703,\"timestamp\":\"2026-09-07T08:51:35.912744Z\"}]}"}
{"stream":"book:BTC/USD","kind":"frame","seq":196,"receive_ts":1788771095893273000,"monotonic_ts":3188837723184375,"payload":"{\"channel\":\"book\",\"type\":\"update\",\"data\":[{\"symbol\":\"BTC/USD\",\"bids\":[],\"asks\":[{\"price\":81838.7,\"qty\":0.49093194}],\"checksum\":3543436703,\"timestamp\":\"2026-09-07T08:51:35.923551Z\"}]}"}
{"stream":"book:BTC/USD","kind":"frame","seq":197,"receive_ts":1788771095932051000,"monotonic_ts":3188837761961750,"payload":"{\"channel\":\"book\",\"type\":\"update\",\"data\":[{\"symbol\":\"BTC/USD\",\"bids\":[{\"price\":79270.3,\"qty\":0.00000000},{\"price\":76893.7,\"qty\":0.01280000},{\"price\":79270.2,\"qty\":0.73126449}],\"asks\":[],\"checksum\":3543436703,\"timestamp\":\"2026-09-07T08:51:35.966533Z\"}]}"}
{"stream":"book:BTC/USD","kind":"frame","seq":198,"receive_ts":1788771095936417000,"monotonic_ts":3188837766327500,"payload":"{\"channel\":\"book\",\"type\":\"update\",\"data\":[{\"symbol\":\"BTC/USD\",\"bids\":[{\"price\":79444.0,\"qty\":0.00000000},{\"price\":76893.7,\"qty\":0.01280000},{\"price\":79447.0,\"qty\":0.07015007}],\"asks\":[],\"checksum\":3165526406,\"timestamp\":\"2026-09-07T08:51:35.967786Z\"}]}"}
{"stream":"book:BTC/USD","kind":"frame","seq":199,"receive_ts":1788771095958157000,"monotonic_ts":3188837788068458,"payload":"{\"channel\":\"book\",\"type\":\"update\",\"data\":[{\"symbol\":\"BTC/USD\",\"bids\":[{\"price\":77618.6,\"qty\":0.00097914}],\"asks\":[],\"checksum\":3165526406,\"timestamp\":\"2026-09-07T08:51:35.992684Z\"}]}"}
{"stream":"book:BTC/USD","kind":"frame","seq":200,"receive_ts":1788771095963203000,"monotonic_ts":3188837793113583,"payload":"{\"channel\":\"book\",\"type\":\"update\",\"data\":[{\"symbol\":\"BTC/USD\",\"bids\":[{\"price\":77618.6,\"qty\":0.00090184}],\"asks\":[],\"checksum\":3165526406,\"timestamp\":\"2026-09-07T08:51:35.996593Z\"}]}"}
{"stream":"book:BTC/USD","kind":"frame","seq":201,"receive_ts":1788771096033991000,"monotonic_ts":3188837863904125,"payload":"{\"channel\":\"book\",\"type\":\"update\",\"data\":[{\"symbol\":\"BTC/USD\",\"bids\":[{\"price\":77700.9,\"qty\":0.00000000},{\"price\":76893.7,\"qty\":0.01280000}],\"asks\":[],\"checksum\":3165526406,\"timestamp\":\"2026-09-07T08:51:36.068626Z\"}]}"}
{"stream":"book:BTC/USD","kind":"frame","seq":202,"receive_ts":1788771096083517000,"monotonic_ts":3188837913428000,"payload":"{\"channel\":\"book\",\"type\":\"update\",\"data\":[{\"symbol\":\"BTC/USD\",\"bids\":[],\"asks\":[{\"price\":79722.1,\"qty\":0.00000000},{\"price\":82974.6,\"qty\":0.00007779},{\"price\":79721.2,\"qty\":0.00087814}],\"checksum\":3165526406,\"timestamp\":\"2026-09-07T08:51:36.119418Z\"}]}"}
{"stream":"book:BTC/USD","kind":"frame","seq":203,"receive_ts":1788771096189586000,"monotonic_ts":3188838019496791,"payload":"{\"channel\":\"book\",\"type\":\"update\",\"data\":[{\"symbol\":\"BTC/USD\",\"bids\":[{\"price\":77701.1,\"qty\":31.96259353}],\"asks\":[],\"checksum\":3165526406,\"timestamp\":\"2026-09-07T08:51:36.224371Z\"}]}"}
{"stream":"book:BTC/USD","kind":"frame","seq":204,"receive_ts":1788771096247395000,"monotonic_ts":3188838077305250,"payload":"{\"channel\":\"book\",\"type\":\"update\",\"data\":[{\"symbol\":\"BTC/USD\",\"bids\":[{\"price\":77701.0,\"qty\":0.00000000},{\"price\":76893.7,\"qty\":0.01280000},{\"price\":77700.1,\"qty\":20.00000000}],\"asks\":[],\"checksum\":3165526406,\"timestamp\":\"2026-09-07T08:51:36.281517Z\"}]}"}
{"stream":"book:BTC/USD","kind":"frame","seq":205,"receive_ts":1788771096252039000,"monotonic_ts":3188838081950208,"payload":"{\"channel\":\"book\",\"type\":\"update\",\"data\":[{\"symbol\":\"BTC/USD\",\"bids\":[],\"asks\":[{\"price\":80356.9,\"qty\":0.00157304}],\"checksum\":3165526406,\"timestamp\":\"2026-09-07T08:51:36.285117Z\"}]}"}
{"stream":"book:BTC/USD","kind":"frame","seq":206,"receive_ts":1788771096252065000,"monotonic_ts":3188838081973583,"payload":"{\"channel\":\"book\",\"type\":\"update\",\"data\":[{\"symbol\":\"BTC/USD\",\"bids\":[],\"asks\":[{\"price\":80260.2,\"qty\":0.00000000},{\"price\":82974.6,\"qty\":0.00007779}],\"checksum\":3165526406,\"timestamp\":\"2026-09-07T08:51:36.285149Z\"}]}"}
{"stream":"book:BTC/USD","kind":"frame","seq":207,"receive_ts":1788771096252070000,"monotonic_ts":3188838081978625,"payload":"{\"channel\":\"book\",\"type\":\"update\",\"data\":[{\"symbol\":\"BTC/USD\",\"bids\":[],\"asks\":[{\"price\":80392.7,\"qty\":0.00000000},{\"price\":82975.3,\"qty\":0.00012359}],\"checksum\":3165526406,\"timestamp\":\"2026-09-07T08:51:36.285168Z\"}]}"}
{"stream":"book:BTC/USD","kind":"frame","seq":208,"receive_ts":1788771096252075000,"monotonic_ts":3188838081983875,"payload":"{\"channel\":\"book\",\"type\":\"update\",\"data\":[{\"symbol\":\"BTC/USD\",\"bids\":[],\"asks\":[{\"price\":80349.9,\"qty\":0.00000000},{\"price\":82978.0,\"qty\":0.50000000}],\"checksum\":3165526406,\"timestamp\":\"2026-09-07T08:51:36.285220Z\"}]}"}
{"stream":"book:BTC/USD","kind":"frame","seq":209,"receive_ts":1788771096252079000,"monotonic_ts":3188838081987791,"payload":"{\"channel\":\"book\",\"type\":\"update\",\"data\":[{\"symbol\":\"BTC/USD\",\"bids\":[],\"asks\":[{\"price\":80384.9,\"qty\":0.00000000},{\"price\":82982.2,\"qty\":0.00053013}],\"checksum\":3165526406,\"timestamp\":\"2026-09-07T08:51:36.285230Z\"}]}"}
{"stream":"book:BTC/USD","kind":"frame","seq":210,"receive_ts":1788771096252083000,"monotonic_ts":3188838081991666,"payload":"{\"channel\":\"book\",\"type\":\"update\",\"data\":[{\"symbol\":\"BTC/USD\",\"bids\":[],\"asks\":[{\"price\":80356.9,\"qty\":0.00000000},{\"price\":82984.0,\"qty\":0.00111619}],\"checksum\":3165526406,\"timestamp\":\"2026-09-07T08:51:36.285251Z\"}]}"}
{"stream":"book:BTC/USD","kind":"frame","seq":211,"receive_ts":1788771096287547000,"monotonic_ts":3188838117458125,"payload":"{\"channel\":\"book\",\"type\":\"update\",\"data\":[{\"symbol\":\"BTC/USD\",\"bids\":[],\"asks\":[{\"price\":79455.0,\"qty\":3.41271817}],\"checksum\":4043502997,\"timestamp\":\"2026-09-07T08:51:36.319133Z\"}]}"}
{"stream":"book:BTC/USD","kind":"frame","seq":212,"receive_ts":1788771096431839000,"monotonic_ts":3188838261748625,"payload":"{\"channel\":\"book\",\"type\":\"update\",\"data\":[{\"symbol\":\"BTC/USD\",\"bids\":[{\"price\":79446.9,\"qty\":0.00000000},{\"price\":76893.7,\"qty\":0.01280000}],\"asks\":[],\"checksum\":248699576,\"timestamp\":\"2026-09-07T08:51:36.458611Z\"}]}"}
{"stream":"book:BTC/USD","kind":"frame","seq":213,"receive_ts":1788771096431899000,"monotonic_ts":3188838261807375,"payload":"{\"channel\":\"book\",\"type\":\"update\",\"data\":[{\"symbol\":\"BTC/USD\",\"bids\":[{\"price\":79445.8,\"qty\":0.62935935}],\"asks\":[],\"checksum\":3408151742,\"timestamp\":\"2026-09-07T08:51:36.459881Z\"}]}"}
{"stream":"book:BTC/USD","kind":"frame","seq":214,"receive_ts":1788771096431908000,"monotonic_ts":3188838261816333,"payload":"{\"channel\":\"book\",\"type\":\"update\",\"data\":[{\"symbol\":\"BTC/USD\",\"bids\":[{\"price\":79447.0,\"qty\":0.00000000},{\"price\":76893.7,\"qty\":0.01280000},{\"price\":79444.0,\"qty\":0.07015840}],\"asks\":[],\"checksum\":882693940,\"timestamp\":\"2026-09-07T08:51:36.460760Z\"}]}"}
{"stream":"book:BTC/USD","kind":"frame","seq":215,"receive_ts":1788771096435509000,"monotonic_ts":3188838265419083,"payload":"{\"channel\":\"book\",\"type\":\"update\",\"data\":[{\"symbol\":\"BTC/USD\",\"bids\":[{\"price\":79443.9,\"qty\":0.00000000},{\"price\":76893.7,\"qty\":0.01280000}],\"asks\":[],\"checksum\":1053943490,\"timestamp\":\"2026-09-07T08:51:36.464866Z\"}]}"}
{"stream":"book:BTC/USD","kind":"frame","seq":216,"receive_ts":1788771096435531000,"monotonic_ts":3188838265439666,"payload":"{\"channel\":\"book\",\"type\":\"update\",\"data\":[{\"symbol\":\"BTC/USD\",\"bids\":[{\"price\":79445.8,\"qty\":0.00000000},{\"price\":76892.1,\"qty\":0.00204000}],\"asks\":[],\"checksum\":2128573078,\"timestamp\":\"2026-09-07T08:51:36.467297Z\"}]}"}
{"stream":"book:BTC/USD","kind":"frame","seq":217,"receive_ts":1788771096446885000,"monotonic_ts":3188838276794416,"payload":"{\"channel\":\"book\",\"type\":\"update\",\"data\":[{\"symbol\":\"BTC/USD\",\"bids\":[{\"price\":79439.3,\"qty\":0.00000000},{\"price\":76889.1,\"qty\":0.05345997}],\"asks\":[],\"checksum\":2128573078,\"timestamp\":\"2026-09-07T08:51:36.471380Z\"}]}"}
{"stream":"book:BTC/USD","kind":"frame","seq":218,"receive_ts":1788771096463394000,"monotonic_ts":3188838293303291,"payload":"{\"channel\":\"book\",\"type\":\"update\",\"data\":[{\"symbol\":\"BTC/USD\",\"bids\":[{\"price\":79435.0,\"qty\":0.00000000},{\"price\":76883.0,\"qty\":0.04075090}],\"asks\":[],\"checksum\":2128573078,\"timestamp\":\"2026-09-07T08:51:36.476002Z\"}]}"}
{"stream":"book:BTC/USD","kind":"frame","seq":219,"receive_ts":1788771096463408000,"monotonic_ts":3188838293316625,"payload":"{\"channel\":\"book\",\"type\":\"update\",\"data\":[{\"symbol\":\"BTC/USD\",\"bids\":[{\"price\":79407.1,\"qty\":0.00000000},{\"price\":76880.0,\"qty\":0.00100000}],\"asks\":[],\"checksum\":2128573078,\"timestamp\":\"2026-09-07T08:51:36.479163Z\"}]}"}
{"stream":"book:BTC/USD","kind":"frame","seq":220,"receive_ts":1788771096463412000,"monotonic_ts":3188838293320375,"payload":"{\"channel\":\"book\",\"type\":\"update\",\"data\":[{\"symbol\":\"BTC/USD\",\"bids\":[{\"price\":79441.0,\"qty\":0.62939752}],\"asks\":[],\"checksum\":467740505,\"timestamp\":\"2026-09-07T08:51:36.480750Z\"}]}"}
{"stream":"book:BTC/USD","kind":"frame","seq":221,"receive_ts":1788771096463416000,"monotonic_ts":3188838293323708,"payload":"{\"channel\":\"book\",\"type\":\"update\",\"data\":[{\"symbol\":\"BTC/USD\",\"bids\":[{\"price\":79436.2,\"qty\":0.62943521}],\"asks\":[],\"checksum\":467740505,\"timestamp\":\"2026-09-07T08:51:36.481054Z\"}]}"}
{"stream":"book:BTC/USD","kind":"frame","seq":222,"receive_ts":1788771096463418000,"monotonic_ts":3188838293326625,"payload":"{\"channel\":\"book\",\"type\":\"update\",\"data\":[{\"symbol\":\"BTC/USD\",\"bids\":[{\"price\":79441.0,\"qty\":0.00000000},{\"price\":76883.0,\"qty\":0.04075090}],\"asks\":[],\"checksum\":2128573078,\"timestamp\":\"2026-09-07T08:51:36.482151Z\"}]}"}
{"stream":"book:BTC/USD","kind":"frame","seq":223,"receive_ts":1788771096463421000,"monotonic_ts":3188838293329416,"payload":"{\"channel\":\"book\",\"type\":\"update\",\"data\":[{\"symbol\":\"BTC/USD\",\"bids\":[{\"price\":79436.2,\"qty\":0.00000000},{\"price\":76880.0,\"qty\":0.00100000}],\"asks\":[],\"checksum\":2128573078,\"timestamp\":\"2026-09-07T08:51:36.482399Z\"}]}"}
{"stream":"book:BTC/USD","kind":"frame","seq":224,"receive_ts":1788771096469754000,"monotonic_ts":3188838299663333,"payload":"{\"channel\":\"book\",\"type\":\"update\",\"data\":[{\"symbol\":\"BTC/USD\",\"bids\":[{\"price\":79435.3,\"qty\":0.00000000},{\"price\":76872.0,\"qty\":0.10000000}],\"asks\":[],\"checksum\":2128573078,\"timestamp\":\"2026-09-07T08:51:36.489839Z\"}]}"}
{"stream":"book:BTC/USD","kind":"frame","seq":225,"receive_ts":1788771096469772000,"monotonic_ts":3188838299679958,"payload":"{\"channel\":\"book\",\"type\":\"update\",\"data\":[{\"symbol\":\"BTC/USD\",\"bids\":[{\"price\":79415.0,\"qty\":0.00000000},{\"price\":76869.7,\"qty\":0.00088591}],\"asks\":[],\"checksum\":2128573078,\"timestamp\":\"2026-09-07T08:51:36.495377Z\"}]}"}
{"stream":"book:BTC/USD","kind":"frame","seq":226,"receive_ts":1788771096469778000,"monotonic_ts":3188838299685750,"payload":"{\"channel\":\"book\",\"type\":\"update\",\"data\":[{\"symbol\":\"BTC/USD\",\"bids\":[],\"asks\":[{\"price\":79455.0,\"qty\":3.56516712}],\"checksum\":3693735674,\"timestamp\":\"2026-09-07T08:51:36.496372Z\"}]}"}
{"stream":"book:BTC/USD","kind":"frame","seq":227,"receive_ts":1788771096484484000,"monotonic_ts":3188838314393708,"payload":"{\"channel\":\"book\",\"type\":\"update\",\"data\":[{\"symbol\":\"BTC/USD\",\"bids\":[],\"asks\":[{\"price\":79624.8,\"qty\":0.00000000},{\"price\":82986.0,\"qty\":0.00166300}],\"checksum\":3693735674,\"timestamp\":\"2026-09-07T08:51:36.501451Z\"}]}"}
{"stream":"book:BTC/USD","kind":"frame","seq":228,"receive_ts":1788771096484505000,"monotonic_ts":3188838314413125,"payload":"{\"channel\":\"book\",\"type\":\"update\",\"data\":[{\"symbol\":\"BTC/USD\",\"bids\":[],\"asks\":[{\"price\":79468.9,\"qty\":0.00000000},{\"price\":82987.9,\"qty\":0.00012145},{\"price\":79465.2,\"qty\":1.26196158}],\"checksum\":3693735674,\"timestamp\":\"2026-09-07T08:51:36.503541Z\"}]}"}
{"stream":"book:BTC/USD","kind":"frame","seq":229,"receive_ts":1788771096484511000,"monotonic_ts":3188838314419458,"payload":"{\"channel\":\"book\",\"type\":\"update\",\"data\":[{\"symbol\":\"BTC/USD\",\"bids\":[{\"price\":79427.4,\"qty\":0.00685020},{\"price\":79417.0,\"qty\":0.00341403}],\"asks\":[],\"checksum\":3693735674,\"timestamp\":\"2026-09-07T08:51:36.506056Z\"}]}"}
{"stream":"book:BTC/USD","kind":"frame","seq":230,"receive_ts":1788771096484517000,"monotonic_ts":3188838314425541,"payload":"{\"channel\":\"book\",\"type\":\"update\",\"data\":[{\"symbol\":\"BTC/USD\",\"bids\":[{\"price\":79416.6,\"qty\":0.00000000},{\"price\":76869.7,\"qty\":0.00088591}],\"asks\":[],\"checksum\":3693735674,\"timestamp\":\"2026-09-07T08:51:36.506708Z\"}]}"}
{"stream":"book:BTC/USD","kind":"frame","seq":231,"receive_ts":1788771096484525000,"monotonic_ts":3188838314433583,"payload":"{\"channel\":\"book\",\"type\":\"update\",\"data\":[{\"symbol\":\"BTC/USD\",\"bids\":[{\"price\":79416.4,\"qty\":0.00000000},{\"price\":76869.0,\"qty\":0.00150000}],\"asks\":[],\"checksum\":3693735674,\"timestamp\":\"2026-09-07T08:51:36.507325Z\"}]}"}
{"stream":"book:BTC/USD","kind":"frame","seq":232,"receive_ts":1788771096484531000,"monotonic_ts":3188838314438916,"payload":"{\"channel\":\"book\",\"type\":\"update\",\"data\":[{\"symbol\":\"BTC/USD\",\"bids\":[],\"asks\":[{\"price\":79474.3,\"qty\":0.02057681}],\"checksum\":3693735674,\"timestamp\":\"2026-09-07T08:51:36.507636Z\"}]}"}
{"stream":"book:BTC/USD","kind":"frame","seq":233,"receive_ts":1788771096510392000,"monotonic_ts":3188838340301000,"payload":"{\"channel\":\"book\",\"type\":\"update\",\"data\":[{\"symbol\":\"BTC/USD\",\"bids\":[{\"price\":79432.0,\"qty\":0.00000000},{\"price\":76859.0,\"qty\":3.04063284}],\"asks\":[],\"checksum\":3693735674,\"timestamp\":\"2026-09-07T08:51:36.519692Z\"}]}"}
{"stream":"book:BTC/USD","kind":"frame","seq":234,"receive_ts":1788771096510417000,"monotonic_ts":3188838340324750,"payload":"{\"channel\":\"book\",\"type\":\"update\",\"data\":[{\"symbol\":\"BTC/USD\",\"bids\":[{\"price\":79416.0,\"qty\":0.01386935}],\"asks\":[],\"checksum\":3693735674,\"timestamp\":\"2026-09-07T08:51:36.519965Z\"}]}"}
{"stream":"book:BTC/USD","kind":"control","seq":235,"receive_ts":1788771096510421000,"monotonic_ts":3188838340328958,"payload":"{\"channel\":\"heartbeat\"}"}
{"stream":"book:BTC/USD","kind":"frame","seq":236,"receive_ts":1788771096510425000,"monotonic_ts":3188838340332666,"payload":"{\"channel\":\"book\",\"type\":\"update\",\"data\":[{\"symbol\":\"BTC/USD\",\"bids\":[{\"price\":79426.1,\"qty\":0.00000000},{\"price\":76859.0,\"qty\":3.04063284}],\"asks\":[],\"checksum\":3693735674,\"timestamp\":\"2026-09-07T08:51:36.521191Z\"}]}"}
{"stream":"book:BTC/USD","kind":"frame","seq":237,"receive_ts":1788771096510428000,"monotonic_ts":3188838340336125,"payload":"{\"channel\":\"book\",\"type\":\"update\",\"data\":[{\"symbol\":\"BTC/USD\",\"bids\":[{\"price\":79416.7,\"qty\":0.00000000},{\"price\":76858.0,\"qty\":0.01040881}],\"asks\":[],\"checksum\":3693735674,\"timestamp\":\"2026-09-07T08:51:36.521984Z\"}]}"}
{"stream":"book:BTC/USD","kind":"frame","seq":238,"receive_ts":1788771096537461000,"monotonic_ts":3188838367371416,"payload":"{\"channel\":\"book\",\"type\":\"update\",\"data\":[{\"symbol\":\"BTC/USD\",\"bids\":[{\"price\":79427.1,\"qty\":0.64773063}],\"asks\":[],\"checksum\":3693735674,\"timestamp\":\"2026-09-07T08:51:36.524148Z\"}]}"}
{"stream":"book:BTC/USD","kind":"frame","seq":239,"receive_ts":1788771096537486000,"monotonic_ts":3188838367394291,"payload":"{\"channel\":\"book\",\"type\":\"update\",\"data\":[{\"symbol\":\"BTC/USD\",\"bids\":[{\"price\":79427.2,\"qty\":0.03455308}],\"asks\":[],\"checksum\":3693735674,\"timestamp\":\"2026-09-07T08:51:36.524249Z\"}]}"}
{"stream":"book:BTC/USD","kind":"frame","seq":240,"receive_ts":1788771096537491000,"monotonic_ts":3188838367398875,"payload":"{\"channel\":\"book\",\"type\":\"update\",\"data\":[{\"symbol\":\"BTC/USD\",\"bids\":[{\"price\":79427.1,\"qty\":0.06293984}],\"asks\":[],\"checksum\":3693735674,\"timestamp\":\"2026-09-07T08:51:36.524910Z\"}]}"}
{"stream":"book:BTC/USD","kind":"frame","seq":241,"receive_ts":1788771096537495000,"monotonic_ts":3188838367403333,"payload":"{\"channel\":\"book\",\"type\":\"update\",\"data\":[{\"symbol\":\"BTC/USD\",\"bids\":[{\"price\":79368.5,\"qty\":0.00000000},{\"price\":76858.0,\"qty\":0.01040881}],\"asks\":[],\"checksum\":3693735674,\"timestamp\":\"2026-09-07T08:51:36.525967Z\"}]}"}
{"stream":"book:BTC/USD","kind":"frame","seq":242,"receive_ts":1788771096537500000,"monotonic_ts":3188838367407416,"payload":"{\"channel\":\"book\",\"type\":\"update\",\"data\":[{\"symbol\":\"BTC/USD\",\"bids\":[{\"price\":79413.4,\"qty\":0.00000000},{\"price\":76854.8,\"qty\":0.00038785}],\"asks\":[],\"checksum\":3693735674,\"timestamp\":\"2026-09-07T08:51:36.526259Z\"}]}"}
{"stream":"book:BTC/USD","kind":"frame","seq":243,"receive_ts":1788771096537503000,"monotonic_ts":3188838367411375,"payload":"{\"channel\":\"book\",\"type\":\"update\",\"data\":[{\"symbol\":\"BTC/USD\",\"bids\":[],\"asks\":[{\"price\":79455.0,\"qty\":3.68598302}],\"checksum\":1994728719,\"timestamp\":\"2026-09-07T08:51:36.530008Z\"}]}"}
{"stream":"book:BTC/USD","kind":"frame","seq":244,"receive_ts":1788771096537507000,"monotonic_ts":3188838367414958,"payload":"{\"channel\":\"book\",\"type\":\"update\",\"data\":[{\"symbol\":\"BTC/USD\",\"bids\":[{\"price\":79423.2,\"qty\":0.06219240}],\"asks\":[],\"checksum\":1994728719,\"timestamp\":\"2026-09-07T08:51:36.531463Z\"}]}"}
{"stream":"book:BTC/USD","kind":"frame","seq":245,"receive_ts":1788771096537511000,"monotonic_ts":3188838367418625,"payload":"{\"channel\":\"book\",\"type\":\"update\",\"data\":[{\"symbol\":\"BTC/USD\",\"bids\":[{\"price\":79427.3,\"qty\":0.00000000},{\"price\":76854.8,\"qty\":0.00038785}],\"asks\":[],\"checksum\":1994728719,\"timestamp\":\"2026-09-07T08:51:36.534632Z\"}]}"}
{"stream":"book:BTC/USD","kind":"frame","seq":246,"receive_ts":1788771096537514000,"monotonic_ts":3188838367422208,"payload":"{\"channel\":\"book\",\"type\":\"update\",\"data\":[{\"symbol\":\"BTC/USD\",\"bids\":[{\"price\":79422.6,\"qty\":0.00125909}],\"asks\":[],\"checksum\":1994728719,\"timestamp\":\"2026-09-07T08:51:36.534716Z\"}]}"}
{"stream":"book:BTC/USD","kind":"frame","seq":247,"receive_ts":1788771096537519000,"monotonic_ts":3188838367426750,"payload":"{\"channel\":\"book\",\"type\":\"update\",\"data\":[{\"symbol\":\"BTC/USD\",\"bids\":[{\"price\":79424.0,\"qty\":0.02424865}],\"asks\":[],\"checksum\":1994728719,\"timestamp\":\"2026-09-07T08:51:36.534991Z\"}]}"}
{"stream":"book:BTC/USD","kind":"frame","seq":248,"receive_ts":1788771096537524000,"monotonic_ts":3188838367432041,"payload":"{\"channel\":\"book\",\"type\":\"update\",\"data\":[{\"symbol\":\"BTC/USD\",\"bids\":[{\"price\":79417.0,\"qty\":0.00000000},{\"price\":76854.8,\"qty\":0.00038785},{\"price\":79426.2,\"qty\":0.00341403}],\"asks\":[],\"checksum\":1994728719,\"timestamp\":\"2026-09-07T08:51:36.536076Z\"}]}"}
{"stream":"book:BTC/USD","kind":"frame","seq":249,"receive_ts":1788771096537528000,"monotonic_ts":3188838367435875,"payload":"{\"channel\":\"book\",\"type\":\"update\",\"data\":[{\"symbol\":\"BTC/USD\",\"bids\":[{\"price\":79422.6,\"qty\":0.00000000},{\"price\":76854.8,\"qty\":0.00038785}],\"asks\":[],\"checksum\":1994728719,\"timestamp\":\"2026-09-07T08:51:36.538853Z\"}]}"}
{"stream":"book:BTC/USD","kind":"frame","seq":250,"receive_ts":1788771096537532000,"monotonic_ts":3188838367439458,"payload":"{\"channel\":\"book\",\"type\":\"update\",\"data\":[{\"symbol\":\"BTC/USD\",\"bids\":[],\"asks\":[{\"price\":79515.2,\"qty\":4.40167443}],\"checksum\":1994728719,\"timestamp\":\"2026-09-07T08:51:36.540085Z\"}]}"}
{"stream":"book:BTC/USD","kind":"frame","seq":251,"receive_ts":1788771096537535000,"monotonic_ts":3188838367443208,"payload":"{\"channel\":\"book\",\"type\":\"update\",\"data\":[{\"symbol\":\"BTC/USD\",\"bids\":[{\"price\":79420.5,\"qty\":1.88867982}],\"asks\":[],\"checksum\":1994728719,\"timestamp\":\"2026-09-07T08:51:36.540119Z\"}]}"}
{"stream":"book:BTC/USD","kind":"frame","seq":252,"receive_ts":1788771096537556000,"monotonic_ts":3188838367463916,"payload":"{\"channel\":\"book\",\"type\":\"update\",\"data\":[{\"symbol\":\"BTC/USD\",\"bids\":[{\"price\":79376.8,\"qty\":6.29906519}],\"asks\":[],\"checksum\":1994728719,\"timestamp\":\"2026-09-07T08:51:36.540153Z\"}]}"}
{"stream":"book:BTC/USD","kind":"frame","seq":253,"receive_ts":1788771096537563000,"monotonic_ts":3188838367470541,"payload":"{\"channel\":\"book\",\"type\":\"update\",\"data\":[{\"symbol\":\"BTC/USD\",\"bids\":[],\"asks\":[{\"price\":79465.2,\"qty\":0.00000000},{\"price\":82984.0,\"qty\":0.00111619},{\"price\":79463.9,\"qty\":1.26196158}],\"checksum\":1994728719,\"timestamp\":\"2026-09-07T08:51:36.540777Z\"}]}"}
{"stream":"book:BTC/USD","kind":"frame","seq":254,"receive_ts":1788771096537567000,"monotonic_ts":3188838367474416,"payload":"{\"channel\":\"book\",\"type\":\"update\",\"data\":[{\"symbol\":\"BTC/USD\",\"bids\":[],\"asks\":[{\"price\":79461.7,\"qty\":0.19004082}],\"checksum\":1994728719,\"timestamp\":\"2026-09-07T08:51:36.543271Z\"}]}"}
{"stream":"book:BTC/USD","kind":"frame","seq":255,"receive_ts":1788771096537571000,"monotonic_ts":3188838367479166,"payload":"{\"channel\":\"book\",\"type\":\"update\",\"data\":[{\"symbol\":\"BTC/USD\",\"bids\":[],\"asks\":[{\"price\":79461.7,\"qty\":0.00000000},{\"price\":82984.0,\"qty\":0.00111619}],\"checksum\":1994728719,\"timestamp\":\"2026-09-07T08:51:36.543309Z\"}]}"}
{"stream":"book:BTC/USD","kind":"frame","seq":256,"receive_ts":1788771096537575000,"monotonic_ts":3188838367483208,"payload":"{\"channel\":\"book\",\"type\":\"update\",\"data\":[{\"symbol\":\"BTC/USD\",\"bids\":[],\"asks\":[{\"price\":79461.7,\"qty\":0.83846929}],\"checksum\":1994728719,\"timestamp\":\"2026-09-07T08:51:36.545020Z\"}]}"}
{"stream":"book:BTC/USD","kind":"frame","seq":257,"receive_ts":1788771096550515000,"monotonic_ts":3188838380423875,"payload":"{\"channel\":\"book\",\"type\":\"update\",\"data\":[{\"symbol\":\"BTC/USD\",\"bids\":[{\"price\":79399.5,\"qty\":0.00000000},{\"price\":76858.0,\"qty\":0.01040881}],\"asks\":[],\"checksum\":1994728719,\"timestamp\":\"2026-09-07T08:51:36.552294Z\"}]}"}
{"stream":"book:BTC/USD","kind":"frame","seq":258,"receive_ts":1788771096550528000,"monotonic_ts":3188838380435791,"payload":"{\"channel\":\"book\",\"type\":\"update\",\"data\":[{\"symbol\":\"BTC/USD\",\"bids\":[{\"price\":79308.8,\"qty\":0.00000000},{\"price\":76854.8,\"qty\":0.00038785}],\"asks\":[],\"checksum\":1994728719,\"timestamp\":\"2026-09-07T08:51:36.553525Z\"}]}"}
{"stream":"book:BTC/USD","kind":"frame","seq":259,"receive_ts":1788771096550532000,"monotonic_ts":3188838380439875,"payload":"{\"channel\":\"book\",\"type\":\"update\",\"data\":[{\"symbol\":\"BTC/USD\",\"bids\":[{\"price\":79423.2,\"qty\":0.61801215}],\"asks\":[],\"checksum\":1994728719,\"timestamp\":\"2026-09-07T08:51:36.553916Z\"}]}"}
{"stream":"book:BTC/USD","kind":"frame","seq":260,"receive_ts":1788771096550536000,"monotonic_ts":3188838380444208,"payload":"{\"channel\":\"book\",\"type\":\"update\",\"data\":[{\"symbol\":\"BTC/USD\",\"bids\":[{\"price\":79454.9,\"qty\":0.01347967},{\"price\":79454.9,\"qty\":0.00047197},{\"price\":79454.9,\"qty\":0.00000000},{\"price\":76851.0,\"qty\":0.00650610}],\"asks\":[],\"checksum\":2673063673,\"timestamp\":\"2026-09-07T08:51:36.555670Z\"}]}"}
{"stream":"book:BTC/USD","kind":"frame","seq":261,"receive_ts":1788771096550540000,"monotonic_ts":3188838380447541,"payload":"{\"channel\":\"book\",\"type\":\"update\",\"data\":[{\"symbol\":\"BTC/USD\",\"bids\":[{\"price\":79420.5,\"qty\":0.00000000},{\"price\":76850.6,\"qty\":0.00032531}],\"asks\":[],\"checksum\":2673063673,\"timestamp\":\"2026-09-07T08:51:36.555911Z\"}]}"}
{"stream":"book:BTC/USD","kind":"frame","seq":262,"receive_ts":1788771096550543000,"monotonic_ts":3188838380450791,"payload":"{\"channel\":\"book\",\"type\":\"update\",\"data\":[{\"symbol\":\"BTC/USD\",\"bids\":[{\"price\":79423.2,\"qty\":0.06219240}],\"asks\":[],\"checksum\":2673063673,\"timestamp\":\"2026-09-07T08:51:36.557811Z\"}]}"}
{"stream":"book:BTC/USD","kind":"frame","seq":263,"receive_ts":1788771096550547000,"monotonic_ts":3188838380454791,"payload":"{\"channel\":\"book\",\"type\":\"update\",\"data\":[{\"symbol\":\"BTC/USD\",\"bids\":[{\"price\":79454.7,\"qty\":0.00000000},{\"price\":76850.0,\"qty\":0.08177397},{\"price\":79451.9,\"qty\":0.00000000},{\"price\":76848.8,\"qty\":0.00100587},{\"price\":79450.8,\"qty\":0.00000000},{\"price\":76847.7,\"qty\":0.04636311}],\"asks\":[{\"price\":79447.6,\"qty\":0.03738197}],\"checksum\":1554514306,\"timestamp\":\"2026-09-07T08:51:36.557960Z\"}]}"}
{"stream":"book:BTC/USD","kind":"frame","seq":264,"receive_ts":1788771096550550000,"monotonic_ts":3188838380457958,"payload":"{\"channel\":\"book\",\"type\":\"update\",\"data\":[{\"symbol\":\"BTC/USD\",\"bids\":[],\"asks\":[{\"price\":79457.0,\"qty\":0.00000000},{\"price\":82982.2,\"qty\":0.00053013}],\"checksum\":2063755177,\"timestamp\":\"2026-09-07T08:51:36.558396Z\"}]}"}
{"stream":"book:BTC/USD","kind":"frame","seq":265,"receive_ts":1788771096550553000,"monotonic_ts":3188838380461041,"payload":"{\"channel\":\"book\",\"type\":\"update\",\"data\":[{\"symbol\":\"BTC/USD\",\"bids\":[{\"price\":79025.7,\"qty\":0.00000000},{\"price\":76827.9,\"qty\":0.00012935}],\"asks\":[],\"checksum\":2063755177,\"timestamp\":\"2026-09-07T08:51:36.558537Z\"}]}"}
{"stream":"book:BTC/USD","kind":"frame","seq":266,"receive_ts":1788771096550556000,"monotonic_ts":3188838380464250,"payload":"{\"channel\":\"book\",\"type\":\"update\",\"data\":[{\"symbol\":\"BTC/USD\",\"bids\":[],\"asks\":[{\"price\":79455.0,\"qty\":3.53353407}],\"checksum\":1980038754,\"timestamp\":\"2026-09-07T08:51:36.559075Z\"}]}"}
{"stream":"book:BTC/USD","kind":"frame","seq":267,"receive_ts":1788771096550560000,"monotonic_ts":3188838380468250,"payload":"{\"channel\":\"book\",\"type\":\"update\",\"data\":[{\"symbol\":\"BTC/USD\",\"bids\":[],\"asks\":[{\"price\":79452.0,\"qty\":0.37638058}],\"checksum\":1117824454,\"timestamp\":\"2026-09-07T08:51:36.559310Z\"}]}"}
{"stream":"book:BTC/USD","kind":"frame","seq":268,"receive_ts":1788771096550564000,"monotonic_ts":3188838380471458,"payload":"{\"channel\":\"book\",\"type\":\"update\",\"data\":[{\"symbol\":\"BTC/USD\",\"bids\":[],\"asks\":[{\"price\":79455.0,\"qty\":3.51534043}],\"checksum\":532242164,\"timestamp\":\"2026-09-07T08:51:36.559809Z\"}]}"}
{"stream":"book:BTC/USD","kind":"frame","seq":269,"receive_ts":1788771096550567000,"monotonic_ts":3188838380474583,"payload":"{\"channel\":\"book\",\"type\":\"update\",\"data\":[{\"symbol\":\"BTC/USD\",\"bids\":[],\"asks\":[{\"price\":79455.0,\"qty\":3.39452453}],\"checksum\":2794237391,\"timestamp\":\"2026-09-07T08:51:36.559999Z\"}]}"}
{"stream":"book:BTC/USD","kind":"frame","seq":270,"receive_ts":1788771096550579000,"monotonic_ts":3188838380487125,"payload":"{\"channel\":\"book\",\"type\":\"update\",\"data\":[{\"symbol\":\"BTC/USD\",\"bids\":[{\"price\":79444.0,\"qty\":0.00000000},{\"price\":76819.1,\"qty\":0.00132610}],\"asks\":[],\"checksum\":1853337302,\"timestamp\":\"2026-09-07T08:51:36.560028Z\"}]}"}
{"stream":"book:BTC/USD","kind":"frame","seq":271,"receive_ts":1788771096550582000,"monotonic_ts":3188838380490291,"payload":"{\"channel\":\"book\",\"type\":\"update\",\"data\":[{\"symbol\":\"BTC/USD\",\"bids\":[],\"asks\":[{\"price\":79457.1,\"qty\":0.00000000},{\"price\":82982.2,\"qty\":0.00053013}],\"checksum\":2453212116,\"timestamp\":\"2026-09-07T08:51:36.560071Z\"}]}"}
{"stream":"book:BTC/USD","kind":"frame","seq":272,"receive_ts":1788771096550586000,"monotonic_ts":3188838380493583,"payload":"{\"channel\":\"book\",\"type\":\"update\",\"data\":[{\"symbol\":\"BTC/USD\",\"bids\":[],\"asks\":[{\"price\":79455.0,\"qty\":3.37977129}],\"checksum\":1397298523,\"timestamp\":\"2026-09-07T08:51:36.560105Z\"}]}"}
{"stream":"book:BTC/USD","kind":"frame","seq":273,"receive_ts":1788771096550607000,"monotonic_ts":3188838380515125,"payload":"{\"channel\":\"book\",\"type\":\"update\",\"data\":[{\"symbol\":\"BTC/USD\",\"bids\":[{\"price\":79447.5,\"qty\":0.00000000},{\"price\":76816.0,\"qty\":0.00009019}],\"asks\":[{\"price\":79446.9,\"qty\":0.03738208}],\"checksum\":2935196067,\"timestamp\":\"2026-09-07T08:51:36.560233Z\"}]}"}
{"stream":"book:BTC/USD","kind":"frame","seq":274,"receive_ts":1788771096550611000,"monotonic_ts":3188838380518458,"payload":"{\"channel\":\"book\",\"type\":\"update\",\"data\":[{\"symbol\":\"BTC/USD\",\"bids\":[],\"asks\":[{\"price\":79455.0,\"qty\":3.29199416}],\"checksum\":571216080,\"timestamp\":\"2026-09-07T08:51:36.560370Z\"}]}"}
{"stream":"book:BTC/USD","kind":"frame","seq":275,"receive_ts":1788771096550614000,"monotonic_ts":3188838380522208,"payload":"{\"channel\":\"book\",\"type\":\"update\",\"data\":[{\"symbol\":\"BTC/USD\",\"bids\":[],\"asks\":[{\"price\":79448.0,\"qty\":0.01419799}],\"checksum\":4120180495,\"timestamp\":\"2026-09-07T08:51:36.560425Z\"}]}"}
{"stream":"book:BTC/USD","kind":"frame","seq":276,"receive_ts":1788771096550618000,"monotonic_ts":3188838380525333,"payload":"{\"channel\":\"book\",\"type\":\"update\",\"data\":[{\"symbol\":\"BTC/USD\",\"bids\":[],\"asks\":[{\"price\":79455.0,\"qty\":3.27259588}],\"checksum\":654441074,\"timestamp\":\"2026-09-07T08:51:36.560527Z\"}]}"}
{"stream":"book:BTC/USD","kind":"frame","seq":277,"receive_ts":1788771096550625000,"monotonic_ts":3188838380532625,"payload":"{\"channel\":\"book\",\"type\":\"update\",\"data\":[{\"symbol\":\"BTC/USD\",\"bids\":[],\"asks\":[{\"price\":79452.0,\"qty\":1.16500228}],\"checksum\":2963126214,\"timestamp\":\"2026-09-07T08:51:36.560833Z\"}]}"}
{"stream":"book:BTC/USD","kind":"frame","seq":278,"receive_ts":1788771096550628000,"monotonic_ts":3188838380535833,"payload":"{\"channel\":\"book\",\"type\":\"update\",\"data\":[{\"symbol\":\"BTC/USD\",\"bids\":[],\"asks\":[{\"price\":79447.6,\"qty\":0.13738197}],\"checksum\":804384749,\"timestamp\":\"2026-09-07T08:51:36.561189Z\"}]}"}
{"stream":"book:BTC/USD","kind":"frame","seq":279,"receive_ts":1788771096550631000,"monotonic_ts":3188838380539000,"payload":"{\"channel\":\"book\",\"type\":\"update\",\"data\":[{\"symbol\":\"BTC/USD\",\"bids\":[],\"asks\":[{\"price\":79454.9,\"qty\":0.12000000}],\"checksum\":172855516,\"timestamp\":\"2026-09-07T08:51:36.561397Z\"}]}"}
{"stream":"book:BTC/USD","kind":"frame","seq":280,"receive_ts":1788771096550643000,"monotonic_ts":3188838380550791,"payload":"{\"channel\":\"book\",\"type\":\"update\",\"data\":[{\"symbol\":\"BTC/USD\",\"bids\":[{\"price\":79446.8,\"qty\":0.00000000},{\"price\":76815.2,\"qty\":0.00650913},{\"price\":79443.3,\"qty\":0.00000000},{\"price\":76814.2,\"qty\":0.00028704}],\"asks\":[{\"price\":79442.9,\"qty\":0.03738395}],\"checksum\":3460283830,\"timestamp\":\"2026-09-07T08:51:36.562208Z\"}]}"}
{"stream":"book:BTC/USD","kind":"frame","seq":281,"receive_ts":1788771096550647000,"monotonic_ts":3188838380554875,"payload":"{\"channel\":\"book\",\"type\":\"update\",\"data\":[{\"symbol\":\"BTC/USD\",\"bids\":[],\"asks\":[{\"price\":79446.9,\"qty\":0.41374029}],\"checksum\":156918367,\"timestamp\":\"2026-09-07T08:51:36.562363Z\"}]}"}
{"stream":"book:BTC/USD","kind":"frame","seq":282,"receive_ts":1788771096550650000,"monotonic_ts":3188838380558333,"payload":"{\"channel\":\"book\",\"type\":\"update\",\"data\":[{\"symbol\":\"BTC/USD\",\"bids\":[],\"asks\":[{\"price\":79459.6,\"qty\":0.18783119}],\"checksum\":156918367,\"timestamp\":\"2026-09-07T08:51:36.562432Z\"}]}"}
{"stream":"book:BTC/USD","kind":"frame","seq":283,"receive_ts":1788771096550657000,"monotonic_ts":3188838380564583,"payload":"{\"channel\":\"book\",\"type\":\"update\",\"data\":[{\"symbol\":\"BTC/USD\",\"bids\":[],\"asks\":[{\"price\":79447.5,\"qty\":0.01539662}],\"checksum\":295670204,\"timestamp\":\"2026-09-07T08:51:36.562566Z\"}]}"}
{"stream":"book:BTC/USD","kind":"frame","seq":284,"receive_ts":1788771096550666000,"monotonic_ts":3188838380573750,"payload":"{\"channel\":\"book\",\"type\":\"update\",\"data\":[{\"symbol\":\"BTC/USD\",\"bids\":[{\"price\":79427.4,\"qty\":0.00000000},{\"price\":76813.8,\"qty\":0.00046700},{\"price\":79417.0,\"qty\":0.00685020}],\"asks\":[],\"checksum\":578866735,\"timestamp\":\"2026-09-07T08:51:36.562866Z\"}]}"}
{"stream":"book:BTC/USD","kind":"frame","seq":285,"receive_ts":1788771096550670000,"monotonic_ts":3188838380577625,"payload":"{\"channel\":\"book\",\"type\":\"update\",\"data\":[{\"symbol\":\"BTC/USD\",\"bids\":[],\"asks\":[{\"price\":79447.5,\"qty\":0.04327819}],\"checksum\":2664374934,\"timestamp\":\"2026-09-07T08:51:36.563459Z\"}]}"}
{"stream":"book:BTC/USD","kind":"frame","seq":286,"receive_ts":1788771096550673000,"monotonic_ts":3188838380580791,"payload":"{\"channel\":\"book\",\"type\":\"update\",\"data\":[{\"symbol\":\"BTC/USD\",\"bids\":[],\"asks\":[{\"price\":79455.1,\"qty\":0.00000000},{\"price\":82973.0,\"qty\":0.00013718}],\"checksum\":3293173098,\"timestamp\":\"2026-09-07T08:51:36.563894Z\"}]}"}
{"stream":"book:BTC/USD","kind":"frame","seq":287,"receive_ts":1788771096550676000,"monotonic_ts":3188838380584125,"payload":"{\"channel\":\"book\",\"type\":\"update\",\"data\":[{\"symbol\":\"BTC/USD\",\"bids\":[],\"asks\":[{\"price\":79459.7,\"qty\":0.00000000},{\"price\":82974.0,\"qty\":0.00212965}],\"checksum\":3293173098,\"timestamp\":\"2026-09-07T08:51:36.564323Z\"}]}"}
{"stream":"book:BTC/USD","kind":"frame","seq":288,"receive_ts":1788771096550680000,"monotonic_ts":3188838380587750,"payload":"{\"channel\":\"book\",\"type\":\"update\",\"data\":[{\"symbol\":\"BTC/USD\",\"bids\":[],\"asks\":[{\"price\":79454.8,\"qty\":0.43696100}],\"checksum\":4285835925,\"timestamp\":\"2026-09-07T08:51:36.564464Z\"}]}"}
{"stream":"book:BTC/USD","kind":"frame","seq":289,"receive_ts":1788771096559843000,"monotonic_ts":3188838389752458,"payload":"{\"channel\":\"book\",\"type\":\"update\",\"data\":[{\"symbol\":\"BTC/USD\",\"bids\":[],\"asks\":[{\"price\":79454.9,\"qty\":0.00000000},{\"price\":82974.0,\"qty\":0.00212965}],\"checksum\":94525550,\"timestamp\":\"2026-09-07T08:51:36.564812Z\"}]}"}
{"stream":"book:BTC/USD","kind":"frame","seq":290,"receive_ts":1788771096559858000,"monotonic_ts":3188838389765583,"payload":"{\"channel\":\"book\",\"type\":\"update\",\"data\":[{\"symbol\":\"BTC/USD\",\"bids\":[],\"asks\":[{\"price\":79446.9,\"qty\":0.53374029}],\"checksum\":729835381,\"timestamp\":\"2026-09-07T08:51:36.565015Z\"}]}"}
{"stream":"book:BTC/USD","kind":"frame","seq":291,"receive_ts":1788771096559862000,"monotonic_ts":3188838389770125,"payload":"{\"channel\":\"book\",\"type\":\"update\",\"data\":[{\"symbol\":\"BTC/USD\",\"bids\":[],\"asks\":[{\"price\":79463.9,\"qty\":0.00000000},{\"price\":82974.6,\"qty\":0.00007779},{\"price\":79459.6,\"qty\":1.44979277}],\"checksum\":729835381,\"timestamp\":\"2026-09-07T08:51:36.566059Z\"}]}"}
{"stream":"book:BTC/USD","kind":"frame","seq":292,"receive_ts":1788771096559866000,"monotonic_ts":3188838389773583,"payload":"{\"channel\":\"book\",\"type\":\"update\",\"data\":[{\"symbol\":\"BTC/USD\",\"bids\":[{\"price\":79363.6,\"qty\":0.00000000},{\"price\":76813.8,\"qty\":0.00046700}],\"asks\":[],\"checksum\":729835381,\"timestamp\":\"2026-09-07T08:51:36.566073Z\"}]}"}
{"stream":"book:BTC/USD","kind":"frame","seq":293,"receive_ts":1788771096559869000,"monotonic_ts":3188838389776416,"payload":"{\"channel\":\"book\",\"type\":\"update\",\"data\":[{\"symbol\":\"BTC/USD\",\"bids\":[],\"asks\":[{\"price\":79454.8,\"qty\":0.44777767}],\"checksum\":3665542644,\"timestamp\":\"2026-09-07T08:51:36.566147Z\"}]}"}
{"stream":"book:BTC/USD","kind":"frame","seq":294,"receive_ts":1788771096559871000,"monotonic_ts":3188838389779125,"payload":"{\"channel\":\"book\",\"type\":\"update\",\"data\":[{\"symbol\":\"BTC/USD\",\"bids\":[],\"asks\":[{\"price\":79464.0,\"qty\":0.01709413},{\"price\":79459.6,\"qty\":2.17730678}],\"checksum\":3665542644,\"timestamp\":\"2026-09-07T08:51:36.566565Z\"}]}"}
{"stream":"book:BTC/USD","kind":"frame","seq":295,"receive_ts":1788771096559874000,"monotonic_ts":3188838389782041,"payload":"{\"channel\":\"book\",\"type\":\"update\",\"data\":[{\"symbol\":\"BTC/USD\",\"bids\":[],\"asks\":[{\"price\":79505.0,\"qty\":0.00100000}],\"checksum\":3665542644,\"timestamp\":\"2026-09-07T08:51:36.566673Z\"}]}"}
{"stream":"book:BTC/USD","kind":"frame","seq":296,"receive_ts":1788771096559877000,"monotonic_ts":3188838389784750,"payload":"{\"channel\":\"book\",\"type\":\"update\",\"data\":[{\"symbol\":\"BTC/USD\",\"bids\":[],\"asks\":[{\"price\":79447.5,\"qty\":0.01539662}],\"checksum\":4078181957,\"timestamp\":\"2026-09-07T08:51:36.568141Z\"}]}"}
{"stream":"book:BTC/USD","kind":"frame","seq":297,"receive_ts":1788771096559880000,"monotonic_ts":3188838389787416,"payload":"{\"channel\":\"book\",\"type\":\"update\",\"data\":[{\"symbol\":\"BTC/USD\",\"bids\":[],\"asks\":[{\"price\":79446.9,\"qty\":0.57898691}],\"checksum\":2659290990,\"timestamp\":\"2026-09-07T08:51:36.568445Z\"}]}"}
{"stream":"book:BTC/USD","kind":"frame","seq":298,"receive_ts":1788771096559882000,"monotonic_ts":3188838389790083,"payload":"{\"channel\":\"book\",\"type\":\"update\",\"data\":[{\"symbol\":\"BTC/USD\",\"bids\":[{\"price\":79363.4,\"qty\":0.05440000}],\"asks\":[],\"checksum\":2659290990,\"timestamp\":\"2026-09-07T08:51:36.568473Z\"}]}"}
{"stream":"book:BTC/USD","kind":"frame","seq":299,"receive_ts":1788771096559885000,"monotonic_ts":3188838389793083,"payload":"{\"channel\":\"book\",\"type\":\"update\",\"data\":[{\"symbol\":\"BTC/USD\",\"bids\":[],\"asks\":[{\"price\":79446.9,\"qty\":0.20262870}],\"checksum\":3151692309,\"timestamp\":\"2026-09-07T08:51:36.568722Z\"}]}"}
{"stream":"book:BTC/USD","kind":"frame","seq":300,"receive_ts":1788771096559888000,"monotonic_ts":3188838389796083,"payload":"{\"channel\":\"book\",\"type\":\"update\",\"data\":[{\"symbol\":\"BTC/USD\",\"bids\":[],\"asks\":[{\"price\":79447.5,\"qty\":0.00000000},{\"price\":82975.3,\"qty\":0.00012359}],\"checksum\":3859796725,\"timestamp\":\"2026-09-07T08:51:36.568861Z\"}]}"}
{"stream":"book:BTC/USD","kind":"frame","seq":301,"receive_ts":1788771096559891000,"monotonic_ts":3188838389798833,"payload":"{\"channel\":\"book\",\"type\":\"update\",\"data\":[{\"symbol\":\"BTC/USD\",\"bids\":[],\"asks\":[{\"price\":79465.3,\"qty\":0.00000000},{\"price\":82978.0,\"qty\":0.50000000}],\"checksum\":3859796725,\"timestamp\":\"2026-09-07T08:51:36.569249Z\"}]}"}
{"stream":"book:BTC/USD","kind":"frame","seq":302,"receive_ts":1788771096559894000,"monotonic_ts":3188838389801500,"payload":"{\"channel\":\"book\",\"type\":\"update\",\"data\":[{\"symbol\":\"BTC/USD\",\"bids\":[],\"asks\":[{\"price\":79505.8,\"qty\":0.60000000}],\"checksum\":3859796725,\"timestamp\":\"2026-09-07T08:51:36.569318Z\"}]}"}
{"stream":"book:BTC/USD","kind":"frame","seq":303,"receive_ts":1788771096559897000,"monotonic_ts":3188838389805041,"payload":"{\"channel\":\"book\",\"type\":\"update\",\"data\":[{\"symbol\":\"BTC/USD\",\"bids\":[],\"asks\":[{\"price\":79464.0,\"qty\":0.13073690}],\"checksum\":3859796725,\"timestamp\":\"2026-09-07T08:51:36.570966Z\"}]}"}
{"stream":"book:BTC/USD","kind":"frame","seq":304,"receive_ts":1788771096559900000,"monotonic_ts":3188838389807791,"payload":"{\"channel\":\"book\",\"type\":\"update\",\"data\":[{\"symbol\":\"BTC/USD\",\"bids\":[],\"asks\":[{\"price\":79470.8,\"qty\":0.23769319}],\"checksum\":3859796725,\"timestamp\":\"2026-09-07T08:51:36.571131Z\"}]}"}
{"stream":"book:BTC/USD","kind":"frame","seq":305,"receive_ts":1788771096559903000,"monotonic_ts":3188838389810458,"payload":"{\"channel\":\"book\",\"type\":\"update\",\"data\":[{\"symbol\":\"BTC/USD\",\"bids\":[],\"asks\":[{\"price\":79459.6,\"qty\":1.98947559}],\"checksum\":3859796725,\"timestamp\":\"2026-09-07T08:51:36.571662Z\"}]}"}
{"stream":"book:BTC/USD","kind":"frame","seq":306,"receive_ts":1788771096559906000,"monotonic_ts":3188838389813375,"payload":"{\"channel\":\"book\",\"type\":\"update\",\"data\":[{\"symbol\":\"BTC/USD\",\"bids\":[],\"asks\":[{\"price\":79454.8,\"qty\":0.43696100}],\"checksum\":2014639205,\"timestamp\":\"2026-09-07T08:51:36.571763Z\"}]}"}
{"stream":"book:BTC/USD","kind":"frame","seq":307,"receive_ts":1788771096559910000,"monotonic_ts":3188838389817875,"payload":"{\"channel\":\"book\",\"type\":\"update\",\"data\":[{\"symbol\":\"BTC/USD\",\"bids\":[],\"asks\":[{\"price\":79446.9,\"qty\":0.15738208}],\"checksum\":1713732120,\"timestamp\":\"2026-09-07T08:51:36.571812Z\"}]}"}
{"stream":"book:BTC/USD","kind":"frame","seq":308,"receive_ts":1788771096559913000,"monotonic_ts":3188838389820583,"payload":"{\"channel\":\"book\",\"type\":\"update\",\"data\":[{\"symbol\":\"BTC/USD\",\"bids\":[],\"asks\":[{\"price\":79504.9,\"qty\":0.02298745}],\"checksum\":1713732120,\"timestamp\":\"2026-09-07T08:51:36.571916Z\"}]}"}
{"stream":"book:BTC/USD","kind":"frame","seq":309,"receive_ts":1788771096559916000,"monotonic_ts":3188838389823291,"payload":"{\"channel\":\"book\",\"type\":\"update\",\"data\":[{\"symbol\":\"BTC/USD\",\"bids\":[],\"asks\":[{\"price\":79461.7,\"qty\":1.08308012}],\"checksum\":1713732120,\"timestamp\":\"2026-09-07T08:51:36.572071Z\"}]}"}
